Workbook

Sheet Prosek 1940-2025
A1: PROSEČNE MESEČNE, GODIŠNJE I EKSTREMNE VREDNOSTI ZA PERIOD 1940-2025. GODINA
A2: CMILJEVAC II, CRVENA LOKVA, 1295M φ 43.11°N λ 17.67°E h 1295 m
A4: METEOROLOŠKI PARAMETAR | B4: jan | C4: feb | D4: mar | E4: apr | F4: maj | G4: jun | H4: jul | I4: avg | J4: sep | K4: okt | L4: nov | M4: dec | N4: god.
A5: TEMPERATURA VAZDUHA (°C)
A6: Normalna vrednost | B6: =AVERAGE('1940'!B6,'1941'!B6,'1942'!B6,'1943'!B6,'1944'!B6,'1945'!B6,'1946'!B6,'1947'!B6,'1948'!B6,'1949'!B6,'1950'!B6,'1951'!B6,'1952'!B6,'1953'!B6,'1954'!B6,'1955'!B6,'1956'!B6,'1957'!B6,'1958'!B6,'1959'!B6,'1960'!B6,'1961'!B6,'1962'!B6,'1963'!B6,'1964'!B6,'1965'!B6,'1966'!B6,'1967'!B6,'1968'!B6,'1969'!B6,'1970'!B6,'1971'!B6,'1972'!B6,'1973'!B6,'1974'!B6,'1975'!B6,'1976'!B6,'1977'!B6,'1978'!B6,'1979'!B6,'1980'!B6,'1981'!B6,'1982'!B6,'1983'!B6,'1984'!B6,'1985'!B6,'1986'!B6,'1987'!B6,'1988'!B6,'1989'!B6,'1990'!B6,'1991'!B6,'1992'!B6,'1993'!B6,'1994'!B6,'1995'!B6,'1996'!B6,'1997'!B6,'1998'!B6,'1999'!B6,'2000'!B6,'2001'!B6,'2002'!B6,'2003'!B6,'2004'!B6,'2005'!B6,'2006'!B6,'2007'!B6,'2008'!B6,'2009'!B6,'2010'!B6,'2011'!B6,'2012'!B6,'2013'!B6,'2014'!B6,'2015'!B6,'2016'!B6,'2017'!B6,'2018'!B6,'2019'!B6,'2020'!B6,'2021'!B6,'2022'!B6,'2023'!B6,'2024'!B6,'2025'!B6) | C6: =AVERAGE('1940'!C6,'1941'!C6,'1942'!C6,'1943'!C6,'1944'!C6,'1945'!C6,'1946'!C6,'1947'!C6,'1948'!C6,'1949'!C6,'1950'!C6,'1951'!C6,'1952'!C6,'1953'!C6,'1954'!C6,'1955'!C6,'1956'!C6,'1957'!C6,'1958'!C6,'1959'!C6,'1960'!C6,'1961'!C6,'1962'!C6,'1963'!C6,'1964'!C6,'1965'!C6,'1966'!C6,'1967'!C6,'1968'!C6,'1969'!C6,'1970'!C6,'1971'!C6,'1972'!C6,'1973'!C6,'1974'!C6,'1975'!C6,'1976'!C6,'1977'!C6,'1978'!C6,'1979'!C6,'1980'!C6,'1981'!C6,'1982'!C6,'1983'!C6,'1984'!C6,'1985'!C6,'1986'!C6,'1987'!C6,'1988'!C6,'1989'!C6,'1990'!C6,'1991'!C6,'1992'!C6,'1993'!C6,'1994'!C6,'1995'!C6,'1996'!C6,'1997'!C6,'1998'!C6,'1999'!C6,'2000'!C6,'2001'!C6,'2002'!C6,'2003'!C6,'2004'!C6,'2005'!C6,'2006'!C6,'2007'!C6,'2008'!C6,'2009'!C6,'2010'!C6,'2011'!C6,'2012'!C6,'2013'!C6,'2014'!C6,'2015'!C6,'2016'!C6,'2017'!C6,'2018'!C6,'2019'!C6,'2020'!C6,'2021'!C6,'2022'!C6,'2023'!C6,'2024'!C6,'2025'!C6) | D6: =AVERAGE('1940'!D6,'1941'!D6,'1942'!D6,'1943'!D6,'1944'!D6,'1945'!D6,'1946'!D6,'1947'!D6,'1948'!D6,'1949'!D6,'1950'!D6,'1951'!D6,'1952'!D6,'1953'!D6,'1954'!D6,'1955'!D6,'1956'!D6,'1957'!D6,'1958'!D6,'1959'!D6,'1960'!D6,'1961'!D6,'1962'!D6,'1963'!D6,'1964'!D6,'1965'!D6,'1966'!D6,'1967'!D6,'1968'!D6,'1969'!D6,'1970'!D6,'1971'!D6,'1972'!D6,'1973'!D6,'1974'!D6,'1975'!D6,'1976'!D6,'1977'!D6,'1978'!D6,'1979'!D6,'1980'!D6,'1981'!D6,'1982'!D6,'1983'!D6,'1984'!D6,'1985'!D6,'1986'!D6,'1987'!D6,'1988'!D6,'1989'!D6,'1990'!D6,'1991'!D6,'1992'!D6,'1993'!D6,'1994'!D6,'1995'!D6,'1996'!D6,'1997'!D6,'1998'!D6,'1999'!D6,'2000'!D6,'2001'!D6,'2002'!D6,'2003'!D6,'2004'!D6,'2005'!D6,'2006'!D6,'2007'!D6,'2008'!D6,'2009'!D6,'2010'!D6,'2011'!D6,'2012'!D6,'2013'!D6,'2014'!D6,'2015'!D6,'2016'!D6,'2017'!D6,'2018'!D6,'2019'!D6,'2020'!D6,'2021'!D6,'2022'!D6,'2023'!D6,'2024'!D6,'2025'!D6) | E6: =AVERAGE('1940'!E6,'1941'!E6,'1942'!E6,'1943'!E6,'1944'!E6,'1945'!E6,'1946'!E6,'1947'!E6,'1948'!E6,'1949'!E6,'1950'!E6,'1951'!E6,'1952'!E6,'1953'!E6,'1954'!E6,'1955'!E6,'1956'!E6,'1957'!E6,'1958'!E6,'1959'!E6,'1960'!E6,'1961'!E6,'1962'!E6,'1963'!E6,'1964'!E6,'1965'!E6,'1966'!E6,'1967'!E6,'1968'!E6,'1969'!E6,'1970'!E6,'1971'!E6,'1972'!E6,'1973'!E6,'1974'!E6,'1975'!E6,'1976'!E6,'1977'!E6,'1978'!E6,'1979'!E6,'1980'!E6,'1981'!E6,'1982'!E6,'1983'!E6,'1984'!E6,'1985'!E6,'1986'!E6,'1987'!E6,'1988'!E6,'1989'!E6,'1990'!E6,'1991'!E6,'1992'!E6,'1993'!E6,'1994'!E6,'1995'!E6,'1996'!E6,'1997'!E6,'1998'!E6,'1999'!E6,'2000'!E6,'2001'!E6,'2002'!E6,'2003'!E6,'2004'!E6,'2005'!E6,'2006'!E6,'2007'!E6,'2008'!E6,'2009'!E6,'2010'!E6,'2011'!E6,'2012'!E6,'2013'!E6,'2014'!E6,'2015'!E6,'2016'!E6,'2017'!E6,'2018'!E6,'2019'!E6,'2020'!E6,'2021'!E6,'2022'!E6,'2023'!E6,'2024'!E6,'2025'!E6) | F6: =AVERAGE('1940'!F6,'1941'!F6,'1942'!F6,'1943'!F6,'1944'!F6,'1945'!F6,'1946'!F6,'1947'!F6,'1948'!F6,'1949'!F6,'1950'!F6,'1951'!F6,'1952'!F6,'1953'!F6,'1954'!F6,'1955'!F6,'1956'!F6,'1957'!F6,'1958'!F6,'1959'!F6,'1960'!F6,'1961'!F6,'1962'!F6,'1963'!F6,'1964'!F6,'1965'!F6,'1966'!F6,'1967'!F6,'1968'!F6,'1969'!F6,'1970'!F6,'1971'!F6,'1972'!F6,'1973'!F6,'1974'!F6,'1975'!F6,'1976'!F6,'1977'!F6,'1978'!F6,'1979'!F6,'1980'!F6,'1981'!F6,'1982'!F6,'1983'!F6,'1984'!F6,'1985'!F6,'1986'!F6,'1987'!F6,'1988'!F6,'1989'!F6,'1990'!F6,'1991'!F6,'1992'!F6,'1993'!F6,'1994'!F6,'1995'!F6,'1996'!F6,'1997'!F6,'1998'!F6,'1999'!F6,'2000'!F6,'2001'!F6,'2002'!F6,'2003'!F6,'2004'!F6,'2005'!F6,'2006'!F6,'2007'!F6,'2008'!F6,'2009'!F6,'2010'!F6,'2011'!F6,'2012'!F6,'2013'!F6,'2014'!F6,'2015'!F6,'2016'!F6,'2017'!F6,'2018'!F6,'2019'!F6,'2020'!F6,'2021'!F6,'2022'!F6,'2023'!F6,'2024'!F6,'2025'!F6) | G6: =AVERAGE('1940'!G6,'1941'!G6,'1942'!G6,'1943'!G6,'1944'!G6,'1945'!G6,'1946'!G6,'1947'!G6,'1948'!G6,'1949'!G6,'1950'!G6,'1951'!G6,'1952'!G6,'1953'!G6,'1954'!G6,'1955'!G6,'1956'!G6,'1957'!G6,'1958'!G6,'1959'!G6,'1960'!G6,'1961'!G6,'1962'!G6,'1963'!G6,'1964'!G6,'1965'!G6,'1966'!G6,'1967'!G6,'1968'!G6,'1969'!G6,'1970'!G6,'1971'!G6,'1972'!G6,'1973'!G6,'1974'!G6,'1975'!G6,'1976'!G6,'1977'!G6,'1978'!G6,'1979'!G6,'1980'!G6,'1981'!G6,'1982'!G6,'1983'!G6,'1984'!G6,'1985'!G6,'1986'!G6,'1987'!G6,'1988'!G6,'1989'!G6,'1990'!G6,'1991'!G6,'1992'!G6,'1993'!G6,'1994'!G6,'1995'!G6,'1996'!G6,'1997'!G6,'1998'!G6,'1999'!G6,'2000'!G6,'2001'!G6,'2002'!G6,'2003'!G6,'2004'!G6,'2005'!G6,'2006'!G6,'2007'!G6,'2008'!G6,'2009'!G6,'2010'!G6,'2011'!G6,'2012'!G6,'2013'!G6,'2014'!G6,'2015'!G6,'2016'!G6,'2017'!G6,'2018'!G6,'2019'!G6,'2020'!G6,'2021'!G6,'2022'!G6,'2023'!G6,'2024'!G6,'2025'!G6) | H6: =AVERAGE('1940'!H6,'1941'!H6,'1942'!H6,'1943'!H6,'1944'!H6,'1945'!H6,'1946'!H6,'1947'!H6,'1948'!H6,'1949'!H6,'1950'!H6,'1951'!H6,'1952'!H6,'1953'!H6,'1954'!H6,'1955'!H6,'1956'!H6,'1957'!H6,'1958'!H6,'1959'!H6,'1960'!H6,'1961'!H6,'1962'!H6,'1963'!H6,'1964'!H6,'1965'!H6,'1966'!H6,'1967'!H6,'1968'!H6,'1969'!H6,'1970'!H6,'1971'!H6,'1972'!H6,'1973'!H6,'1974'!H6,'1975'!H6,'1976'!H6,'1977'!H6,'1978'!H6,'1979'!H6,'1980'!H6,'1981'!H6,'1982'!H6,'1983'!H6,'1984'!H6,'1985'!H6,'1986'!H6,'1987'!H6,'1988'!H6,'1989'!H6,'1990'!H6,'1991'!H6,'1992'!H6,'1993'!H6,'1994'!H6,'1995'!H6,'1996'!H6,'1997'!H6,'1998'!H6,'1999'!H6,'2000'!H6,'2001'!H6,'2002'!H6,'2003'!H6,'2004'!H6,'2005'!H6,'2006'!H6,'2007'!H6,'2008'!H6,'2009'!H6,'2010'!H6,'2011'!H6,'2012'!H6,'2013'!H6,'2014'!H6,'2015'!H6,'2016'!H6,'2017'!H6,'2018'!H6,'2019'!H6,'2020'!H6,'2021'!H6,'2022'!H6,'2023'!H6,'2024'!H6,'2025'!H6) | I6: =AVERAGE('1940'!I6,'1941'!I6,'1942'!I6,'1943'!I6,'1944'!I6,'1945'!I6,'1946'!I6,'1947'!I6,'1948'!I6,'1949'!I6,'1950'!I6,'1951'!I6,'1952'!I6,'1953'!I6,'1954'!I6,'1955'!I6,'1956'!I6,'1957'!I6,'1958'!I6,'1959'!I6,'1960'!I6,'1961'!I6,'1962'!I6,'1963'!I6,'1964'!I6,'1965'!I6,'1966'!I6,'1967'!I6,'1968'!I6,'1969'!I6,'1970'!I6,'1971'!I6,'1972'!I6,'1973'!I6,'1974'!I6,'1975'!I6,'1976'!I6,'1977'!I6,'1978'!I6,'1979'!I6,'1980'!I6,'1981'!I6,'1982'!I6,'1983'!I6,'1984'!I6,'1985'!I6,'1986'!I6,'1987'!I6,'1988'!I6,'1989'!I6,'1990'!I6,'1991'!I6,'1992'!I6,'1993'!I6,'1994'!I6,'1995'!I6,'1996'!I6,'1997'!I6,'1998'!I6,'1999'!I6,'2000'!I6,'2001'!I6,'2002'!I6,'2003'!I6,'2004'!I6,'2005'!I6,'2006'!I6,'2007'!I6,'2008'!I6,'2009'!I6,'2010'!I6,'2011'!I6,'2012'!I6,'2013'!I6,'2014'!I6,'2015'!I6,'2016'!I6,'2017'!I6,'2018'!I6,'2019'!I6,'2020'!I6,'2021'!I6,'2022'!I6,'2023'!I6,'2024'!I6,'2025'!I6) | ... M6: =AVERAGE('1940'!M6,'1941'!M6,'1942'!M6,'1943'!M6,'1944'!M6,'1945'!M6,'1946'!M6,'1947'!M6,'1948'!M6,'1949'!M6,'1950'!M6,'1951'!M6,'1952'!M6,'1953'!M6,'1954'!M6,'1955'!M6,'1956'!M6,'1957'!M6,'1958'!M6,'1959'!M6,'1960'!M6,'1961'!M6,'1962'!M6,'1963'!M6,'1964'!M6,'1965'!M6,'1966'!M6,'1967'!M6,'1968'!M6,'1969'!M6,'1970'!M6,'1971'!M6,'1972'!M6,'1973'!M6,'1974'!M6,'1975'!M6,'1976'!M6,'1977'!M6,'1978'!M6,'1979'!M6,'1980'!M6,'1981'!M6,'1982'!M6,'1983'!M6,'1984'!M6,'1985'!M6,'1986'!M6,'1987'!M6,'1988'!M6,'1989'!M6,'1990'!M6,'1991'!M6,'1992'!M6,'1993'!M6,'1994'!M6,'1995'!M6,'1996'!M6,'1997'!M6,'1998'!M6,'1999'!M6,'2000'!M6,'2001'!M6,'2002'!M6,'2003'!M6,'2004'!M6,'2005'!M6,'2006'!M6,'2007'!M6,'2008'!M6,'2009'!M6,'2010'!M6,'2011'!M6,'2012'!M6,'2013'!M6,'2014'!M6,'2015'!M6,'2016'!M6,'2017'!M6,'2018'!M6,'2019'!M6,'2020'!M6,'2021'!M6,'2022'!M6,'2023'!M6,'2024'!M6,'2025'!M6) | N6: =AVERAGE(B6:M6)
A7: Srednja maksimalna | B7: =AVERAGE('1940'!B7,'1941'!B7,'1942'!B7,'1943'!B7,'1944'!B7,'1945'!B7,'1946'!B7,'1947'!B7,'1948'!B7,'1949'!B7,'1950'!B7,'1951'!B7,'1952'!B7,'1953'!B7,'1954'!B7,'1955'!B7,'1956'!B7,'1957'!B7,'1958'!B7,'1959'!B7,'1960'!B7,'1961'!B7,'1962'!B7,'1963'!B7,'1964'!B7,'1965'!B7,'1966'!B7,'1967'!B7,'1968'!B7,'1969'!B7,'1970'!B7,'1971'!B7,'1972'!B7,'1973'!B7,'1974'!B7,'1975'!B7,'1976'!B7,'1977'!B7,'1978'!B7,'1979'!B7,'1980'!B7,'1981'!B7,'1982'!B7,'1983'!B7,'1984'!B7,'1985'!B7,'1986'!B7,'1987'!B7,'1988'!B7,'1989'!B7,'1990'!B7,'1991'!B7,'1992'!B7,'1993'!B7,'1994'!B7,'1995'!B7,'1996'!B7,'1997'!B7,'1998'!B7,'1999'!B7,'2000'!B7,'2001'!B7,'2002'!B7,'2003'!B7,'2004'!B7,'2005'!B7,'2006'!B7,'2007'!B7,'2008'!B7,'2009'!B7,'2010'!B7,'2011'!B7,'2012'!B7,'2013'!B7,'2014'!B7,'2015'!B7,'2016'!B7,'2017'!B7,'2018'!B7,'2019'!B7,'2020'!B7,'2021'!B7,'2022'!B7,'2023'!B7,'2024'!B7,'2025'!B7) | C7: =AVERAGE('1940'!C7,'1941'!C7,'1942'!C7,'1943'!C7,'1944'!C7,'1945'!C7,'1946'!C7,'1947'!C7,'1948'!C7,'1949'!C7,'1950'!C7,'1951'!C7,'1952'!C7,'1953'!C7,'1954'!C7,'1955'!C7,'1956'!C7,'1957'!C7,'1958'!C7,'1959'!C7,'1960'!C7,'1961'!C7,'1962'!C7,'1963'!C7,'1964'!C7,'1965'!C7,'1966'!C7,'1967'!C7,'1968'!C7,'1969'!C7,'1970'!C7,'1971'!C7,'1972'!C7,'1973'!C7,'1974'!C7,'1975'!C7,'1976'!C7,'1977'!C7,'1978'!C7,'1979'!C7,'1980'!C7,'1981'!C7,'1982'!C7,'1983'!C7,'1984'!C7,'1985'!C7,'1986'!C7,'1987'!C7,'1988'!C7,'1989'!C7,'1990'!C7,'1991'!C7,'1992'!C7,'1993'!C7,'1994'!C7,'1995'!C7,'1996'!C7,'1997'!C7,'1998'!C7,'1999'!C7,'2000'!C7,'2001'!C7,'2002'!C7,'2003'!C7,'2004'!C7,'2005'!C7,'2006'!C7,'2007'!C7,'2008'!C7,'2009'!C7,'2010'!C7,'2011'!C7,'2012'!C7,'2013'!C7,'2014'!C7,'2015'!C7,'2016'!C7,'2017'!C7,'2018'!C7,'2019'!C7,'2020'!C7,'2021'!C7,'2022'!C7,'2023'!C7,'2024'!C7,'2025'!C7) | D7: =AVERAGE('1940'!D7,'1941'!D7,'1942'!D7,'1943'!D7,'1944'!D7,'1945'!D7,'1946'!D7,'1947'!D7,'1948'!D7,'1949'!D7,'1950'!D7,'1951'!D7,'1952'!D7,'1953'!D7,'1954'!D7,'1955'!D7,'1956'!D7,'1957'!D7,'1958'!D7,'1959'!D7,'1960'!D7,'1961'!D7,'1962'!D7,'1963'!D7,'1964'!D7,'1965'!D7,'1966'!D7,'1967'!D7,'1968'!D7,'1969'!D7,'1970'!D7,'1971'!D7,'1972'!D7,'1973'!D7,'1974'!D7,'1975'!D7,'1976'!D7,'1977'!D7,'1978'!D7,'1979'!D7,'1980'!D7,'1981'!D7,'1982'!D7,'1983'!D7,'1984'!D7,'1985'!D7,'1986'!D7,'1987'!D7,'1988'!D7,'1989'!D7,'1990'!D7,'1991'!D7,'1992'!D7,'1993'!D7,'1994'!D7,'1995'!D7,'1996'!D7,'1997'!D7,'1998'!D7,'1999'!D7,'2000'!D7,'2001'!D7,'2002'!D7,'2003'!D7,'2004'!D7,'2005'!D7,'2006'!D7,'2007'!D7,'2008'!D7,'2009'!D7,'2010'!D7,'2011'!D7,'2012'!D7,'2013'!D7,'2014'!D7,'2015'!D7,'2016'!D7,'2017'!D7,'2018'!D7,'2019'!D7,'2020'!D7,'2021'!D7,'2022'!D7,'2023'!D7,'2024'!D7,'2025'!D7) | E7: =AVERAGE('1940'!E7,'1941'!E7,'1942'!E7,'1943'!E7,'1944'!E7,'1945'!E7,'1946'!E7,'1947'!E7,'1948'!E7,'1949'!E7,'1950'!E7,'1951'!E7,'1952'!E7,'1953'!E7,'1954'!E7,'1955'!E7,'1956'!E7,'1957'!E7,'1958'!E7,'1959'!E7,'1960'!E7,'1961'!E7,'1962'!E7,'1963'!E7,'1964'!E7,'1965'!E7,'1966'!E7,'1967'!E7,'1968'!E7,'1969'!E7,'1970'!E7,'1971'!E7,'1972'!E7,'1973'!E7,'1974'!E7,'1975'!E7,'1976'!E7,'1977'!E7,'1978'!E7,'1979'!E7,'1980'!E7,'1981'!E7,'1982'!E7,'1983'!E7,'1984'!E7,'1985'!E7,'1986'!E7,'1987'!E7,'1988'!E7,'1989'!E7,'1990'!E7,'1991'!E7,'1992'!E7,'1993'!E7,'1994'!E7,'1995'!E7,'1996'!E7,'1997'!E7,'1998'!E7,'1999'!E7,'2000'!E7,'2001'!E7,'2002'!E7,'2003'!E7,'2004'!E7,'2005'!E7,'2006'!E7,'2007'!E7,'2008'!E7,'2009'!E7,'2010'!E7,'2011'!E7,'2012'!E7,'2013'!E7,'2014'!E7,'2015'!E7,'2016'!E7,'2017'!E7,'2018'!E7,'2019'!E7,'2020'!E7,'2021'!E7,'2022'!E7,'2023'!E7,'2024'!E7,'2025'!E7) | F7: =AVERAGE('1940'!F7,'1941'!F7,'1942'!F7,'1943'!F7,'1944'!F7,'1945'!F7,'1946'!F7,'1947'!F7,'1948'!F7,'1949'!F7,'1950'!F7,'1951'!F7,'1952'!F7,'1953'!F7,'1954'!F7,'1955'!F7,'1956'!F7,'1957'!F7,'1958'!F7,'1959'!F7,'1960'!F7,'1961'!F7,'1962'!F7,'1963'!F7,'1964'!F7,'1965'!F7,'1966'!F7,'1967'!F7,'1968'!F7,'1969'!F7,'1970'!F7,'1971'!F7,'1972'!F7,'1973'!F7,'1974'!F7,'1975'!F7,'1976'!F7,'1977'!F7,'1978'!F7,'1979'!F7,'1980'!F7,'1981'!F7,'1982'!F7,'1983'!F7,'1984'!F7,'1985'!F7,'1986'!F7,'1987'!F7,'1988'!F7,'1989'!F7,'1990'!F7,'1991'!F7,'1992'!F7,'1993'!F7,'1994'!F7,'1995'!F7,'1996'!F7,'1997'!F7,'1998'!F7,'1999'!F7,'2000'!F7,'2001'!F7,'2002'!F7,'2003'!F7,'2004'!F7,'2005'!F7,'2006'!F7,'2007'!F7,'2008'!F7,'2009'!F7,'2010'!F7,'2011'!F7,'2012'!F7,'2013'!F7,'2014'!F7,'2015'!F7,'2016'!F7,'2017'!F7,'2018'!F7,'2019'!F7,'2020'!F7,'2021'!F7,'2022'!F7,'2023'!F7,'2024'!F7,'2025'!F7) | G7: =AVERAGE('1940'!G7,'1941'!G7,'1942'!G7,'1943'!G7,'1944'!G7,'1945'!G7,'1946'!G7,'1947'!G7,'1948'!G7,'1949'!G7,'1950'!G7,'1951'!G7,'1952'!G7,'1953'!G7,'1954'!G7,'1955'!G7,'1956'!G7,'1957'!G7,'1958'!G7,'1959'!G7,'1960'!G7,'1961'!G7,'1962'!G7,'1963'!G7,'1964'!G7,'1965'!G7,'1966'!G7,'1967'!G7,'1968'!G7,'1969'!G7,'1970'!G7,'1971'!G7,'1972'!G7,'1973'!G7,'1974'!G7,'1975'!G7,'1976'!G7,'1977'!G7,'1978'!G7,'1979'!G7,'1980'!G7,'1981'!G7,'1982'!G7,'1983'!G7,'1984'!G7,'1985'!G7,'1986'!G7,'1987'!G7,'1988'!G7,'1989'!G7,'1990'!G7,'1991'!G7,'1992'!G7,'1993'!G7,'1994'!G7,'1995'!G7,'1996'!G7,'1997'!G7,'1998'!G7,'1999'!G7,'2000'!G7,'2001'!G7,'2002'!G7,'2003'!G7,'2004'!G7,'2005'!G7,'2006'!G7,'2007'!G7,'2008'!G7,'2009'!G7,'2010'!G7,'2011'!G7,'2012'!G7,'2013'!G7,'2014'!G7,'2015'!G7,'2016'!G7,'2017'!G7,'2018'!G7,'2019'!G7,'2020'!G7,'2021'!G7,'2022'!G7,'2023'!G7,'2024'!G7,'2025'!G7) | H7: =AVERAGE('1940'!H7,'1941'!H7,'1942'!H7,'1943'!H7,'1944'!H7,'1945'!H7,'1946'!H7,'1947'!H7,'1948'!H7,'1949'!H7,'1950'!H7,'1951'!H7,'1952'!H7,'1953'!H7,'1954'!H7,'1955'!H7,'1956'!H7,'1957'!H7,'1958'!H7,'1959'!H7,'1960'!H7,'1961'!H7,'1962'!H7,'1963'!H7,'1964'!H7,'1965'!H7,'1966'!H7,'1967'!H7,'1968'!H7,'1969'!H7,'1970'!H7,'1971'!H7,'1972'!H7,'1973'!H7,'1974'!H7,'1975'!H7,'1976'!H7,'1977'!H7,'1978'!H7,'1979'!H7,'1980'!H7,'1981'!H7,'1982'!H7,'1983'!H7,'1984'!H7,'1985'!H7,'1986'!H7,'1987'!H7,'1988'!H7,'1989'!H7,'1990'!H7,'1991'!H7,'1992'!H7,'1993'!H7,'1994'!H7,'1995'!H7,'1996'!H7,'1997'!H7,'1998'!H7,'1999'!H7,'2000'!H7,'2001'!H7,'2002'!H7,'2003'!H7,'2004'!H7,'2005'!H7,'2006'!H7,'2007'!H7,'2008'!H7,'2009'!H7,'2010'!H7,'2011'!H7,'2012'!H7,'2013'!H7,'2014'!H7,'2015'!H7,'2016'!H7,'2017'!H7,'2018'!H7,'2019'!H7,'2020'!H7,'2021'!H7,'2022'!H7,'2023'!H7,'2024'!H7,'2025'!H7) | I7: =AVERAGE('1940'!I7,'1941'!I7,'1942'!I7,'1943'!I7,'1944'!I7,'1945'!I7,'1946'!I7,'1947'!I7,'1948'!I7,'1949'!I7,'1950'!I7,'1951'!I7,'1952'!I7,'1953'!I7,'1954'!I7,'1955'!I7,'1956'!I7,'1957'!I7,'1958'!I7,'1959'!I7,'1960'!I7,'1961'!I7,'1962'!I7,'1963'!I7,'1964'!I7,'1965'!I7,'1966'!I7,'1967'!I7,'1968'!I7,'1969'!I7,'1970'!I7,'1971'!I7,'1972'!I7,'1973'!I7,'1974'!I7,'1975'!I7,'1976'!I7,'1977'!I7,'1978'!I7,'1979'!I7,'1980'!I7,'1981'!I7,'1982'!I7,'1983'!I7,'1984'!I7,'1985'!I7,'1986'!I7,'1987'!I7,'1988'!I7,'1989'!I7,'1990'!I7,'1991'!I7,'1992'!I7,'1993'!I7,'1994'!I7,'1995'!I7,'1996'!I7,'1997'!I7,'1998'!I7,'1999'!I7,'2000'!I7,'2001'!I7,'2002'!I7,'2003'!I7,'2004'!I7,'2005'!I7,'2006'!I7,'2007'!I7,'2008'!I7,'2009'!I7,'2010'!I7,'2011'!I7,'2012'!I7,'2013'!I7,'2014'!I7,'2015'!I7,'2016'!I7,'2017'!I7,'2018'!I7,'2019'!I7,'2020'!I7,'2021'!I7,'2022'!I7,'2023'!I7,'2024'!I7,'2025'!I7) | ... M7: =AVERAGE('1940'!M7,'1941'!M7,'1942'!M7,'1943'!M7,'1944'!M7,'1945'!M7,'1946'!M7,'1947'!M7,'1948'!M7,'1949'!M7,'1950'!M7,'1951'!M7,'1952'!M7,'1953'!M7,'1954'!M7,'1955'!M7,'1956'!M7,'1957'!M7,'1958'!M7,'1959'!M7,'1960'!M7,'1961'!M7,'1962'!M7,'1963'!M7,'1964'!M7,'1965'!M7,'1966'!M7,'1967'!M7,'1968'!M7,'1969'!M7,'1970'!M7,'1971'!M7,'1972'!M7,'1973'!M7,'1974'!M7,'1975'!M7,'1976'!M7,'1977'!M7,'1978'!M7,'1979'!M7,'1980'!M7,'1981'!M7,'1982'!M7,'1983'!M7,'1984'!M7,'1985'!M7,'1986'!M7,'1987'!M7,'1988'!M7,'1989'!M7,'1990'!M7,'1991'!M7,'1992'!M7,'1993'!M7,'1994'!M7,'1995'!M7,'1996'!M7,'1997'!M7,'1998'!M7,'1999'!M7,'2000'!M7,'2001'!M7,'2002'!M7,'2003'!M7,'2004'!M7,'2005'!M7,'2006'!M7,'2007'!M7,'2008'!M7,'2009'!M7,'2010'!M7,'2011'!M7,'2012'!M7,'2013'!M7,'2014'!M7,'2015'!M7,'2016'!M7,'2017'!M7,'2018'!M7,'2019'!M7,'2020'!M7,'2021'!M7,'2022'!M7,'2023'!M7,'2024'!M7,'2025'!M7) | N7: =AVERAGE(B7:M7)
A8: Srednja minimalna | B8: =AVERAGE('1940'!B8,'1941'!B8,'1942'!B8,'1943'!B8,'1944'!B8,'1945'!B8,'1946'!B8,'1947'!B8,'1948'!B8,'1949'!B8,'1950'!B8,'1951'!B8,'1952'!B8,'1953'!B8,'1954'!B8,'1955'!B8,'1956'!B8,'1957'!B8,'1958'!B8,'1959'!B8,'1960'!B8,'1961'!B8,'1962'!B8,'1963'!B8,'1964'!B8,'1965'!B8,'1966'!B8,'1967'!B8,'1968'!B8,'1969'!B8,'1970'!B8,'1971'!B8,'1972'!B8,'1973'!B8,'1974'!B8,'1975'!B8,'1976'!B8,'1977'!B8,'1978'!B8,'1979'!B8,'1980'!B8,'1981'!B8,'1982'!B8,'1983'!B8,'1984'!B8,'1985'!B8,'1986'!B8,'1987'!B8,'1988'!B8,'1989'!B8,'1990'!B8,'1991'!B8,'1992'!B8,'1993'!B8,'1994'!B8,'1995'!B8,'1996'!B8,'1997'!B8,'1998'!B8,'1999'!B8,'2000'!B8,'2001'!B8,'2002'!B8,'2003'!B8,'2004'!B8,'2005'!B8,'2006'!B8,'2007'!B8,'2008'!B8,'2009'!B8,'2010'!B8,'2011'!B8,'2012'!B8,'2013'!B8,'2014'!B8,'2015'!B8,'2016'!B8,'2017'!B8,'2018'!B8,'2019'!B8,'2020'!B8,'2021'!B8,'2022'!B8,'2023'!B8,'2024'!B8,'2025'!B8) | C8: =AVERAGE('1940'!C8,'1941'!C8,'1942'!C8,'1943'!C8,'1944'!C8,'1945'!C8,'1946'!C8,'1947'!C8,'1948'!C8,'1949'!C8,'1950'!C8,'1951'!C8,'1952'!C8,'1953'!C8,'1954'!C8,'1955'!C8,'1956'!C8,'1957'!C8,'1958'!C8,'1959'!C8,'1960'!C8,'1961'!C8,'1962'!C8,'1963'!C8,'1964'!C8,'1965'!C8,'1966'!C8,'1967'!C8,'1968'!C8,'1969'!C8,'1970'!C8,'1971'!C8,'1972'!C8,'1973'!C8,'1974'!C8,'1975'!C8,'1976'!C8,'1977'!C8,'1978'!C8,'1979'!C8,'1980'!C8,'1981'!C8,'1982'!C8,'1983'!C8,'1984'!C8,'1985'!C8,'1986'!C8,'1987'!C8,'1988'!C8,'1989'!C8,'1990'!C8,'1991'!C8,'1992'!C8,'1993'!C8,'1994'!C8,'1995'!C8,'1996'!C8,'1997'!C8,'1998'!C8,'1999'!C8,'2000'!C8,'2001'!C8,'2002'!C8,'2003'!C8,'2004'!C8,'2005'!C8,'2006'!C8,'2007'!C8,'2008'!C8,'2009'!C8,'2010'!C8,'2011'!C8,'2012'!C8,'2013'!C8,'2014'!C8,'2015'!C8,'2016'!C8,'2017'!C8,'2018'!C8,'2019'!C8,'2020'!C8,'2021'!C8,'2022'!C8,'2023'!C8,'2024'!C8,'2025'!C8) | D8: =AVERAGE('1940'!D8,'1941'!D8,'1942'!D8,'1943'!D8,'1944'!D8,'1945'!D8,'1946'!D8,'1947'!D8,'1948'!D8,'1949'!D8,'1950'!D8,'1951'!D8,'1952'!D8,'1953'!D8,'1954'!D8,'1955'!D8,'1956'!D8,'1957'!D8,'1958'!D8,'1959'!D8,'1960'!D8,'1961'!D8,'1962'!D8,'1963'!D8,'1964'!D8,'1965'!D8,'1966'!D8,'1967'!D8,'1968'!D8,'1969'!D8,'1970'!D8,'1971'!D8,'1972'!D8,'1973'!D8,'1974'!D8,'1975'!D8,'1976'!D8,'1977'!D8,'1978'!D8,'1979'!D8,'1980'!D8,'1981'!D8,'1982'!D8,'1983'!D8,'1984'!D8,'1985'!D8,'1986'!D8,'1987'!D8,'1988'!D8,'1989'!D8,'1990'!D8,'1991'!D8,'1992'!D8,'1993'!D8,'1994'!D8,'1995'!D8,'1996'!D8,'1997'!D8,'1998'!D8,'1999'!D8,'2000'!D8,'2001'!D8,'2002'!D8,'2003'!D8,'2004'!D8,'2005'!D8,'2006'!D8,'2007'!D8,'2008'!D8,'2009'!D8,'2010'!D8,'2011'!D8,'2012'!D8,'2013'!D8,'2014'!D8,'2015'!D8,'2016'!D8,'2017'!D8,'2018'!D8,'2019'!D8,'2020'!D8,'2021'!D8,'2022'!D8,'2023'!D8,'2024'!D8,'2025'!D8) | E8: =AVERAGE('1940'!E8,'1941'!E8,'1942'!E8,'1943'!E8,'1944'!E8,'1945'!E8,'1946'!E8,'1947'!E8,'1948'!E8,'1949'!E8,'1950'!E8,'1951'!E8,'1952'!E8,'1953'!E8,'1954'!E8,'1955'!E8,'1956'!E8,'1957'!E8,'1958'!E8,'1959'!E8,'1960'!E8,'1961'!E8,'1962'!E8,'1963'!E8,'1964'!E8,'1965'!E8,'1966'!E8,'1967'!E8,'1968'!E8,'1969'!E8,'1970'!E8,'1971'!E8,'1972'!E8,'1973'!E8,'1974'!E8,'1975'!E8,'1976'!E8,'1977'!E8,'1978'!E8,'1979'!E8,'1980'!E8,'1981'!E8,'1982'!E8,'1983'!E8,'1984'!E8,'1985'!E8,'1986'!E8,'1987'!E8,'1988'!E8,'1989'!E8,'1990'!E8,'1991'!E8,'1992'!E8,'1993'!E8,'1994'!E8,'1995'!E8,'1996'!E8,'1997'!E8,'1998'!E8,'1999'!E8,'2000'!E8,'2001'!E8,'2002'!E8,'2003'!E8,'2004'!E8,'2005'!E8,'2006'!E8,'2007'!E8,'2008'!E8,'2009'!E8,'2010'!E8,'2011'!E8,'2012'!E8,'2013'!E8,'2014'!E8,'2015'!E8,'2016'!E8,'2017'!E8,'2018'!E8,'2019'!E8,'2020'!E8,'2021'!E8,'2022'!E8,'2023'!E8,'2024'!E8,'2025'!E8) | F8: =AVERAGE('1940'!F8,'1941'!F8,'1942'!F8,'1943'!F8,'1944'!F8,'1945'!F8,'1946'!F8,'1947'!F8,'1948'!F8,'1949'!F8,'1950'!F8,'1951'!F8,'1952'!F8,'1953'!F8,'1954'!F8,'1955'!F8,'1956'!F8,'1957'!F8,'1958'!F8,'1959'!F8,'1960'!F8,'1961'!F8,'1962'!F8,'1963'!F8,'1964'!F8,'1965'!F8,'1966'!F8,'1967'!F8,'1968'!F8,'1969'!F8,'1970'!F8,'1971'!F8,'1972'!F8,'1973'!F8,'1974'!F8,'1975'!F8,'1976'!F8,'1977'!F8,'1978'!F8,'1979'!F8,'1980'!F8,'1981'!F8,'1982'!F8,'1983'!F8,'1984'!F8,'1985'!F8,'1986'!F8,'1987'!F8,'1988'!F8,'1989'!F8,'1990'!F8,'1991'!F8,'1992'!F8,'1993'!F8,'1994'!F8,'1995'!F8,'1996'!F8,'1997'!F8,'1998'!F8,'1999'!F8,'2000'!F8,'2001'!F8,'2002'!F8,'2003'!F8,'2004'!F8,'2005'!F8,'2006'!F8,'2007'!F8,'2008'!F8,'2009'!F8,'2010'!F8,'2011'!F8,'2012'!F8,'2013'!F8,'2014'!F8,'2015'!F8,'2016'!F8,'2017'!F8,'2018'!F8,'2019'!F8,'2020'!F8,'2021'!F8,'2022'!F8,'2023'!F8,'2024'!F8,'2025'!F8) | G8: =AVERAGE('1940'!G8,'1941'!G8,'1942'!G8,'1943'!G8,'1944'!G8,'1945'!G8,'1946'!G8,'1947'!G8,'1948'!G8,'1949'!G8,'1950'!G8,'1951'!G8,'1952'!G8,'1953'!G8,'1954'!G8,'1955'!G8,'1956'!G8,'1957'!G8,'1958'!G8,'1959'!G8,'1960'!G8,'1961'!G8,'1962'!G8,'1963'!G8,'1964'!G8,'1965'!G8,'1966'!G8,'1967'!G8,'1968'!G8,'1969'!G8,'1970'!G8,'1971'!G8,'1972'!G8,'1973'!G8,'1974'!G8,'1975'!G8,'1976'!G8,'1977'!G8,'1978'!G8,'1979'!G8,'1980'!G8,'1981'!G8,'1982'!G8,'1983'!G8,'1984'!G8,'1985'!G8,'1986'!G8,'1987'!G8,'1988'!G8,'1989'!G8,'1990'!G8,'1991'!G8,'1992'!G8,'1993'!G8,'1994'!G8,'1995'!G8,'1996'!G8,'1997'!G8,'1998'!G8,'1999'!G8,'2000'!G8,'2001'!G8,'2002'!G8,'2003'!G8,'2004'!G8,'2005'!G8,'2006'!G8,'2007'!G8,'2008'!G8,'2009'!G8,'2010'!G8,'2011'!G8,'2012'!G8,'2013'!G8,'2014'!G8,'2015'!G8,'2016'!G8,'2017'!G8,'2018'!G8,'2019'!G8,'2020'!G8,'2021'!G8,'2022'!G8,'2023'!G8,'2024'!G8,'2025'!G8) | H8: =AVERAGE('1940'!H8,'1941'!H8,'1942'!H8,'1943'!H8,'1944'!H8,'1945'!H8,'1946'!H8,'1947'!H8,'1948'!H8,'1949'!H8,'1950'!H8,'1951'!H8,'1952'!H8,'1953'!H8,'1954'!H8,'1955'!H8,'1956'!H8,'1957'!H8,'1958'!H8,'1959'!H8,'1960'!H8,'1961'!H8,'1962'!H8,'1963'!H8,'1964'!H8,'1965'!H8,'1966'!H8,'1967'!H8,'1968'!H8,'1969'!H8,'1970'!H8,'1971'!H8,'1972'!H8,'1973'!H8,'1974'!H8,'1975'!H8,'1976'!H8,'1977'!H8,'1978'!H8,'1979'!H8,'1980'!H8,'1981'!H8,'1982'!H8,'1983'!H8,'1984'!H8,'1985'!H8,'1986'!H8,'1987'!H8,'1988'!H8,'1989'!H8,'1990'!H8,'1991'!H8,'1992'!H8,'1993'!H8,'1994'!H8,'1995'!H8,'1996'!H8,'1997'!H8,'1998'!H8,'1999'!H8,'2000'!H8,'2001'!H8,'2002'!H8,'2003'!H8,'2004'!H8,'2005'!H8,'2006'!H8,'2007'!H8,'2008'!H8,'2009'!H8,'2010'!H8,'2011'!H8,'2012'!H8,'2013'!H8,'2014'!H8,'2015'!H8,'2016'!H8,'2017'!H8,'2018'!H8,'2019'!H8,'2020'!H8,'2021'!H8,'2022'!H8,'2023'!H8,'2024'!H8,'2025'!H8) | I8: =AVERAGE('1940'!I8,'1941'!I8,'1942'!I8,'1943'!I8,'1944'!I8,'1945'!I8,'1946'!I8,'1947'!I8,'1948'!I8,'1949'!I8,'1950'!I8,'1951'!I8,'1952'!I8,'1953'!I8,'1954'!I8,'1955'!I8,'1956'!I8,'1957'!I8,'1958'!I8,'1959'!I8,'1960'!I8,'1961'!I8,'1962'!I8,'1963'!I8,'1964'!I8,'1965'!I8,'1966'!I8,'1967'!I8,'1968'!I8,'1969'!I8,'1970'!I8,'1971'!I8,'1972'!I8,'1973'!I8,'1974'!I8,'1975'!I8,'1976'!I8,'1977'!I8,'1978'!I8,'1979'!I8,'1980'!I8,'1981'!I8,'1982'!I8,'1983'!I8,'1984'!I8,'1985'!I8,'1986'!I8,'1987'!I8,'1988'!I8,'1989'!I8,'1990'!I8,'1991'!I8,'1992'!I8,'1993'!I8,'1994'!I8,'1995'!I8,'1996'!I8,'1997'!I8,'1998'!I8,'1999'!I8,'2000'!I8,'2001'!I8,'2002'!I8,'2003'!I8,'2004'!I8,'2005'!I8,'2006'!I8,'2007'!I8,'2008'!I8,'2009'!I8,'2010'!I8,'2011'!I8,'2012'!I8,'2013'!I8,'2014'!I8,'2015'!I8,'2016'!I8,'2017'!I8,'2018'!I8,'2019'!I8,'2020'!I8,'2021'!I8,'2022'!I8,'2023'!I8,'2024'!I8,'2025'!I8) | ... M8: =AVERAGE('1940'!M8,'1941'!M8,'1942'!M8,'1943'!M8,'1944'!M8,'1945'!M8,'1946'!M8,'1947'!M8,'1948'!M8,'1949'!M8,'1950'!M8,'1951'!M8,'1952'!M8,'1953'!M8,'1954'!M8,'1955'!M8,'1956'!M8,'1957'!M8,'1958'!M8,'1959'!M8,'1960'!M8,'1961'!M8,'1962'!M8,'1963'!M8,'1964'!M8,'1965'!M8,'1966'!M8,'1967'!M8,'1968'!M8,'1969'!M8,'1970'!M8,'1971'!M8,'1972'!M8,'1973'!M8,'1974'!M8,'1975'!M8,'1976'!M8,'1977'!M8,'1978'!M8,'1979'!M8,'1980'!M8,'1981'!M8,'1982'!M8,'1983'!M8,'1984'!M8,'1985'!M8,'1986'!M8,'1987'!M8,'1988'!M8,'1989'!M8,'1990'!M8,'1991'!M8,'1992'!M8,'1993'!M8,'1994'!M8,'1995'!M8,'1996'!M8,'1997'!M8,'1998'!M8,'1999'!M8,'2000'!M8,'2001'!M8,'2002'!M8,'2003'!M8,'2004'!M8,'2005'!M8,'2006'!M8,'2007'!M8,'2008'!M8,'2009'!M8,'2010'!M8,'2011'!M8,'2012'!M8,'2013'!M8,'2014'!M8,'2015'!M8,'2016'!M8,'2017'!M8,'2018'!M8,'2019'!M8,'2020'!M8,'2021'!M8,'2022'!M8,'2023'!M8,'2024'!M8,'2025'!M8) | N8: =AVERAGE(B8:M8)
A9: Apsolutni maksimum | B9: =AVERAGE('1940'!B9,'1941'!B9,'1942'!B9,'1943'!B9,'1944'!B9,'1945'!B9,'1946'!B9,'1947'!B9,'1948'!B9,'1949'!B9,'1950'!B9,'1951'!B9,'1952'!B9,'1953'!B9,'1954'!B9,'1955'!B9,'1956'!B9,'1957'!B9,'1958'!B9,'1959'!B9,'1960'!B9,'1961'!B9,'1962'!B9,'1963'!B9,'1964'!B9,'1965'!B9,'1966'!B9,'1967'!B9,'1968'!B9,'1969'!B9,'1970'!B9,'1971'!B9,'1972'!B9,'1973'!B9,'1974'!B9,'1975'!B9,'1976'!B9,'1977'!B9,'1978'!B9,'1979'!B9,'1980'!B9,'1981'!B9,'1982'!B9,'1983'!B9,'1984'!B9,'1985'!B9,'1986'!B9,'1987'!B9,'1988'!B9,'1989'!B9,'1990'!B9,'1991'!B9,'1992'!B9,'1993'!B9,'1994'!B9,'1995'!B9,'1996'!B9,'1997'!B9,'1998'!B9,'1999'!B9,'2000'!B9,'2001'!B9,'2002'!B9,'2003'!B9,'2004'!B9,'2005'!B9,'2006'!B9,'2007'!B9,'2008'!B9,'2009'!B9,'2010'!B9,'2011'!B9,'2012'!B9,'2013'!B9,'2014'!B9,'2015'!B9,'2016'!B9,'2017'!B9,'2018'!B9,'2019'!B9,'2020'!B9,'2021'!B9,'2022'!B9,'2023'!B9,'2024'!B9,'2025'!B9) | C9: =AVERAGE('1940'!C9,'1941'!C9,'1942'!C9,'1943'!C9,'1944'!C9,'1945'!C9,'1946'!C9,'1947'!C9,'1948'!C9,'1949'!C9,'1950'!C9,'1951'!C9,'1952'!C9,'1953'!C9,'1954'!C9,'1955'!C9,'1956'!C9,'1957'!C9,'1958'!C9,'1959'!C9,'1960'!C9,'1961'!C9,'1962'!C9,'1963'!C9,'1964'!C9,'1965'!C9,'1966'!C9,'1967'!C9,'1968'!C9,'1969'!C9,'1970'!C9,'1971'!C9,'1972'!C9,'1973'!C9,'1974'!C9,'1975'!C9,'1976'!C9,'1977'!C9,'1978'!C9,'1979'!C9,'1980'!C9,'1981'!C9,'1982'!C9,'1983'!C9,'1984'!C9,'1985'!C9,'1986'!C9,'1987'!C9,'1988'!C9,'1989'!C9,'1990'!C9,'1991'!C9,'1992'!C9,'1993'!C9,'1994'!C9,'1995'!C9,'1996'!C9,'1997'!C9,'1998'!C9,'1999'!C9,'2000'!C9,'2001'!C9,'2002'!C9,'2003'!C9,'2004'!C9,'2005'!C9,'2006'!C9,'2007'!C9,'2008'!C9,'2009'!C9,'2010'!C9,'2011'!C9,'2012'!C9,'2013'!C9,'2014'!C9,'2015'!C9,'2016'!C9,'2017'!C9,'2018'!C9,'2019'!C9,'2020'!C9,'2021'!C9,'2022'!C9,'2023'!C9,'2024'!C9,'2025'!C9) | D9: =AVERAGE('1940'!D9,'1941'!D9,'1942'!D9,'1943'!D9,'1944'!D9,'1945'!D9,'1946'!D9,'1947'!D9,'1948'!D9,'1949'!D9,'1950'!D9,'1951'!D9,'1952'!D9,'1953'!D9,'1954'!D9,'1955'!D9,'1956'!D9,'1957'!D9,'1958'!D9,'1959'!D9,'1960'!D9,'1961'!D9,'1962'!D9,'1963'!D9,'1964'!D9,'1965'!D9,'1966'!D9,'1967'!D9,'1968'!D9,'1969'!D9,'1970'!D9,'1971'!D9,'1972'!D9,'1973'!D9,'1974'!D9,'1975'!D9,'1976'!D9,'1977'!D9,'1978'!D9,'1979'!D9,'1980'!D9,'1981'!D9,'1982'!D9,'1983'!D9,'1984'!D9,'1985'!D9,'1986'!D9,'1987'!D9,'1988'!D9,'1989'!D9,'1990'!D9,'1991'!D9,'1992'!D9,'1993'!D9,'1994'!D9,'1995'!D9,'1996'!D9,'1997'!D9,'1998'!D9,'1999'!D9,'2000'!D9,'2001'!D9,'2002'!D9,'2003'!D9,'2004'!D9,'2005'!D9,'2006'!D9,'2007'!D9,'2008'!D9,'2009'!D9,'2010'!D9,'2011'!D9,'2012'!D9,'2013'!D9,'2014'!D9,'2015'!D9,'2016'!D9,'2017'!D9,'2018'!D9,'2019'!D9,'2020'!D9,'2021'!D9,'2022'!D9,'2023'!D9,'2024'!D9,'2025'!D9) | E9: =AVERAGE('1940'!E9,'1941'!E9,'1942'!E9,'1943'!E9,'1944'!E9,'1945'!E9,'1946'!E9,'1947'!E9,'1948'!E9,'1949'!E9,'1950'!E9,'1951'!E9,'1952'!E9,'1953'!E9,'1954'!E9,'1955'!E9,'1956'!E9,'1957'!E9,'1958'!E9,'1959'!E9,'1960'!E9,'1961'!E9,'1962'!E9,'1963'!E9,'1964'!E9,'1965'!E9,'1966'!E9,'1967'!E9,'1968'!E9,'1969'!E9,'1970'!E9,'1971'!E9,'1972'!E9,'1973'!E9,'1974'!E9,'1975'!E9,'1976'!E9,'1977'!E9,'1978'!E9,'1979'!E9,'1980'!E9,'1981'!E9,'1982'!E9,'1983'!E9,'1984'!E9,'1985'!E9,'1986'!E9,'1987'!E9,'1988'!E9,'1989'!E9,'1990'!E9,'1991'!E9,'1992'!E9,'1993'!E9,'1994'!E9,'1995'!E9,'1996'!E9,'1997'!E9,'1998'!E9,'1999'!E9,'2000'!E9,'2001'!E9,'2002'!E9,'2003'!E9,'2004'!E9,'2005'!E9,'2006'!E9,'2007'!E9,'2008'!E9,'2009'!E9,'2010'!E9,'2011'!E9,'2012'!E9,'2013'!E9,'2014'!E9,'2015'!E9,'2016'!E9,'2017'!E9,'2018'!E9,'2019'!E9,'2020'!E9,'2021'!E9,'2022'!E9,'2023'!E9,'2024'!E9,'2025'!E9) | F9: =AVERAGE('1940'!F9,'1941'!F9,'1942'!F9,'1943'!F9,'1944'!F9,'1945'!F9,'1946'!F9,'1947'!F9,'1948'!F9,'1949'!F9,'1950'!F9,'1951'!F9,'1952'!F9,'1953'!F9,'1954'!F9,'1955'!F9,'1956'!F9,'1957'!F9,'1958'!F9,'1959'!F9,'1960'!F9,'1961'!F9,'1962'!F9,'1963'!F9,'1964'!F9,'1965'!F9,'1966'!F9,'1967'!F9,'1968'!F9,'1969'!F9,'1970'!F9,'1971'!F9,'1972'!F9,'1973'!F9,'1974'!F9,'1975'!F9,'1976'!F9,'1977'!F9,'1978'!F9,'1979'!F9,'1980'!F9,'1981'!F9,'1982'!F9,'1983'!F9,'1984'!F9,'1985'!F9,'1986'!F9,'1987'!F9,'1988'!F9,'1989'!F9,'1990'!F9,'1991'!F9,'1992'!F9,'1993'!F9,'1994'!F9,'1995'!F9,'1996'!F9,'1997'!F9,'1998'!F9,'1999'!F9,'2000'!F9,'2001'!F9,'2002'!F9,'2003'!F9,'2004'!F9,'2005'!F9,'2006'!F9,'2007'!F9,'2008'!F9,'2009'!F9,'2010'!F9,'2011'!F9,'2012'!F9,'2013'!F9,'2014'!F9,'2015'!F9,'2016'!F9,'2017'!F9,'2018'!F9,'2019'!F9,'2020'!F9,'2021'!F9,'2022'!F9,'2023'!F9,'2024'!F9,'2025'!F9) | G9: =AVERAGE('1940'!G9,'1941'!G9,'1942'!G9,'1943'!G9,'1944'!G9,'1945'!G9,'1946'!G9,'1947'!G9,'1948'!G9,'1949'!G9,'1950'!G9,'1951'!G9,'1952'!G9,'1953'!G9,'1954'!G9,'1955'!G9,'1956'!G9,'1957'!G9,'1958'!G9,'1959'!G9,'1960'!G9,'1961'!G9,'1962'!G9,'1963'!G9,'1964'!G9,'1965'!G9,'1966'!G9,'1967'!G9,'1968'!G9,'1969'!G9,'1970'!G9,'1971'!G9,'1972'!G9,'1973'!G9,'1974'!G9,'1975'!G9,'1976'!G9,'1977'!G9,'1978'!G9,'1979'!G9,'1980'!G9,'1981'!G9,'1982'!G9,'1983'!G9,'1984'!G9,'1985'!G9,'1986'!G9,'1987'!G9,'1988'!G9,'1989'!G9,'1990'!G9,'1991'!G9,'1992'!G9,'1993'!G9,'1994'!G9,'1995'!G9,'1996'!G9,'1997'!G9,'1998'!G9,'1999'!G9,'2000'!G9,'2001'!G9,'2002'!G9,'2003'!G9,'2004'!G9,'2005'!G9,'2006'!G9,'2007'!G9,'2008'!G9,'2009'!G9,'2010'!G9,'2011'!G9,'2012'!G9,'2013'!G9,'2014'!G9,'2015'!G9,'2016'!G9,'2017'!G9,'2018'!G9,'2019'!G9,'2020'!G9,'2021'!G9,'2022'!G9,'2023'!G9,'2024'!G9,'2025'!G9) | H9: =AVERAGE('1940'!H9,'1941'!H9,'1942'!H9,'1943'!H9,'1944'!H9,'1945'!H9,'1946'!H9,'1947'!H9,'1948'!H9,'1949'!H9,'1950'!H9,'1951'!H9,'1952'!H9,'1953'!H9,'1954'!H9,'1955'!H9,'1956'!H9,'1957'!H9,'1958'!H9,'1959'!H9,'1960'!H9,'1961'!H9,'1962'!H9,'1963'!H9,'1964'!H9,'1965'!H9,'1966'!H9,'1967'!H9,'1968'!H9,'1969'!H9,'1970'!H9,'1971'!H9,'1972'!H9,'1973'!H9,'1974'!H9,'1975'!H9,'1976'!H9,'1977'!H9,'1978'!H9,'1979'!H9,'1980'!H9,'1981'!H9,'1982'!H9,'1983'!H9,'1984'!H9,'1985'!H9,'1986'!H9,'1987'!H9,'1988'!H9,'1989'!H9,'1990'!H9,'1991'!H9,'1992'!H9,'1993'!H9,'1994'!H9,'1995'!H9,'1996'!H9,'1997'!H9,'1998'!H9,'1999'!H9,'2000'!H9,'2001'!H9,'2002'!H9,'2003'!H9,'2004'!H9,'2005'!H9,'2006'!H9,'2007'!H9,'2008'!H9,'2009'!H9,'2010'!H9,'2011'!H9,'2012'!H9,'2013'!H9,'2014'!H9,'2015'!H9,'2016'!H9,'2017'!H9,'2018'!H9,'2019'!H9,'2020'!H9,'2021'!H9,'2022'!H9,'2023'!H9,'2024'!H9,'2025'!H9) | I9: =AVERAGE('1940'!I9,'1941'!I9,'1942'!I9,'1943'!I9,'1944'!I9,'1945'!I9,'1946'!I9,'1947'!I9,'1948'!I9,'1949'!I9,'1950'!I9,'1951'!I9,'1952'!I9,'1953'!I9,'1954'!I9,'1955'!I9,'1956'!I9,'1957'!I9,'1958'!I9,'1959'!I9,'1960'!I9,'1961'!I9,'1962'!I9,'1963'!I9,'1964'!I9,'1965'!I9,'1966'!I9,'1967'!I9,'1968'!I9,'1969'!I9,'1970'!I9,'1971'!I9,'1972'!I9,'1973'!I9,'1974'!I9,'1975'!I9,'1976'!I9,'1977'!I9,'1978'!I9,'1979'!I9,'1980'!I9,'1981'!I9,'1982'!I9,'1983'!I9,'1984'!I9,'1985'!I9,'1986'!I9,'1987'!I9,'1988'!I9,'1989'!I9,'1990'!I9,'1991'!I9,'1992'!I9,'1993'!I9,'1994'!I9,'1995'!I9,'1996'!I9,'1997'!I9,'1998'!I9,'1999'!I9,'2000'!I9,'2001'!I9,'2002'!I9,'2003'!I9,'2004'!I9,'2005'!I9,'2006'!I9,'2007'!I9,'2008'!I9,'2009'!I9,'2010'!I9,'2011'!I9,'2012'!I9,'2013'!I9,'2014'!I9,'2015'!I9,'2016'!I9,'2017'!I9,'2018'!I9,'2019'!I9,'2020'!I9,'2021'!I9,'2022'!I9,'2023'!I9,'2024'!I9,'2025'!I9) | ... M9: =AVERAGE('1940'!M9,'1941'!M9,'1942'!M9,'1943'!M9,'1944'!M9,'1945'!M9,'1946'!M9,'1947'!M9,'1948'!M9,'1949'!M9,'1950'!M9,'1951'!M9,'1952'!M9,'1953'!M9,'1954'!M9,'1955'!M9,'1956'!M9,'1957'!M9,'1958'!M9,'1959'!M9,'1960'!M9,'1961'!M9,'1962'!M9,'1963'!M9,'1964'!M9,'1965'!M9,'1966'!M9,'1967'!M9,'1968'!M9,'1969'!M9,'1970'!M9,'1971'!M9,'1972'!M9,'1973'!M9,'1974'!M9,'1975'!M9,'1976'!M9,'1977'!M9,'1978'!M9,'1979'!M9,'1980'!M9,'1981'!M9,'1982'!M9,'1983'!M9,'1984'!M9,'1985'!M9,'1986'!M9,'1987'!M9,'1988'!M9,'1989'!M9,'1990'!M9,'1991'!M9,'1992'!M9,'1993'!M9,'1994'!M9,'1995'!M9,'1996'!M9,'1997'!M9,'1998'!M9,'1999'!M9,'2000'!M9,'2001'!M9,'2002'!M9,'2003'!M9,'2004'!M9,'2005'!M9,'2006'!M9,'2007'!M9,'2008'!M9,'2009'!M9,'2010'!M9,'2011'!M9,'2012'!M9,'2013'!M9,'2014'!M9,'2015'!M9,'2016'!M9,'2017'!M9,'2018'!M9,'2019'!M9,'2020'!M9,'2021'!M9,'2022'!M9,'2023'!M9,'2024'!M9,'2025'!M9) | N9: =MAX(B9:M9)
A10: Apsolutni minimum | B10: =AVERAGE('1940'!B10,'1941'!B10,'1942'!B10,'1943'!B10,'1944'!B10,'1945'!B10,'1946'!B10,'1947'!B10,'1948'!B10,'1949'!B10,'1950'!B10,'1951'!B10,'1952'!B10,'1953'!B10,'1954'!B10,'1955'!B10,'1956'!B10,'1957'!B10,'1958'!B10,'1959'!B10,'1960'!B10,'1961'!B10,'1962'!B10,'1963'!B10,'1964'!B10,'1965'!B10,'1966'!B10,'1967'!B10,'1968'!B10,'1969'!B10,'1970'!B10,'1971'!B10,'1972'!B10,'1973'!B10,'1974'!B10,'1975'!B10,'1976'!B10,'1977'!B10,'1978'!B10,'1979'!B10,'1980'!B10,'1981'!B10,'1982'!B10,'1983'!B10,'1984'!B10,'1985'!B10,'1986'!B10,'1987'!B10,'1988'!B10,'1989'!B10,'1990'!B10,'1991'!B10,'1992'!B10,'1993'!B10,'1994'!B10,'1995'!B10,'1996'!B10,'1997'!B10,'1998'!B10,'1999'!B10,'2000'!B10,'2001'!B10,'2002'!B10,'2003'!B10,'2004'!B10,'2005'!B10,'2006'!B10,'2007'!B10,'2008'!B10,'2009'!B10,'2010'!B10,'2011'!B10,'2012'!B10,'2013'!B10,'2014'!B10,'2015'!B10,'2016'!B10,'2017'!B10,'2018'!B10,'2019'!B10,'2020'!B10,'2021'!B10,'2022'!B10,'2023'!B10,'2024'!B10,'2025'!B10) | C10: =AVERAGE('1940'!C10,'1941'!C10,'1942'!C10,'1943'!C10,'1944'!C10,'1945'!C10,'1946'!C10,'1947'!C10,'1948'!C10,'1949'!C10,'1950'!C10,'1951'!C10,'1952'!C10,'1953'!C10,'1954'!C10,'1955'!C10,'1956'!C10,'1957'!C10,'1958'!C10,'1959'!C10,'1960'!C10,'1961'!C10,'1962'!C10,'1963'!C10,'1964'!C10,'1965'!C10,'1966'!C10,'1967'!C10,'1968'!C10,'1969'!C10,'1970'!C10,'1971'!C10,'1972'!C10,'1973'!C10,'1974'!C10,'1975'!C10,'1976'!C10,'1977'!C10,'1978'!C10,'1979'!C10,'1980'!C10,'1981'!C10,'1982'!C10,'1983'!C10,'1984'!C10,'1985'!C10,'1986'!C10,'1987'!C10,'1988'!C10,'1989'!C10,'1990'!C10,'1991'!C10,'1992'!C10,'1993'!C10,'1994'!C10,'1995'!C10,'1996'!C10,'1997'!C10,'1998'!C10,'1999'!C10,'2000'!C10,'2001'!C10,'2002'!C10,'2003'!C10,'2004'!C10,'2005'!C10,'2006'!C10,'2007'!C10,'2008'!C10,'2009'!C10,'2010'!C10,'2011'!C10,'2012'!C10,'2013'!C10,'2014'!C10,'2015'!C10,'2016'!C10,'2017'!C10,'2018'!C10,'2019'!C10,'2020'!C10,'2021'!C10,'2022'!C10,'2023'!C10,'2024'!C10,'2025'!C10) | D10: =AVERAGE('1940'!D10,'1941'!D10,'1942'!D10,'1943'!D10,'1944'!D10,'1945'!D10,'1946'!D10,'1947'!D10,'1948'!D10,'1949'!D10,'1950'!D10,'1951'!D10,'1952'!D10,'1953'!D10,'1954'!D10,'1955'!D10,'1956'!D10,'1957'!D10,'1958'!D10,'1959'!D10,'1960'!D10,'1961'!D10,'1962'!D10,'1963'!D10,'1964'!D10,'1965'!D10,'1966'!D10,'1967'!D10,'1968'!D10,'1969'!D10,'1970'!D10,'1971'!D10,'1972'!D10,'1973'!D10,'1974'!D10,'1975'!D10,'1976'!D10,'1977'!D10,'1978'!D10,'1979'!D10,'1980'!D10,'1981'!D10,'1982'!D10,'1983'!D10,'1984'!D10,'1985'!D10,'1986'!D10,'1987'!D10,'1988'!D10,'1989'!D10,'1990'!D10,'1991'!D10,'1992'!D10,'1993'!D10,'1994'!D10,'1995'!D10,'1996'!D10,'1997'!D10,'1998'!D10,'1999'!D10,'2000'!D10,'2001'!D10,'2002'!D10,'2003'!D10,'2004'!D10,'2005'!D10,'2006'!D10,'2007'!D10,'2008'!D10,'2009'!D10,'2010'!D10,'2011'!D10,'2012'!D10,'2013'!D10,'2014'!D10,'2015'!D10,'2016'!D10,'2017'!D10,'2018'!D10,'2019'!D10,'2020'!D10,'2021'!D10,'2022'!D10,'2023'!D10,'2024'!D10,'2025'!D10) | E10: =AVERAGE('1940'!E10,'1941'!E10,'1942'!E10,'1943'!E10,'1944'!E10,'1945'!E10,'1946'!E10,'1947'!E10,'1948'!E10,'1949'!E10,'1950'!E10,'1951'!E10,'1952'!E10,'1953'!E10,'1954'!E10,'1955'!E10,'1956'!E10,'1957'!E10,'1958'!E10,'1959'!E10,'1960'!E10,'1961'!E10,'1962'!E10,'1963'!E10,'1964'!E10,'1965'!E10,'1966'!E10,'1967'!E10,'1968'!E10,'1969'!E10,'1970'!E10,'1971'!E10,'1972'!E10,'1973'!E10,'1974'!E10,'1975'!E10,'1976'!E10,'1977'!E10,'1978'!E10,'1979'!E10,'1980'!E10,'1981'!E10,'1982'!E10,'1983'!E10,'1984'!E10,'1985'!E10,'1986'!E10,'1987'!E10,'1988'!E10,'1989'!E10,'1990'!E10,'1991'!E10,'1992'!E10,'1993'!E10,'1994'!E10,'1995'!E10,'1996'!E10,'1997'!E10,'1998'!E10,'1999'!E10,'2000'!E10,'2001'!E10,'2002'!E10,'2003'!E10,'2004'!E10,'2005'!E10,'2006'!E10,'2007'!E10,'2008'!E10,'2009'!E10,'2010'!E10,'2011'!E10,'2012'!E10,'2013'!E10,'2014'!E10,'2015'!E10,'2016'!E10,'2017'!E10,'2018'!E10,'2019'!E10,'2020'!E10,'2021'!E10,'2022'!E10,'2023'!E10,'2024'!E10,'2025'!E10) | F10: =AVERAGE('1940'!F10,'1941'!F10,'1942'!F10,'1943'!F10,'1944'!F10,'1945'!F10,'1946'!F10,'1947'!F10,'1948'!F10,'1949'!F10,'1950'!F10,'1951'!F10,'1952'!F10,'1953'!F10,'1954'!F10,'1955'!F10,'1956'!F10,'1957'!F10,'1958'!F10,'1959'!F10,'1960'!F10,'1961'!F10,'1962'!F10,'1963'!F10,'1964'!F10,'1965'!F10,'1966'!F10,'1967'!F10,'1968'!F10,'1969'!F10,'1970'!F10,'1971'!F10,'1972'!F10,'1973'!F10,'1974'!F10,'1975'!F10,'1976'!F10,'1977'!F10,'1978'!F10,'1979'!F10,'1980'!F10,'1981'!F10,'1982'!F10,'1983'!F10,'1984'!F10,'1985'!F10,'1986'!F10,'1987'!F10,'1988'!F10,'1989'!F10,'1990'!F10,'1991'!F10,'1992'!F10,'1993'!F10,'1994'!F10,'1995'!F10,'1996'!F10,'1997'!F10,'1998'!F10,'1999'!F10,'2000'!F10,'2001'!F10,'2002'!F10,'2003'!F10,'2004'!F10,'2005'!F10,'2006'!F10,'2007'!F10,'2008'!F10,'2009'!F10,'2010'!F10,'2011'!F10,'2012'!F10,'2013'!F10,'2014'!F10,'2015'!F10,'2016'!F10,'2017'!F10,'2018'!F10,'2019'!F10,'2020'!F10,'2021'!F10,'2022'!F10,'2023'!F10,'2024'!F10,'2025'!F10) | G10: =AVERAGE('1940'!G10,'1941'!G10,'1942'!G10,'1943'!G10,'1944'!G10,'1945'!G10,'1946'!G10,'1947'!G10,'1948'!G10,'1949'!G10,'1950'!G10,'1951'!G10,'1952'!G10,'1953'!G10,'1954'!G10,'1955'!G10,'1956'!G10,'1957'!G10,'1958'!G10,'1959'!G10,'1960'!G10,'1961'!G10,'1962'!G10,'1963'!G10,'1964'!G10,'1965'!G10,'1966'!G10,'1967'!G10,'1968'!G10,'1969'!G10,'1970'!G10,'1971'!G10,'1972'!G10,'1973'!G10,'1974'!G10,'1975'!G10,'1976'!G10,'1977'!G10,'1978'!G10,'1979'!G10,'1980'!G10,'1981'!G10,'1982'!G10,'1983'!G10,'1984'!G10,'1985'!G10,'1986'!G10,'1987'!G10,'1988'!G10,'1989'!G10,'1990'!G10,'1991'!G10,'1992'!G10,'1993'!G10,'1994'!G10,'1995'!G10,'1996'!G10,'1997'!G10,'1998'!G10,'1999'!G10,'2000'!G10,'2001'!G10,'2002'!G10,'2003'!G10,'2004'!G10,'2005'!G10,'2006'!G10,'2007'!G10,'2008'!G10,'2009'!G10,'2010'!G10,'2011'!G10,'2012'!G10,'2013'!G10,'2014'!G10,'2015'!G10,'2016'!G10,'2017'!G10,'2018'!G10,'2019'!G10,'2020'!G10,'2021'!G10,'2022'!G10,'2023'!G10,'2024'!G10,'2025'!G10) | H10: =AVERAGE('1940'!H10,'1941'!H10,'1942'!H10,'1943'!H10,'1944'!H10,'1945'!H10,'1946'!H10,'1947'!H10,'1948'!H10,'1949'!H10,'1950'!H10,'1951'!H10,'1952'!H10,'1953'!H10,'1954'!H10,'1955'!H10,'1956'!H10,'1957'!H10,'1958'!H10,'1959'!H10,'1960'!H10,'1961'!H10,'1962'!H10,'1963'!H10,'1964'!H10,'1965'!H10,'1966'!H10,'1967'!H10,'1968'!H10,'1969'!H10,'1970'!H10,'1971'!H10,'1972'!H10,'1973'!H10,'1974'!H10,'1975'!H10,'1976'!H10,'1977'!H10,'1978'!H10,'1979'!H10,'1980'!H10,'1981'!H10,'1982'!H10,'1983'!H10,'1984'!H10,'1985'!H10,'1986'!H10,'1987'!H10,'1988'!H10,'1989'!H10,'1990'!H10,'1991'!H10,'1992'!H10,'1993'!H10,'1994'!H10,'1995'!H10,'1996'!H10,'1997'!H10,'1998'!H10,'1999'!H10,'2000'!H10,'2001'!H10,'2002'!H10,'2003'!H10,'2004'!H10,'2005'!H10,'2006'!H10,'2007'!H10,'2008'!H10,'2009'!H10,'2010'!H10,'2011'!H10,'2012'!H10,'2013'!H10,'2014'!H10,'2015'!H10,'2016'!H10,'2017'!H10,'2018'!H10,'2019'!H10,'2020'!H10,'2021'!H10,'2022'!H10,'2023'!H10,'2024'!H10,'2025'!H10) | I10: =AVERAGE('1940'!I10,'1941'!I10,'1942'!I10,'1943'!I10,'1944'!I10,'1945'!I10,'1946'!I10,'1947'!I10,'1948'!I10,'1949'!I10,'1950'!I10,'1951'!I10,'1952'!I10,'1953'!I10,'1954'!I10,'1955'!I10,'1956'!I10,'1957'!I10,'1958'!I10,'1959'!I10,'1960'!I10,'1961'!I10,'1962'!I10,'1963'!I10,'1964'!I10,'1965'!I10,'1966'!I10,'1967'!I10,'1968'!I10,'1969'!I10,'1970'!I10,'1971'!I10,'1972'!I10,'1973'!I10,'1974'!I10,'1975'!I10,'1976'!I10,'1977'!I10,'1978'!I10,'1979'!I10,'1980'!I10,'1981'!I10,'1982'!I10,'1983'!I10,'1984'!I10,'1985'!I10,'1986'!I10,'1987'!I10,'1988'!I10,'1989'!I10,'1990'!I10,'1991'!I10,'1992'!I10,'1993'!I10,'1994'!I10,'1995'!I10,'1996'!I10,'1997'!I10,'1998'!I10,'1999'!I10,'2000'!I10,'2001'!I10,'2002'!I10,'2003'!I10,'2004'!I10,'2005'!I10,'2006'!I10,'2007'!I10,'2008'!I10,'2009'!I10,'2010'!I10,'2011'!I10,'2012'!I10,'2013'!I10,'2014'!I10,'2015'!I10,'2016'!I10,'2017'!I10,'2018'!I10,'2019'!I10,'2020'!I10,'2021'!I10,'2022'!I10,'2023'!I10,'2024'!I10,'2025'!I10) | ... M10: =AVERAGE('1940'!M10,'1941'!M10,'1942'!M10,'1943'!M10,'1944'!M10,'1945'!M10,'1946'!M10,'1947'!M10,'1948'!M10,'1949'!M10,'1950'!M10,'1951'!M10,'1952'!M10,'1953'!M10,'1954'!M10,'1955'!M10,'1956'!M10,'1957'!M10,'1958'!M10,'1959'!M10,'1960'!M10,'1961'!M10,'1962'!M10,'1963'!M10,'1964'!M10,'1965'!M10,'1966'!M10,'1967'!M10,'1968'!M10,'1969'!M10,'1970'!M10,'1971'!M10,'1972'!M10,'1973'!M10,'1974'!M10,'1975'!M10,'1976'!M10,'1977'!M10,'1978'!M10,'1979'!M10,'1980'!M10,'1981'!M10,'1982'!M10,'1983'!M10,'1984'!M10,'1985'!M10,'1986'!M10,'1987'!M10,'1988'!M10,'1989'!M10,'1990'!M10,'1991'!M10,'1992'!M10,'1993'!M10,'1994'!M10,'1995'!M10,'1996'!M10,'1997'!M10,'1998'!M10,'1999'!M10,'2000'!M10,'2001'!M10,'2002'!M10,'2003'!M10,'2004'!M10,'2005'!M10,'2006'!M10,'2007'!M10,'2008'!M10,'2009'!M10,'2010'!M10,'2011'!M10,'2012'!M10,'2013'!M10,'2014'!M10,'2015'!M10,'2016'!M10,'2017'!M10,'2018'!M10,'2019'!M10,'2020'!M10,'2021'!M10,'2022'!M10,'2023'!M10,'2024'!M10,'2025'!M10) | N10: =MIN(B10:M10)
A11: Sr. br. mraznih dana | B11: =AVERAGE('1940'!B11,'1941'!B11,'1942'!B11,'1943'!B11,'1944'!B11,'1945'!B11,'1946'!B11,'1947'!B11,'1948'!B11,'1949'!B11,'1950'!B11,'1951'!B11,'1952'!B11,'1953'!B11,'1954'!B11,'1955'!B11,'1956'!B11,'1957'!B11,'1958'!B11,'1959'!B11,'1960'!B11,'1961'!B11,'1962'!B11,'1963'!B11,'1964'!B11,'1965'!B11,'1966'!B11,'1967'!B11,'1968'!B11,'1969'!B11,'1970'!B11,'1971'!B11,'1972'!B11,'1973'!B11,'1974'!B11,'1975'!B11,'1976'!B11,'1977'!B11,'1978'!B11,'1979'!B11,'1980'!B11,'1981'!B11,'1982'!B11,'1983'!B11,'1984'!B11,'1985'!B11,'1986'!B11,'1987'!B11,'1988'!B11,'1989'!B11,'1990'!B11,'1991'!B11,'1992'!B11,'1993'!B11,'1994'!B11,'1995'!B11,'1996'!B11,'1997'!B11,'1998'!B11,'1999'!B11,'2000'!B11,'2001'!B11,'2002'!B11,'2003'!B11,'2004'!B11,'2005'!B11,'2006'!B11,'2007'!B11,'2008'!B11,'2009'!B11,'2010'!B11,'2011'!B11,'2012'!B11,'2013'!B11,'2014'!B11,'2015'!B11,'2016'!B11,'2017'!B11,'2018'!B11,'2019'!B11,'2020'!B11,'2021'!B11,'2022'!B11,'2023'!B11,'2024'!B11,'2025'!B11) | C11: =AVERAGE('1940'!C11,'1941'!C11,'1942'!C11,'1943'!C11,'1944'!C11,'1945'!C11,'1946'!C11,'1947'!C11,'1948'!C11,'1949'!C11,'1950'!C11,'1951'!C11,'1952'!C11,'1953'!C11,'1954'!C11,'1955'!C11,'1956'!C11,'1957'!C11,'1958'!C11,'1959'!C11,'1960'!C11,'1961'!C11,'1962'!C11,'1963'!C11,'1964'!C11,'1965'!C11,'1966'!C11,'1967'!C11,'1968'!C11,'1969'!C11,'1970'!C11,'1971'!C11,'1972'!C11,'1973'!C11,'1974'!C11,'1975'!C11,'1976'!C11,'1977'!C11,'1978'!C11,'1979'!C11,'1980'!C11,'1981'!C11,'1982'!C11,'1983'!C11,'1984'!C11,'1985'!C11,'1986'!C11,'1987'!C11,'1988'!C11,'1989'!C11,'1990'!C11,'1991'!C11,'1992'!C11,'1993'!C11,'1994'!C11,'1995'!C11,'1996'!C11,'1997'!C11,'1998'!C11,'1999'!C11,'2000'!C11,'2001'!C11,'2002'!C11,'2003'!C11,'2004'!C11,'2005'!C11,'2006'!C11,'2007'!C11,'2008'!C11,'2009'!C11,'2010'!C11,'2011'!C11,'2012'!C11,'2013'!C11,'2014'!C11,'2015'!C11,'2016'!C11,'2017'!C11,'2018'!C11,'2019'!C11,'2020'!C11,'2021'!C11,'2022'!C11,'2023'!C11,'2024'!C11,'2025'!C11) | D11: =AVERAGE('1940'!D11,'1941'!D11,'1942'!D11,'1943'!D11,'1944'!D11,'1945'!D11,'1946'!D11,'1947'!D11,'1948'!D11,'1949'!D11,'1950'!D11,'1951'!D11,'1952'!D11,'1953'!D11,'1954'!D11,'1955'!D11,'1956'!D11,'1957'!D11,'1958'!D11,'1959'!D11,'1960'!D11,'1961'!D11,'1962'!D11,'1963'!D11,'1964'!D11,'1965'!D11,'1966'!D11,'1967'!D11,'1968'!D11,'1969'!D11,'1970'!D11,'1971'!D11,'1972'!D11,'1973'!D11,'1974'!D11,'1975'!D11,'1976'!D11,'1977'!D11,'1978'!D11,'1979'!D11,'1980'!D11,'1981'!D11,'1982'!D11,'1983'!D11,'1984'!D11,'1985'!D11,'1986'!D11,'1987'!D11,'1988'!D11,'1989'!D11,'1990'!D11,'1991'!D11,'1992'!D11,'1993'!D11,'1994'!D11,'1995'!D11,'1996'!D11,'1997'!D11,'1998'!D11,'1999'!D11,'2000'!D11,'2001'!D11,'2002'!D11,'2003'!D11,'2004'!D11,'2005'!D11,'2006'!D11,'2007'!D11,'2008'!D11,'2009'!D11,'2010'!D11,'2011'!D11,'2012'!D11,'2013'!D11,'2014'!D11,'2015'!D11,'2016'!D11,'2017'!D11,'2018'!D11,'2019'!D11,'2020'!D11,'2021'!D11,'2022'!D11,'2023'!D11,'2024'!D11,'2025'!D11) | E11: =AVERAGE('1940'!E11,'1941'!E11,'1942'!E11,'1943'!E11,'1944'!E11,'1945'!E11,'1946'!E11,'1947'!E11,'1948'!E11,'1949'!E11,'1950'!E11,'1951'!E11,'1952'!E11,'1953'!E11,'1954'!E11,'1955'!E11,'1956'!E11,'1957'!E11,'1958'!E11,'1959'!E11,'1960'!E11,'1961'!E11,'1962'!E11,'1963'!E11,'1964'!E11,'1965'!E11,'1966'!E11,'1967'!E11,'1968'!E11,'1969'!E11,'1970'!E11,'1971'!E11,'1972'!E11,'1973'!E11,'1974'!E11,'1975'!E11,'1976'!E11,'1977'!E11,'1978'!E11,'1979'!E11,'1980'!E11,'1981'!E11,'1982'!E11,'1983'!E11,'1984'!E11,'1985'!E11,'1986'!E11,'1987'!E11,'1988'!E11,'1989'!E11,'1990'!E11,'1991'!E11,'1992'!E11,'1993'!E11,'1994'!E11,'1995'!E11,'1996'!E11,'1997'!E11,'1998'!E11,'1999'!E11,'2000'!E11,'2001'!E11,'2002'!E11,'2003'!E11,'2004'!E11,'2005'!E11,'2006'!E11,'2007'!E11,'2008'!E11,'2009'!E11,'2010'!E11,'2011'!E11,'2012'!E11,'2013'!E11,'2014'!E11,'2015'!E11,'2016'!E11,'2017'!E11,'2018'!E11,'2019'!E11,'2020'!E11,'2021'!E11,'2022'!E11,'2023'!E11,'2024'!E11,'2025'!E11) | F11: =AVERAGE('1940'!F11,'1941'!F11,'1942'!F11,'1943'!F11,'1944'!F11,'1945'!F11,'1946'!F11,'1947'!F11,'1948'!F11,'1949'!F11,'1950'!F11,'1951'!F11,'1952'!F11,'1953'!F11,'1954'!F11,'1955'!F11,'1956'!F11,'1957'!F11,'1958'!F11,'1959'!F11,'1960'!F11,'1961'!F11,'1962'!F11,'1963'!F11,'1964'!F11,'1965'!F11,'1966'!F11,'1967'!F11,'1968'!F11,'1969'!F11,'1970'!F11,'1971'!F11,'1972'!F11,'1973'!F11,'1974'!F11,'1975'!F11,'1976'!F11,'1977'!F11,'1978'!F11,'1979'!F11,'1980'!F11,'1981'!F11,'1982'!F11,'1983'!F11,'1984'!F11,'1985'!F11,'1986'!F11,'1987'!F11,'1988'!F11,'1989'!F11,'1990'!F11,'1991'!F11,'1992'!F11,'1993'!F11,'1994'!F11,'1995'!F11,'1996'!F11,'1997'!F11,'1998'!F11,'1999'!F11,'2000'!F11,'2001'!F11,'2002'!F11,'2003'!F11,'2004'!F11,'2005'!F11,'2006'!F11,'2007'!F11,'2008'!F11,'2009'!F11,'2010'!F11,'2011'!F11,'2012'!F11,'2013'!F11,'2014'!F11,'2015'!F11,'2016'!F11,'2017'!F11,'2018'!F11,'2019'!F11,'2020'!F11,'2021'!F11,'2022'!F11,'2023'!F11,'2024'!F11,'2025'!F11) | G11: =AVERAGE('1940'!G11,'1941'!G11,'1942'!G11,'1943'!G11,'1944'!G11,'1945'!G11,'1946'!G11,'1947'!G11,'1948'!G11,'1949'!G11,'1950'!G11,'1951'!G11,'1952'!G11,'1953'!G11,'1954'!G11,'1955'!G11,'1956'!G11,'1957'!G11,'1958'!G11,'1959'!G11,'1960'!G11,'1961'!G11,'1962'!G11,'1963'!G11,'1964'!G11,'1965'!G11,'1966'!G11,'1967'!G11,'1968'!G11,'1969'!G11,'1970'!G11,'1971'!G11,'1972'!G11,'1973'!G11,'1974'!G11,'1975'!G11,'1976'!G11,'1977'!G11,'1978'!G11,'1979'!G11,'1980'!G11,'1981'!G11,'1982'!G11,'1983'!G11,'1984'!G11,'1985'!G11,'1986'!G11,'1987'!G11,'1988'!G11,'1989'!G11,'1990'!G11,'1991'!G11,'1992'!G11,'1993'!G11,'1994'!G11,'1995'!G11,'1996'!G11,'1997'!G11,'1998'!G11,'1999'!G11,'2000'!G11,'2001'!G11,'2002'!G11,'2003'!G11,'2004'!G11,'2005'!G11,'2006'!G11,'2007'!G11,'2008'!G11,'2009'!G11,'2010'!G11,'2011'!G11,'2012'!G11,'2013'!G11,'2014'!G11,'2015'!G11,'2016'!G11,'2017'!G11,'2018'!G11,'2019'!G11,'2020'!G11,'2021'!G11,'2022'!G11,'2023'!G11,'2024'!G11,'2025'!G11) | H11: =AVERAGE('1940'!H11,'1941'!H11,'1942'!H11,'1943'!H11,'1944'!H11,'1945'!H11,'1946'!H11,'1947'!H11,'1948'!H11,'1949'!H11,'1950'!H11,'1951'!H11,'1952'!H11,'1953'!H11,'1954'!H11,'1955'!H11,'1956'!H11,'1957'!H11,'1958'!H11,'1959'!H11,'1960'!H11,'1961'!H11,'1962'!H11,'1963'!H11,'1964'!H11,'1965'!H11,'1966'!H11,'1967'!H11,'1968'!H11,'1969'!H11,'1970'!H11,'1971'!H11,'1972'!H11,'1973'!H11,'1974'!H11,'1975'!H11,'1976'!H11,'1977'!H11,'1978'!H11,'1979'!H11,'1980'!H11,'1981'!H11,'1982'!H11,'1983'!H11,'1984'!H11,'1985'!H11,'1986'!H11,'1987'!H11,'1988'!H11,'1989'!H11,'1990'!H11,'1991'!H11,'1992'!H11,'1993'!H11,'1994'!H11,'1995'!H11,'1996'!H11,'1997'!H11,'1998'!H11,'1999'!H11,'2000'!H11,'2001'!H11,'2002'!H11,'2003'!H11,'2004'!H11,'2005'!H11,'2006'!H11,'2007'!H11,'2008'!H11,'2009'!H11,'2010'!H11,'2011'!H11,'2012'!H11,'2013'!H11,'2014'!H11,'2015'!H11,'2016'!H11,'2017'!H11,'2018'!H11,'2019'!H11,'2020'!H11,'2021'!H11,'2022'!H11,'2023'!H11,'2024'!H11,'2025'!H11) | I11: =AVERAGE('1940'!I11,'1941'!I11,'1942'!I11,'1943'!I11,'1944'!I11,'1945'!I11,'1946'!I11,'1947'!I11,'1948'!I11,'1949'!I11,'1950'!I11,'1951'!I11,'1952'!I11,'1953'!I11,'1954'!I11,'1955'!I11,'1956'!I11,'1957'!I11,'1958'!I11,'1959'!I11,'1960'!I11,'1961'!I11,'1962'!I11,'1963'!I11,'1964'!I11,'1965'!I11,'1966'!I11,'1967'!I11,'1968'!I11,'1969'!I11,'1970'!I11,'1971'!I11,'1972'!I11,'1973'!I11,'1974'!I11,'1975'!I11,'1976'!I11,'1977'!I11,'1978'!I11,'1979'!I11,'1980'!I11,'1981'!I11,'1982'!I11,'1983'!I11,'1984'!I11,'1985'!I11,'1986'!I11,'1987'!I11,'1988'!I11,'1989'!I11,'1990'!I11,'1991'!I11,'1992'!I11,'1993'!I11,'1994'!I11,'1995'!I11,'1996'!I11,'1997'!I11,'1998'!I11,'1999'!I11,'2000'!I11,'2001'!I11,'2002'!I11,'2003'!I11,'2004'!I11,'2005'!I11,'2006'!I11,'2007'!I11,'2008'!I11,'2009'!I11,'2010'!I11,'2011'!I11,'2012'!I11,'2013'!I11,'2014'!I11,'2015'!I11,'2016'!I11,'2017'!I11,'2018'!I11,'2019'!I11,'2020'!I11,'2021'!I11,'2022'!I11,'2023'!I11,'2024'!I11,'2025'!I11) | ... M11: =AVERAGE('1940'!M11,'1941'!M11,'1942'!M11,'1943'!M11,'1944'!M11,'1945'!M11,'1946'!M11,'1947'!M11,'1948'!M11,'1949'!M11,'1950'!M11,'1951'!M11,'1952'!M11,'1953'!M11,'1954'!M11,'1955'!M11,'1956'!M11,'1957'!M11,'1958'!M11,'1959'!M11,'1960'!M11,'1961'!M11,'1962'!M11,'1963'!M11,'1964'!M11,'1965'!M11,'1966'!M11,'1967'!M11,'1968'!M11,'1969'!M11,'1970'!M11,'1971'!M11,'1972'!M11,'1973'!M11,'1974'!M11,'1975'!M11,'1976'!M11,'1977'!M11,'1978'!M11,'1979'!M11,'1980'!M11,'1981'!M11,'1982'!M11,'1983'!M11,'1984'!M11,'1985'!M11,'1986'!M11,'1987'!M11,'1988'!M11,'1989'!M11,'1990'!M11,'1991'!M11,'1992'!M11,'1993'!M11,'1994'!M11,'1995'!M11,'1996'!M11,'1997'!M11,'1998'!M11,'1999'!M11,'2000'!M11,'2001'!M11,'2002'!M11,'2003'!M11,'2004'!M11,'2005'!M11,'2006'!M11,'2007'!M11,'2008'!M11,'2009'!M11,'2010'!M11,'2011'!M11,'2012'!M11,'2013'!M11,'2014'!M11,'2015'!M11,'2016'!M11,'2017'!M11,'2018'!M11,'2019'!M11,'2020'!M11,'2021'!M11,'2022'!M11,'2023'!M11,'2024'!M11,'2025'!M11) | N11: =SUM(B11:M11)
A12: Sr. br. tropskih dana | B12: =AVERAGE('1940'!B12,'1941'!B12,'1942'!B12,'1943'!B12,'1944'!B12,'1945'!B12,'1946'!B12,'1947'!B12,'1948'!B12,'1949'!B12,'1950'!B12,'1951'!B12,'1952'!B12,'1953'!B12,'1954'!B12,'1955'!B12,'1956'!B12,'1957'!B12,'1958'!B12,'1959'!B12,'1960'!B12,'1961'!B12,'1962'!B12,'1963'!B12,'1964'!B12,'1965'!B12,'1966'!B12,'1967'!B12,'1968'!B12,'1969'!B12,'1970'!B12,'1971'!B12,'1972'!B12,'1973'!B12,'1974'!B12,'1975'!B12,'1976'!B12,'1977'!B12,'1978'!B12,'1979'!B12,'1980'!B12,'1981'!B12,'1982'!B12,'1983'!B12,'1984'!B12,'1985'!B12,'1986'!B12,'1987'!B12,'1988'!B12,'1989'!B12,'1990'!B12,'1991'!B12,'1992'!B12,'1993'!B12,'1994'!B12,'1995'!B12,'1996'!B12,'1997'!B12,'1998'!B12,'1999'!B12,'2000'!B12,'2001'!B12,'2002'!B12,'2003'!B12,'2004'!B12,'2005'!B12,'2006'!B12,'2007'!B12,'2008'!B12,'2009'!B12,'2010'!B12,'2011'!B12,'2012'!B12,'2013'!B12,'2014'!B12,'2015'!B12,'2016'!B12,'2017'!B12,'2018'!B12,'2019'!B12,'2020'!B12,'2021'!B12,'2022'!B12,'2023'!B12,'2024'!B12,'2025'!B12) | C12: =AVERAGE('1940'!C12,'1941'!C12,'1942'!C12,'1943'!C12,'1944'!C12,'1945'!C12,'1946'!C12,'1947'!C12,'1948'!C12,'1949'!C12,'1950'!C12,'1951'!C12,'1952'!C12,'1953'!C12,'1954'!C12,'1955'!C12,'1956'!C12,'1957'!C12,'1958'!C12,'1959'!C12,'1960'!C12,'1961'!C12,'1962'!C12,'1963'!C12,'1964'!C12,'1965'!C12,'1966'!C12,'1967'!C12,'1968'!C12,'1969'!C12,'1970'!C12,'1971'!C12,'1972'!C12,'1973'!C12,'1974'!C12,'1975'!C12,'1976'!C12,'1977'!C12,'1978'!C12,'1979'!C12,'1980'!C12,'1981'!C12,'1982'!C12,'1983'!C12,'1984'!C12,'1985'!C12,'1986'!C12,'1987'!C12,'1988'!C12,'1989'!C12,'1990'!C12,'1991'!C12,'1992'!C12,'1993'!C12,'1994'!C12,'1995'!C12,'1996'!C12,'1997'!C12,'1998'!C12,'1999'!C12,'2000'!C12,'2001'!C12,'2002'!C12,'2003'!C12,'2004'!C12,'2005'!C12,'2006'!C12,'2007'!C12,'2008'!C12,'2009'!C12,'2010'!C12,'2011'!C12,'2012'!C12,'2013'!C12,'2014'!C12,'2015'!C12,'2016'!C12,'2017'!C12,'2018'!C12,'2019'!C12,'2020'!C12,'2021'!C12,'2022'!C12,'2023'!C12,'2024'!C12,'2025'!C12) | D12: =AVERAGE('1940'!D12,'1941'!D12,'1942'!D12,'1943'!D12,'1944'!D12,'1945'!D12,'1946'!D12,'1947'!D12,'1948'!D12,'1949'!D12,'1950'!D12,'1951'!D12,'1952'!D12,'1953'!D12,'1954'!D12,'1955'!D12,'1956'!D12,'1957'!D12,'1958'!D12,'1959'!D12,'1960'!D12,'1961'!D12,'1962'!D12,'1963'!D12,'1964'!D12,'1965'!D12,'1966'!D12,'1967'!D12,'1968'!D12,'1969'!D12,'1970'!D12,'1971'!D12,'1972'!D12,'1973'!D12,'1974'!D12,'1975'!D12,'1976'!D12,'1977'!D12,'1978'!D12,'1979'!D12,'1980'!D12,'1981'!D12,'1982'!D12,'1983'!D12,'1984'!D12,'1985'!D12,'1986'!D12,'1987'!D12,'1988'!D12,'1989'!D12,'1990'!D12,'1991'!D12,'1992'!D12,'1993'!D12,'1994'!D12,'1995'!D12,'1996'!D12,'1997'!D12,'1998'!D12,'1999'!D12,'2000'!D12,'2001'!D12,'2002'!D12,'2003'!D12,'2004'!D12,'2005'!D12,'2006'!D12,'2007'!D12,'2008'!D12,'2009'!D12,'2010'!D12,'2011'!D12,'2012'!D12,'2013'!D12,'2014'!D12,'2015'!D12,'2016'!D12,'2017'!D12,'2018'!D12,'2019'!D12,'2020'!D12,'2021'!D12,'2022'!D12,'2023'!D12,'2024'!D12,'2025'!D12) | E12: =AVERAGE('1940'!E12,'1941'!E12,'1942'!E12,'1943'!E12,'1944'!E12,'1945'!E12,'1946'!E12,'1947'!E12,'1948'!E12,'1949'!E12,'1950'!E12,'1951'!E12,'1952'!E12,'1953'!E12,'1954'!E12,'1955'!E12,'1956'!E12,'1957'!E12,'1958'!E12,'1959'!E12,'1960'!E12,'1961'!E12,'1962'!E12,'1963'!E12,'1964'!E12,'1965'!E12,'1966'!E12,'1967'!E12,'1968'!E12,'1969'!E12,'1970'!E12,'1971'!E12,'1972'!E12,'1973'!E12,'1974'!E12,'1975'!E12,'1976'!E12,'1977'!E12,'1978'!E12,'1979'!E12,'1980'!E12,'1981'!E12,'1982'!E12,'1983'!E12,'1984'!E12,'1985'!E12,'1986'!E12,'1987'!E12,'1988'!E12,'1989'!E12,'1990'!E12,'1991'!E12,'1992'!E12,'1993'!E12,'1994'!E12,'1995'!E12,'1996'!E12,'1997'!E12,'1998'!E12,'1999'!E12,'2000'!E12,'2001'!E12,'2002'!E12,'2003'!E12,'2004'!E12,'2005'!E12,'2006'!E12,'2007'!E12,'2008'!E12,'2009'!E12,'2010'!E12,'2011'!E12,'2012'!E12,'2013'!E12,'2014'!E12,'2015'!E12,'2016'!E12,'2017'!E12,'2018'!E12,'2019'!E12,'2020'!E12,'2021'!E12,'2022'!E12,'2023'!E12,'2024'!E12,'2025'!E12) | F12: =AVERAGE('1940'!F12,'1941'!F12,'1942'!F12,'1943'!F12,'1944'!F12,'1945'!F12,'1946'!F12,'1947'!F12,'1948'!F12,'1949'!F12,'1950'!F12,'1951'!F12,'1952'!F12,'1953'!F12,'1954'!F12,'1955'!F12,'1956'!F12,'1957'!F12,'1958'!F12,'1959'!F12,'1960'!F12,'1961'!F12,'1962'!F12,'1963'!F12,'1964'!F12,'1965'!F12,'1966'!F12,'1967'!F12,'1968'!F12,'1969'!F12,'1970'!F12,'1971'!F12,'1972'!F12,'1973'!F12,'1974'!F12,'1975'!F12,'1976'!F12,'1977'!F12,'1978'!F12,'1979'!F12,'1980'!F12,'1981'!F12,'1982'!F12,'1983'!F12,'1984'!F12,'1985'!F12,'1986'!F12,'1987'!F12,'1988'!F12,'1989'!F12,'1990'!F12,'1991'!F12,'1992'!F12,'1993'!F12,'1994'!F12,'1995'!F12,'1996'!F12,'1997'!F12,'1998'!F12,'1999'!F12,'2000'!F12,'2001'!F12,'2002'!F12,'2003'!F12,'2004'!F12,'2005'!F12,'2006'!F12,'2007'!F12,'2008'!F12,'2009'!F12,'2010'!F12,'2011'!F12,'2012'!F12,'2013'!F12,'2014'!F12,'2015'!F12,'2016'!F12,'2017'!F12,'2018'!F12,'2019'!F12,'2020'!F12,'2021'!F12,'2022'!F12,'2023'!F12,'2024'!F12,'2025'!F12) | G12: =AVERAGE('1940'!G12,'1941'!G12,'1942'!G12,'1943'!G12,'1944'!G12,'1945'!G12,'1946'!G12,'1947'!G12,'1948'!G12,'1949'!G12,'1950'!G12,'1951'!G12,'1952'!G12,'1953'!G12,'1954'!G12,'1955'!G12,'1956'!G12,'1957'!G12,'1958'!G12,'1959'!G12,'1960'!G12,'1961'!G12,'1962'!G12,'1963'!G12,'1964'!G12,'1965'!G12,'1966'!G12,'1967'!G12,'1968'!G12,'1969'!G12,'1970'!G12,'1971'!G12,'1972'!G12,'1973'!G12,'1974'!G12,'1975'!G12,'1976'!G12,'1977'!G12,'1978'!G12,'1979'!G12,'1980'!G12,'1981'!G12,'1982'!G12,'1983'!G12,'1984'!G12,'1985'!G12,'1986'!G12,'1987'!G12,'1988'!G12,'1989'!G12,'1990'!G12,'1991'!G12,'1992'!G12,'1993'!G12,'1994'!G12,'1995'!G12,'1996'!G12,'1997'!G12,'1998'!G12,'1999'!G12,'2000'!G12,'2001'!G12,'2002'!G12,'2003'!G12,'2004'!G12,'2005'!G12,'2006'!G12,'2007'!G12,'2008'!G12,'2009'!G12,'2010'!G12,'2011'!G12,'2012'!G12,'2013'!G12,'2014'!G12,'2015'!G12,'2016'!G12,'2017'!G12,'2018'!G12,'2019'!G12,'2020'!G12,'2021'!G12,'2022'!G12,'2023'!G12,'2024'!G12,'2025'!G12) | H12: =AVERAGE('1940'!H12,'1941'!H12,'1942'!H12,'1943'!H12,'1944'!H12,'1945'!H12,'1946'!H12,'1947'!H12,'1948'!H12,'1949'!H12,'1950'!H12,'1951'!H12,'1952'!H12,'1953'!H12,'1954'!H12,'1955'!H12,'1956'!H12,'1957'!H12,'1958'!H12,'1959'!H12,'1960'!H12,'1961'!H12,'1962'!H12,'1963'!H12,'1964'!H12,'1965'!H12,'1966'!H12,'1967'!H12,'1968'!H12,'1969'!H12,'1970'!H12,'1971'!H12,'1972'!H12,'1973'!H12,'1974'!H12,'1975'!H12,'1976'!H12,'1977'!H12,'1978'!H12,'1979'!H12,'1980'!H12,'1981'!H12,'1982'!H12,'1983'!H12,'1984'!H12,'1985'!H12,'1986'!H12,'1987'!H12,'1988'!H12,'1989'!H12,'1990'!H12,'1991'!H12,'1992'!H12,'1993'!H12,'1994'!H12,'1995'!H12,'1996'!H12,'1997'!H12,'1998'!H12,'1999'!H12,'2000'!H12,'2001'!H12,'2002'!H12,'2003'!H12,'2004'!H12,'2005'!H12,'2006'!H12,'2007'!H12,'2008'!H12,'2009'!H12,'2010'!H12,'2011'!H12,'2012'!H12,'2013'!H12,'2014'!H12,'2015'!H12,'2016'!H12,'2017'!H12,'2018'!H12,'2019'!H12,'2020'!H12,'2021'!H12,'2022'!H12,'2023'!H12,'2024'!H12,'2025'!H12) | I12: =AVERAGE('1940'!I12,'1941'!I12,'1942'!I12,'1943'!I12,'1944'!I12,'1945'!I12,'1946'!I12,'1947'!I12,'1948'!I12,'1949'!I12,'1950'!I12,'1951'!I12,'1952'!I12,'1953'!I12,'1954'!I12,'1955'!I12,'1956'!I12,'1957'!I12,'1958'!I12,'1959'!I12,'1960'!I12,'1961'!I12,'1962'!I12,'1963'!I12,'1964'!I12,'1965'!I12,'1966'!I12,'1967'!I12,'1968'!I12,'1969'!I12,'1970'!I12,'1971'!I12,'1972'!I12,'1973'!I12,'1974'!I12,'1975'!I12,'1976'!I12,'1977'!I12,'1978'!I12,'1979'!I12,'1980'!I12,'1981'!I12,'1982'!I12,'1983'!I12,'1984'!I12,'1985'!I12,'1986'!I12,'1987'!I12,'1988'!I12,'1989'!I12,'1990'!I12,'1991'!I12,'1992'!I12,'1993'!I12,'1994'!I12,'1995'!I12,'1996'!I12,'1997'!I12,'1998'!I12,'1999'!I12,'2000'!I12,'2001'!I12,'2002'!I12,'2003'!I12,'2004'!I12,'2005'!I12,'2006'!I12,'2007'!I12,'2008'!I12,'2009'!I12,'2010'!I12,'2011'!I12,'2012'!I12,'2013'!I12,'2014'!I12,'2015'!I12,'2016'!I12,'2017'!I12,'2018'!I12,'2019'!I12,'2020'!I12,'2021'!I12,'2022'!I12,'2023'!I12,'2024'!I12,'2025'!I12) | ... M12: =AVERAGE('1940'!M12,'1941'!M12,'1942'!M12,'1943'!M12,'1944'!M12,'1945'!M12,'1946'!M12,'1947'!M12,'1948'!M12,'1949'!M12,'1950'!M12,'1951'!M12,'1952'!M12,'1953'!M12,'1954'!M12,'1955'!M12,'1956'!M12,'1957'!M12,'1958'!M12,'1959'!M12,'1960'!M12,'1961'!M12,'1962'!M12,'1963'!M12,'1964'!M12,'1965'!M12,'1966'!M12,'1967'!M12,'1968'!M12,'1969'!M12,'1970'!M12,'1971'!M12,'1972'!M12,'1973'!M12,'1974'!M12,'1975'!M12,'1976'!M12,'1977'!M12,'1978'!M12,'1979'!M12,'1980'!M12,'1981'!M12,'1982'!M12,'1983'!M12,'1984'!M12,'1985'!M12,'1986'!M12,'1987'!M12,'1988'!M12,'1989'!M12,'1990'!M12,'1991'!M12,'1992'!M12,'1993'!M12,'1994'!M12,'1995'!M12,'1996'!M12,'1997'!M12,'1998'!M12,'1999'!M12,'2000'!M12,'2001'!M12,'2002'!M12,'2003'!M12,'2004'!M12,'2005'!M12,'2006'!M12,'2007'!M12,'2008'!M12,'2009'!M12,'2010'!M12,'2011'!M12,'2012'!M12,'2013'!M12,'2014'!M12,'2015'!M12,'2016'!M12,'2017'!M12,'2018'!M12,'2019'!M12,'2020'!M12,'2021'!M12,'2022'!M12,'2023'!M12,'2024'!M12,'2025'!M12) | N12: =SUM(B12:M12)
A13: RELATIVNA VLAGA (%)
