Workbook

Sheet Prosek 2010-2025
A1: PROSEČNE MESEČNE, GODIŠNJE I EKSTREMNE VREDNOSTI ZA PERIOD 2010-2025. GODINA
A2: CMILJEVAC II φ 43.11°N λ 17.66°E h 1295 m
A4: METEOROLOŠKI PARAMETAR | B4: jan | C4: feb | D4: mar | E4: apr | F4: maj | G4: jun | H4: jul | I4: avg | J4: sep | K4: okt | L4: nov | M4: dec | N4: god.
A5: TEMPERATURA VAZDUHA (°C)
A6: Normalna vrednost | B6: =AVERAGE('2010'!B6,'2011'!B6,'2012'!B6,'2013'!B6,'2014'!B6,'2015'!B6,'2016'!B6,'2017'!B6,'2018'!B6,'2019'!B6,'2020'!B6,'2021'!B6,'2022'!B6,'2023'!B6,'2024'!B6,'2025'!B6) | C6: =AVERAGE('2010'!C6,'2011'!C6,'2012'!C6,'2013'!C6,'2014'!C6,'2015'!C6,'2016'!C6,'2017'!C6,'2018'!C6,'2019'!C6,'2020'!C6,'2021'!C6,'2022'!C6,'2023'!C6,'2024'!C6,'2025'!C6) | D6: =AVERAGE('2010'!D6,'2011'!D6,'2012'!D6,'2013'!D6,'2014'!D6,'2015'!D6,'2016'!D6,'2017'!D6,'2018'!D6,'2019'!D6,'2020'!D6,'2021'!D6,'2022'!D6,'2023'!D6,'2024'!D6,'2025'!D6) | E6: =AVERAGE('2010'!E6,'2011'!E6,'2012'!E6,'2013'!E6,'2014'!E6,'2015'!E6,'2016'!E6,'2017'!E6,'2018'!E6,'2019'!E6,'2020'!E6,'2021'!E6,'2022'!E6,'2023'!E6,'2024'!E6,'2025'!E6) | F6: =AVERAGE('2010'!F6,'2011'!F6,'2012'!F6,'2013'!F6,'2014'!F6,'2015'!F6,'2016'!F6,'2017'!F6,'2018'!F6,'2019'!F6,'2020'!F6,'2021'!F6,'2022'!F6,'2023'!F6,'2024'!F6,'2025'!F6) | G6: =AVERAGE('2010'!G6,'2011'!G6,'2012'!G6,'2013'!G6,'2014'!G6,'2015'!G6,'2016'!G6,'2017'!G6,'2018'!G6,'2019'!G6,'2020'!G6,'2021'!G6,'2022'!G6,'2023'!G6,'2024'!G6,'2025'!G6) | H6: =AVERAGE('2010'!H6,'2011'!H6,'2012'!H6,'2013'!H6,'2014'!H6,'2015'!H6,'2016'!H6,'2017'!H6,'2018'!H6,'2019'!H6,'2020'!H6,'2021'!H6,'2022'!H6,'2023'!H6,'2024'!H6,'2025'!H6) | I6: =AVERAGE('2010'!I6,'2011'!I6,'2012'!I6,'2013'!I6,'2014'!I6,'2015'!I6,'2016'!I6,'2017'!I6,'2018'!I6,'2019'!I6,'2020'!I6,'2021'!I6,'2022'!I6,'2023'!I6,'2024'!I6,'2025'!I6) | ... M6: =AVERAGE('2010'!M6,'2011'!M6,'2012'!M6,'2013'!M6,'2014'!M6,'2015'!M6,'2016'!M6,'2017'!M6,'2018'!M6,'2019'!M6,'2020'!M6,'2021'!M6,'2022'!M6,'2023'!M6,'2024'!M6,'2025'!M6) | N6: =AVERAGE(B6:M6)
A7: Srednja maksimalna | B7: =AVERAGE('2010'!B7,'2011'!B7,'2012'!B7,'2013'!B7,'2014'!B7,'2015'!B7,'2016'!B7,'2017'!B7,'2018'!B7,'2019'!B7,'2020'!B7,'2021'!B7,'2022'!B7,'2023'!B7,'2024'!B7,'2025'!B7) | C7: =AVERAGE('2010'!C7,'2011'!C7,'2012'!C7,'2013'!C7,'2014'!C7,'2015'!C7,'2016'!C7,'2017'!C7,'2018'!C7,'2019'!C7,'2020'!C7,'2021'!C7,'2022'!C7,'2023'!C7,'2024'!C7,'2025'!C7) | D7: =AVERAGE('2010'!D7,'2011'!D7,'2012'!D7,'2013'!D7,'2014'!D7,'2015'!D7,'2016'!D7,'2017'!D7,'2018'!D7,'2019'!D7,'2020'!D7,'2021'!D7,'2022'!D7,'2023'!D7,'2024'!D7,'2025'!D7) | E7: =AVERAGE('2010'!E7,'2011'!E7,'2012'!E7,'2013'!E7,'2014'!E7,'2015'!E7,'2016'!E7,'2017'!E7,'2018'!E7,'2019'!E7,'2020'!E7,'2021'!E7,'2022'!E7,'2023'!E7,'2024'!E7,'2025'!E7) | F7: =AVERAGE('2010'!F7,'2011'!F7,'2012'!F7,'2013'!F7,'2014'!F7,'2015'!F7,'2016'!F7,'2017'!F7,'2018'!F7,'2019'!F7,'2020'!F7,'2021'!F7,'2022'!F7,'2023'!F7,'2024'!F7,'2025'!F7) | G7: =AVERAGE('2010'!G7,'2011'!G7,'2012'!G7,'2013'!G7,'2014'!G7,'2015'!G7,'2016'!G7,'2017'!G7,'2018'!G7,'2019'!G7,'2020'!G7,'2021'!G7,'2022'!G7,'2023'!G7,'2024'!G7,'2025'!G7) | H7: =AVERAGE('2010'!H7,'2011'!H7,'2012'!H7,'2013'!H7,'2014'!H7,'2015'!H7,'2016'!H7,'2017'!H7,'2018'!H7,'2019'!H7,'2020'!H7,'2021'!H7,'2022'!H7,'2023'!H7,'2024'!H7,'2025'!H7) | I7: =AVERAGE('2010'!I7,'2011'!I7,'2012'!I7,'2013'!I7,'2014'!I7,'2015'!I7,'2016'!I7,'2017'!I7,'2018'!I7,'2019'!I7,'2020'!I7,'2021'!I7,'2022'!I7,'2023'!I7,'2024'!I7,'2025'!I7) | ... M7: =AVERAGE('2010'!M7,'2011'!M7,'2012'!M7,'2013'!M7,'2014'!M7,'2015'!M7,'2016'!M7,'2017'!M7,'2018'!M7,'2019'!M7,'2020'!M7,'2021'!M7,'2022'!M7,'2023'!M7,'2024'!M7,'2025'!M7) | N7: =AVERAGE(B7:M7)
A8: Srednja minimalna | B8: =AVERAGE('2010'!B8,'2011'!B8,'2012'!B8,'2013'!B8,'2014'!B8,'2015'!B8,'2016'!B8,'2017'!B8,'2018'!B8,'2019'!B8,'2020'!B8,'2021'!B8,'2022'!B8,'2023'!B8,'2024'!B8,'2025'!B8) | C8: =AVERAGE('2010'!C8,'2011'!C8,'2012'!C8,'2013'!C8,'2014'!C8,'2015'!C8,'2016'!C8,'2017'!C8,'2018'!C8,'2019'!C8,'2020'!C8,'2021'!C8,'2022'!C8,'2023'!C8,'2024'!C8,'2025'!C8) | D8: =AVERAGE('2010'!D8,'2011'!D8,'2012'!D8,'2013'!D8,'2014'!D8,'2015'!D8,'2016'!D8,'2017'!D8,'2018'!D8,'2019'!D8,'2020'!D8,'2021'!D8,'2022'!D8,'2023'!D8,'2024'!D8,'2025'!D8) | E8: =AVERAGE('2010'!E8,'2011'!E8,'2012'!E8,'2013'!E8,'2014'!E8,'2015'!E8,'2016'!E8,'2017'!E8,'2018'!E8,'2019'!E8,'2020'!E8,'2021'!E8,'2022'!E8,'2023'!E8,'2024'!E8,'2025'!E8) | F8: =AVERAGE('2010'!F8,'2011'!F8,'2012'!F8,'2013'!F8,'2014'!F8,'2015'!F8,'2016'!F8,'2017'!F8,'2018'!F8,'2019'!F8,'2020'!F8,'2021'!F8,'2022'!F8,'2023'!F8,'2024'!F8,'2025'!F8) | G8: =AVERAGE('2010'!G8,'2011'!G8,'2012'!G8,'2013'!G8,'2014'!G8,'2015'!G8,'2016'!G8,'2017'!G8,'2018'!G8,'2019'!G8,'2020'!G8,'2021'!G8,'2022'!G8,'2023'!G8,'2024'!G8,'2025'!G8) | H8: =AVERAGE('2010'!H8,'2011'!H8,'2012'!H8,'2013'!H8,'2014'!H8,'2015'!H8,'2016'!H8,'2017'!H8,'2018'!H8,'2019'!H8,'2020'!H8,'2021'!H8,'2022'!H8,'2023'!H8,'2024'!H8,'2025'!H8) | I8: =AVERAGE('2010'!I8,'2011'!I8,'2012'!I8,'2013'!I8,'2014'!I8,'2015'!I8,'2016'!I8,'2017'!I8,'2018'!I8,'2019'!I8,'2020'!I8,'2021'!I8,'2022'!I8,'2023'!I8,'2024'!I8,'2025'!I8) | ... M8: =AVERAGE('2010'!M8,'2011'!M8,'2012'!M8,'2013'!M8,'2014'!M8,'2015'!M8,'2016'!M8,'2017'!M8,'2018'!M8,'2019'!M8,'2020'!M8,'2021'!M8,'2022'!M8,'2023'!M8,'2024'!M8,'2025'!M8) | N8: =AVERAGE(B8:M8)
A9: Apsolutni maksimum | B9: =AVERAGE('2010'!B9,'2011'!B9,'2012'!B9,'2013'!B9,'2014'!B9,'2015'!B9,'2016'!B9,'2017'!B9,'2018'!B9,'2019'!B9,'2020'!B9,'2021'!B9,'2022'!B9,'2023'!B9,'2024'!B9,'2025'!B9) | C9: =AVERAGE('2010'!C9,'2011'!C9,'2012'!C9,'2013'!C9,'2014'!C9,'2015'!C9,'2016'!C9,'2017'!C9,'2018'!C9,'2019'!C9,'2020'!C9,'2021'!C9,'2022'!C9,'2023'!C9,'2024'!C9,'2025'!C9) | D9: =AVERAGE('2010'!D9,'2011'!D9,'2012'!D9,'2013'!D9,'2014'!D9,'2015'!D9,'2016'!D9,'2017'!D9,'2018'!D9,'2019'!D9,'2020'!D9,'2021'!D9,'2022'!D9,'2023'!D9,'2024'!D9,'2025'!D9) | E9: =AVERAGE('2010'!E9,'2011'!E9,'2012'!E9,'2013'!E9,'2014'!E9,'2015'!E9,'2016'!E9,'2017'!E9,'2018'!E9,'2019'!E9,'2020'!E9,'2021'!E9,'2022'!E9,'2023'!E9,'2024'!E9,'2025'!E9) | F9: =AVERAGE('2010'!F9,'2011'!F9,'2012'!F9,'2013'!F9,'2014'!F9,'2015'!F9,'2016'!F9,'2017'!F9,'2018'!F9,'2019'!F9,'2020'!F9,'2021'!F9,'2022'!F9,'2023'!F9,'2024'!F9,'2025'!F9) | G9: =AVERAGE('2010'!G9,'2011'!G9,'2012'!G9,'2013'!G9,'2014'!G9,'2015'!G9,'2016'!G9,'2017'!G9,'2018'!G9,'2019'!G9,'2020'!G9,'2021'!G9,'2022'!G9,'2023'!G9,'2024'!G9,'2025'!G9) | H9: =AVERAGE('2010'!H9,'2011'!H9,'2012'!H9,'2013'!H9,'2014'!H9,'2015'!H9,'2016'!H9,'2017'!H9,'2018'!H9,'2019'!H9,'2020'!H9,'2021'!H9,'2022'!H9,'2023'!H9,'2024'!H9,'2025'!H9) | I9: =AVERAGE('2010'!I9,'2011'!I9,'2012'!I9,'2013'!I9,'2014'!I9,'2015'!I9,'2016'!I9,'2017'!I9,'2018'!I9,'2019'!I9,'2020'!I9,'2021'!I9,'2022'!I9,'2023'!I9,'2024'!I9,'2025'!I9) | ... M9: =AVERAGE('2010'!M9,'2011'!M9,'2012'!M9,'2013'!M9,'2014'!M9,'2015'!M9,'2016'!M9,'2017'!M9,'2018'!M9,'2019'!M9,'2020'!M9,'2021'!M9,'2022'!M9,'2023'!M9,'2024'!M9,'2025'!M9) | N9: =MAX(B9:M9)
A10: Apsolutni minimum | B10: =AVERAGE('2010'!B10,'2011'!B10,'2012'!B10,'2013'!B10,'2014'!B10,'2015'!B10,'2016'!B10,'2017'!B10,'2018'!B10,'2019'!B10,'2020'!B10,'2021'!B10,'2022'!B10,'2023'!B10,'2024'!B10,'2025'!B10) | C10: =AVERAGE('2010'!C10,'2011'!C10,'2012'!C10,'2013'!C10,'2014'!C10,'2015'!C10,'2016'!C10,'2017'!C10,'2018'!C10,'2019'!C10,'2020'!C10,'2021'!C10,'2022'!C10,'2023'!C10,'2024'!C10,'2025'!C10) | D10: =AVERAGE('2010'!D10,'2011'!D10,'2012'!D10,'2013'!D10,'2014'!D10,'2015'!D10,'2016'!D10,'2017'!D10,'2018'!D10,'2019'!D10,'2020'!D10,'2021'!D10,'2022'!D10,'2023'!D10,'2024'!D10,'2025'!D10) | E10: =AVERAGE('2010'!E10,'2011'!E10,'2012'!E10,'2013'!E10,'2014'!E10,'2015'!E10,'2016'!E10,'2017'!E10,'2018'!E10,'2019'!E10,'2020'!E10,'2021'!E10,'2022'!E10,'2023'!E10,'2024'!E10,'2025'!E10) | F10: =AVERAGE('2010'!F10,'2011'!F10,'2012'!F10,'2013'!F10,'2014'!F10,'2015'!F10,'2016'!F10,'2017'!F10,'2018'!F10,'2019'!F10,'2020'!F10,'2021'!F10,'2022'!F10,'2023'!F10,'2024'!F10,'2025'!F10) | G10: =AVERAGE('2010'!G10,'2011'!G10,'2012'!G10,'2013'!G10,'2014'!G10,'2015'!G10,'2016'!G10,'2017'!G10,'2018'!G10,'2019'!G10,'2020'!G10,'2021'!G10,'2022'!G10,'2023'!G10,'2024'!G10,'2025'!G10) | H10: =AVERAGE('2010'!H10,'2011'!H10,'2012'!H10,'2013'!H10,'2014'!H10,'2015'!H10,'2016'!H10,'2017'!H10,'2018'!H10,'2019'!H10,'2020'!H10,'2021'!H10,'2022'!H10,'2023'!H10,'2024'!H10,'2025'!H10) | I10: =AVERAGE('2010'!I10,'2011'!I10,'2012'!I10,'2013'!I10,'2014'!I10,'2015'!I10,'2016'!I10,'2017'!I10,'2018'!I10,'2019'!I10,'2020'!I10,'2021'!I10,'2022'!I10,'2023'!I10,'2024'!I10,'2025'!I10) | ... M10: =AVERAGE('2010'!M10,'2011'!M10,'2012'!M10,'2013'!M10,'2014'!M10,'2015'!M10,'2016'!M10,'2017'!M10,'2018'!M10,'2019'!M10,'2020'!M10,'2021'!M10,'2022'!M10,'2023'!M10,'2024'!M10,'2025'!M10) | N10: =MIN(B10:M10)
A11: Sr. br. mraznih dana | B11: =AVERAGE('2010'!B11,'2011'!B11,'2012'!B11,'2013'!B11,'2014'!B11,'2015'!B11,'2016'!B11,'2017'!B11,'2018'!B11,'2019'!B11,'2020'!B11,'2021'!B11,'2022'!B11,'2023'!B11,'2024'!B11,'2025'!B11) | C11: =AVERAGE('2010'!C11,'2011'!C11,'2012'!C11,'2013'!C11,'2014'!C11,'2015'!C11,'2016'!C11,'2017'!C11,'2018'!C11,'2019'!C11,'2020'!C11,'2021'!C11,'2022'!C11,'2023'!C11,'2024'!C11,'2025'!C11) | D11: =AVERAGE('2010'!D11,'2011'!D11,'2012'!D11,'2013'!D11,'2014'!D11,'2015'!D11,'2016'!D11,'2017'!D11,'2018'!D11,'2019'!D11,'2020'!D11,'2021'!D11,'2022'!D11,'2023'!D11,'2024'!D11,'2025'!D11) | E11: =AVERAGE('2010'!E11,'2011'!E11,'2012'!E11,'2013'!E11,'2014'!E11,'2015'!E11,'2016'!E11,'2017'!E11,'2018'!E11,'2019'!E11,'2020'!E11,'2021'!E11,'2022'!E11,'2023'!E11,'2024'!E11,'2025'!E11) | F11: =AVERAGE('2010'!F11,'2011'!F11,'2012'!F11,'2013'!F11,'2014'!F11,'2015'!F11,'2016'!F11,'2017'!F11,'2018'!F11,'2019'!F11,'2020'!F11,'2021'!F11,'2022'!F11,'2023'!F11,'2024'!F11,'2025'!F11) | G11: =AVERAGE('2010'!G11,'2011'!G11,'2012'!G11,'2013'!G11,'2014'!G11,'2015'!G11,'2016'!G11,'2017'!G11,'2018'!G11,'2019'!G11,'2020'!G11,'2021'!G11,'2022'!G11,'2023'!G11,'2024'!G11,'2025'!G11) | H11: =AVERAGE('2010'!H11,'2011'!H11,'2012'!H11,'2013'!H11,'2014'!H11,'2015'!H11,'2016'!H11,'2017'!H11,'2018'!H11,'2019'!H11,'2020'!H11,'2021'!H11,'2022'!H11,'2023'!H11,'2024'!H11,'2025'!H11) | I11: =AVERAGE('2010'!I11,'2011'!I11,'2012'!I11,'2013'!I11,'2014'!I11,'2015'!I11,'2016'!I11,'2017'!I11,'2018'!I11,'2019'!I11,'2020'!I11,'2021'!I11,'2022'!I11,'2023'!I11,'2024'!I11,'2025'!I11) | ... M11: =AVERAGE('2010'!M11,'2011'!M11,'2012'!M11,'2013'!M11,'2014'!M11,'2015'!M11,'2016'!M11,'2017'!M11,'2018'!M11,'2019'!M11,'2020'!M11,'2021'!M11,'2022'!M11,'2023'!M11,'2024'!M11,'2025'!M11) | N11: =SUM(B11:M11)
A12: Sr. br. tropskih dana | B12: =AVERAGE('2010'!B12,'2011'!B12,'2012'!B12,'2013'!B12,'2014'!B12,'2015'!B12,'2016'!B12,'2017'!B12,'2018'!B12,'2019'!B12,'2020'!B12,'2021'!B12,'2022'!B12,'2023'!B12,'2024'!B12,'2025'!B12) | C12: =AVERAGE('2010'!C12,'2011'!C12,'2012'!C12,'2013'!C12,'2014'!C12,'2015'!C12,'2016'!C12,'2017'!C12,'2018'!C12,'2019'!C12,'2020'!C12,'2021'!C12,'2022'!C12,'2023'!C12,'2024'!C12,'2025'!C12) | D12: =AVERAGE('2010'!D12,'2011'!D12,'2012'!D12,'2013'!D12,'2014'!D12,'2015'!D12,'2016'!D12,'2017'!D12,'2018'!D12,'2019'!D12,'2020'!D12,'2021'!D12,'2022'!D12,'2023'!D12,'2024'!D12,'2025'!D12) | E12: =AVERAGE('2010'!E12,'2011'!E12,'2012'!E12,'2013'!E12,'2014'!E12,'2015'!E12,'2016'!E12,'2017'!E12,'2018'!E12,'2019'!E12,'2020'!E12,'2021'!E12,'2022'!E12,'2023'!E12,'2024'!E12,'2025'!E12) | F12: =AVERAGE('2010'!F12,'2011'!F12,'2012'!F12,'2013'!F12,'2014'!F12,'2015'!F12,'2016'!F12,'2017'!F12,'2018'!F12,'2019'!F12,'2020'!F12,'2021'!F12,'2022'!F12,'2023'!F12,'2024'!F12,'2025'!F12) | G12: =AVERAGE('2010'!G12,'2011'!G12,'2012'!G12,'2013'!G12,'2014'!G12,'2015'!G12,'2016'!G12,'2017'!G12,'2018'!G12,'2019'!G12,'2020'!G12,'2021'!G12,'2022'!G12,'2023'!G12,'2024'!G12,'2025'!G12) | H12: =AVERAGE('2010'!H12,'2011'!H12,'2012'!H12,'2013'!H12,'2014'!H12,'2015'!H12,'2016'!H12,'2017'!H12,'2018'!H12,'2019'!H12,'2020'!H12,'2021'!H12,'2022'!H12,'2023'!H12,'2024'!H12,'2025'!H12) | I12: =AVERAGE('2010'!I12,'2011'!I12,'2012'!I12,'2013'!I12,'2014'!I12,'2015'!I12,'2016'!I12,'2017'!I12,'2018'!I12,'2019'!I12,'2020'!I12,'2021'!I12,'2022'!I12,'2023'!I12,'2024'!I12,'2025'!I12) | ... M12: =AVERAGE('2010'!M12,'2011'!M12,'2012'!M12,'2013'!M12,'2014'!M12,'2015'!M12,'2016'!M12,'2017'!M12,'2018'!M12,'2019'!M12,'2020'!M12,'2021'!M12,'2022'!M12,'2023'!M12,'2024'!M12,'2025'!M12) | N12: =SUM(B12:M12)
A13: RELATIVNA VLAGA (%)
A14: Prosek | B14: =AVERAGE('2010'!B14,'2011'!B14,'2012'!B14,'2013'!B14,'2014'!B14,'2015'!B14,'2016'!B14,'2017'!B14,'2018'!B14,'2019'!B14,'2020'!B14,'2021'!B14,'2022'!B14,'2023'!B14,'2024'!B14,'2025'!B14) | C14: =AVERAGE('2010'!C14,'2011'!C14,'2012'!C14,'2013'!C14,'2014'!C14,'2015'!C14,'2016'!C14,'2017'!C14,'2018'!C14,'2019'!C14,'2020'!C14,'2021'!C14,'2022'!C14,'2023'!C14,'2024'!C14,'2025'!C14) | D14: =AVERAGE('2010'!D14,'2011'!D14,'2012'!D14,'2013'!D14,'2014'!D14,'2015'!D14,'2016'!D14,'2017'!D14,'2018'!D14,'2019'!D14,'2020'!D14,'2021'!D14,'2022'!D14,'2023'!D14,'2024'!D14,'2025'!D14) | E14: =AVERAGE('2010'!E14,'2011'!E14,'2012'!E14,'2013'!E14,'2014'!E14,'2015'!E14,'2016'!E14,'2017'!E14,'2018'!E14,'2019'!E14,'2020'!E14,'2021'!E14,'2022'!E14,'2023'!E14,'2024'!E14,'2025'!E14) | F14: =AVERAGE('2010'!F14,'2011'!F14,'2012'!F14,'2013'!F14,'2014'!F14,'2015'!F14,'2016'!F14,'2017'!F14,'2018'!F14,'2019'!F14,'2020'!F14,'2021'!F14,'2022'!F14,'2023'!F14,'2024'!F14,'2025'!F14) | G14: =AVERAGE('2010'!G14,'2011'!G14,'2012'!G14,'2013'!G14,'2014'!G14,'2015'!G14,'2016'!G14,'2017'!G14,'2018'!G14,'2019'!G14,'2020'!G14,'2021'!G14,'2022'!G14,'2023'!G14,'2024'!G14,'2025'!G14) | H14: =AVERAGE('2010'!H14,'2011'!H14,'2012'!H14,'2013'!H14,'2014'!H14,'2015'!H14,'2016'!H14,'2017'!H14,'2018'!H14,'2019'!H14,'2020'!H14,'2021'!H14,'2022'!H14,'2023'!H14,'2024'!H14,'2025'!H14) | I14: =AVERAGE('2010'!I14,'2011'!I14,'2012'!I14,'2013'!I14,'2014'!I14,'2015'!I14,'2016'!I14,'2017'!I14,'2018'!I14,'2019'!I14,'2020'!I14,'2021'!I14,'2022'!I14,'2023'!I14,'2024'!I14,'2025'!I14) | ... M14: =AVERAGE('2010'!M14,'2011'!M14,'2012'!M14,'2013'!M14,'2014'!M14,'2015'!M14,'2016'!M14,'2017'!M14,'2018'!M14,'2019'!M14,'2020'!M14,'2021'!M14,'2022'!M14,'2023'!M14,'2024'!M14,'2025'!M14) | N14: =AVERAGE(B14:M14)
A15: TRAJANJE SIJANJA SUNCA (h)
A16: Prosek | B16: =AVERAGE('2010'!B16,'2011'!B16,'2012'!B16,'2013'!B16,'2014'!B16,'2015'!B16,'2016'!B16,'2017'!B16,'2018'!B16,'2019'!B16,'2020'!B16,'2021'!B16,'2022'!B16,'2023'!B16,'2024'!B16,'2025'!B16) | C16: =AVERAGE('2010'!C16,'2011'!C16,'2012'!C16,'2013'!C16,'2014'!C16,'2015'!C16,'2016'!C16,'2017'!C16,'2018'!C16,'2019'!C16,'2020'!C16,'2021'!C16,'2022'!C16,'2023'!C16,'2024'!C16,'2025'!C16) | D16: =AVERAGE('2010'!D16,'2011'!D16,'2012'!D16,'2013'!D16,'2014'!D16,'2015'!D16,'2016'!D16,'2017'!D16,'2018'!D16,'2019'!D16,'2020'!D16,'2021'!D16,'2022'!D16,'2023'!D16,'2024'!D16,'2025'!D16) | E16: =AVERAGE('2010'!E16,'2011'!E16,'2012'!E16,'2013'!E16,'2014'!E16,'2015'!E16,'2016'!E16,'2017'!E16,'2018'!E16,'2019'!E16,'2020'!E16,'2021'!E16,'2022'!E16,'2023'!E16,'2024'!E16,'2025'!E16) | F16: =AVERAGE('2010'!F16,'2011'!F16,'2012'!F16,'2013'!F16,'2014'!F16,'2015'!F16,'2016'!F16,'2017'!F16,'2018'!F16,'2019'!F16,'2020'!F16,'2021'!F16,'2022'!F16,'2023'!F16,'2024'!F16,'2025'!F16) | G16: =AVERAGE('2010'!G16,'2011'!G16,'2012'!G16,'2013'!G16,'2014'!G16,'2015'!G16,'2016'!G16,'2017'!G16,'2018'!G16,'2019'!G16,'2020'!G16,'2021'!G16,'2022'!G16,'2023'!G16,'2024'!G16,'2025'!G16) | H16: =AVERAGE('2010'!H16,'2011'!H16,'2012'!H16,'2013'!H16,'2014'!H16,'2015'!H16,'2016'!H16,'2017'!H16,'2018'!H16,'2019'!H16,'2020'!H16,'2021'!H16,'2022'!H16,'2023'!H16,'2024'!H16,'2025'!H16) | I16: =AVERAGE('2010'!I16,'2011'!I16,'2012'!I16,'2013'!I16,'2014'!I16,'2015'!I16,'2016'!I16,'2017'!I16,'2018'!I16,'2019'!I16,'2020'!I16,'2021'!I16,'2022'!I16,'2023'!I16,'2024'!I16,'2025'!I16) | ... M16: =AVERAGE('2010'!M16,'2011'!M16,'2012'!M16,'2013'!M16,'2014'!M16,'2015'!M16,'2016'!M16,'2017'!M16,'2018'!M16,'2019'!M16,'2020'!M16,'2021'!M16,'2022'!M16,'2023'!M16,'2024'!M16,'2025'!M16) | N16: =SUM(B16:M16)
A17: Broj vedrih dana | B17: =AVERAGE('2010'!B17,'2011'!B17,'2012'!B17,'2013'!B17,'2014'!B17,'2015'!B17,'2016'!B17,'2017'!B17,'2018'!B17,'2019'!B17,'2020'!B17,'2021'!B17,'2022'!B17,'2023'!B17,'2024'!B17,'2025'!B17) | C17: =AVERAGE('2010'!C17,'2011'!C17,'2012'!C17,'2013'!C17,'2014'!C17,'2015'!C17,'2016'!C17,'2017'!C17,'2018'!C17,'2019'!C17,'2020'!C17,'2021'!C17,'2022'!C17,'2023'!C17,'2024'!C17,'2025'!C17) | D17: =AVERAGE('2010'!D17,'2011'!D17,'2012'!D17,'2013'!D17,'2014'!D17,'2015'!D17,'2016'!D17,'2017'!D17,'2018'!D17,'2019'!D17,'2020'!D17,'2021'!D17,'2022'!D17,'2023'!D17,'2024'!D17,'2025'!D17) | E17: =AVERAGE('2010'!E17,'2011'!E17,'2012'!E17,'2013'!E17,'2014'!E17,'2015'!E17,'2016'!E17,'2017'!E17,'2018'!E17,'2019'!E17,'2020'!E17,'2021'!E17,'2022'!E17,'2023'!E17,'2024'!E17,'2025'!E17) | F17: =AVERAGE('2010'!F17,'2011'!F17,'2012'!F17,'2013'!F17,'2014'!F17,'2015'!F17,'2016'!F17,'2017'!F17,'2018'!F17,'2019'!F17,'2020'!F17,'2021'!F17,'2022'!F17,'2023'!F17,'2024'!F17,'2025'!F17) | G17: =AVERAGE('2010'!G17,'2011'!G17,'2012'!G17,'2013'!G17,'2014'!G17,'2015'!G17,'2016'!G17,'2017'!G17,'2018'!G17,'2019'!G17,'2020'!G17,'2021'!G17,'2022'!G17,'2023'!G17,'2024'!G17,'2025'!G17) | H17: =AVERAGE('2010'!H17,'2011'!H17,'2012'!H17,'2013'!H17,'2014'!H17,'2015'!H17,'2016'!H17,'2017'!H17,'2018'!H17,'2019'!H17,'2020'!H17,'2021'!H17,'2022'!H17,'2023'!H17,'2024'!H17,'2025'!H17) | I17: =AVERAGE('2010'!I17,'2011'!I17,'2012'!I17,'2013'!I17,'2014'!I17,'2015'!I17,'2016'!I17,'2017'!I17,'2018'!I17,'2019'!I17,'2020'!I17,'2021'!I17,'2022'!I17,'2023'!I17,'2024'!I17,'2025'!I17) | ... M17: =AVERAGE('2010'!M17,'2011'!M17,'2012'!M17,'2013'!M17,'2014'!M17,'2015'!M17,'2016'!M17,'2017'!M17,'2018'!M17,'2019'!M17,'2020'!M17,'2021'!M17,'2022'!M17,'2023'!M17,'2024'!M17,'2025'!M17) | N17: =SUM(B17:M17)
A18: Broj oblačnih dana | B18: =AVERAGE('2010'!B18,'2011'!B18,'2012'!B18,'2013'!B18,'2014'!B18,'2015'!B18,'2016'!B18,'2017'!B18,'2018'!B18,'2019'!B18,'2020'!B18,'2021'!B18,'2022'!B18,'2023'!B18,'2024'!B18,'2025'!B18) | C18: =AVERAGE('2010'!C18,'2011'!C18,'2012'!C18,'2013'!C18,'2014'!C18,'2015'!C18,'2016'!C18,'2017'!C18,'2018'!C18,'2019'!C18,'2020'!C18,'2021'!C18,'2022'!C18,'2023'!C18,'2024'!C18,'2025'!C18) | D18: =AVERAGE('2010'!D18,'2011'!D18,'2012'!D18,'2013'!D18,'2014'!D18,'2015'!D18,'2016'!D18,'2017'!D18,'2018'!D18,'2019'!D18,'2020'!D18,'2021'!D18,'2022'!D18,'2023'!D18,'2024'!D18,'2025'!D18) | E18: =AVERAGE('2010'!E18,'2011'!E18,'2012'!E18,'2013'!E18,'2014'!E18,'2015'!E18,'2016'!E18,'2017'!E18,'2018'!E18,'2019'!E18,'2020'!E18,'2021'!E18,'2022'!E18,'2023'!E18,'2024'!E18,'2025'!E18) | F18: =AVERAGE('2010'!F18,'2011'!F18,'2012'!F18,'2013'!F18,'2014'!F18,'2015'!F18,'2016'!F18,'2017'!F18,'2018'!F18,'2019'!F18,'2020'!F18,'2021'!F18,'2022'!F18,'2023'!F18,'2024'!F18,'2025'!F18) | G18: =AVERAGE('2010'!G18,'2011'!G18,'2012'!G18,'2013'!G18,'2014'!G18,'2015'!G18,'2016'!G18,'2017'!G18,'2018'!G18,'2019'!G18,'2020'!G18,'2021'!G18,'2022'!G18,'2023'!G18,'2024'!G18,'2025'!G18) | H18: =AVERAGE('2010'!H18,'2011'!H18,'2012'!H18,'2013'!H18,'2014'!H18,'2015'!H18,'2016'!H18,'2017'!H18,'2018'!H18,'2019'!H18,'2020'!H18,'2021'!H18,'2022'!H18,'2023'!H18,'2024'!H18,'2025'!H18) | I18: =AVERAGE('2010'!I18,'2011'!I18,'2012'!I18,'2013'!I18,'2014'!I18,'2015'!I18,'2016'!I18,'2017'!I18,'2018'!I18,'2019'!I18,'2020'!I18,'2021'!I18,'2022'!I18,'2023'!I18,'2024'!I18,'2025'!I18) | ... M18: =AVERAGE('2010'!M18,'2011'!M18,'2012'!M18,'2013'!M18,'2014'!M18,'2015'!M18,'2016'!M18,'2017'!M18,'2018'!M18,'2019'!M18,'2020'!M18,'2021'!M18,'2022'!M18,'2023'!M18,'2024'!M18,'2025'!M18) | N18: =SUM(B18:M18)
A19: PADAVINE (mm)
A20: Sr. mesečna suma | B20: =AVERAGE('2010'!B20,'2011'!B20,'2012'!B20,'2013'!B20,'2014'!B20,'2015'!B20,'2016'!B20,'2017'!B20,'2018'!B20,'2019'!B20,'2020'!B20,'2021'!B20,'2022'!B20,'2023'!B20,'2024'!B20,'2025'!B20) | C20: =AVERAGE('2010'!C20,'2011'!C20,'2012'!C20,'2013'!C20,'2014'!C20,'2015'!C20,'2016'!C20,'2017'!C20,'2018'!C20,'2019'!C20,'2020'!C20,'2021'!C20,'2022'!C20,'2023'!C20,'2024'!C20,'2025'!C20) | D20: =AVERAGE('2010'!D20,'2011'!D20,'2012'!D20,'2013'!D20,'2014'!D20,'2015'!D20,'2016'!D20,'2017'!D20,'2018'!D20,'2019'!D20,'2020'!D20,'2021'!D20,'2022'!D20,'2023'!D20,'2024'!D20,'2025'!D20) | E20: =AVERAGE('2010'!E20,'2011'!E20,'2012'!E20,'2013'!E20,'2014'!E20,'2015'!E20,'2016'!E20,'2017'!E20,'2018'!E20,'2019'!E20,'2020'!E20,'2021'!E20,'2022'!E20,'2023'!E20,'2024'!E20,'2025'!E20) | F20: =AVERAGE('2010'!F20,'2011'!F20,'2012'!F20,'2013'!F20,'2014'!F20,'2015'!F20,'2016'!F20,'2017'!F20,'2018'!F20,'2019'!F20,'2020'!F20,'2021'!F20,'2022'!F20,'2023'!F20,'2024'!F20,'2025'!F20) | G20: =AVERAGE('2010'!G20,'2011'!G20,'2012'!G20,'2013'!G20,'2014'!G20,'2015'!G20,'2016'!G20,'2017'!G20,'2018'!G20,'2019'!G20,'2020'!G20,'2021'!G20,'2022'!G20,'2023'!G20,'2024'!G20,'2025'!G20) | H20: =AVERAGE('2010'!H20,'2011'!H20,'2012'!H20,'2013'!H20,'2014'!H20,'2015'!H20,'2016'!H20,'2017'!H20,'2018'!H20,'2019'!H20,'2020'!H20,'2021'!H20,'2022'!H20,'2023'!H20,'2024'!H20,'2025'!H20) | I20: =AVERAGE('2010'!I20,'2011'!I20,'2012'!I20,'2013'!I20,'2014'!I20,'2015'!I20,'2016'!I20,'2017'!I20,'2018'!I20,'2019'!I20,'2020'!I20,'2021'!I20,'2022'!I20,'2023'!I20,'2024'!I20,'2025'!I20) | ... M20: =AVERAGE('2010'!M20,'2011'!M20,'2012'!M20,'2013'!M20,'2014'!M20,'2015'!M20,'2016'!M20,'2017'!M20,'2018'!M20,'2019'!M20,'2020'!M20,'2021'!M20,'2022'!M20,'2023'!M20,'2024'!M20,'2025'!M20) | N20: =SUM(B20:M20)
A21: Max. dnevna suma | B21: =AVERAGE('2010'!B21,'2011'!B21,'2012'!B21,'2013'!B21,'2014'!B21,'2015'!B21,'2016'!B21,'2017'!B21,'2018'!B21,'2019'!B21,'2020'!B21,'2021'!B21,'2022'!B21,'2023'!B21,'2024'!B21,'2025'!B21) | C21: =AVERAGE('2010'!C21,'2011'!C21,'2012'!C21,'2013'!C21,'2014'!C21,'2015'!C21,'2016'!C21,'2017'!C21,'2018'!C21,'2019'!C21,'2020'!C21,'2021'!C21,'2022'!C21,'2023'!C21,'2024'!C21,'2025'!C21) | D21: =AVERAGE('2010'!D21,'2011'!D21,'2012'!D21,'2013'!D21,'2014'!D21,'2015'!D21,'2016'!D21,'2017'!D21,'2018'!D21,'2019'!D21,'2020'!D21,'2021'!D21,'2022'!D21,'2023'!D21,'2024'!D21,'2025'!D21) | E21: =AVERAGE('2010'!E21,'2011'!E21,'2012'!E21,'2013'!E21,'2014'!E21,'2015'!E21,'2016'!E21,'2017'!E21,'2018'!E21,'2019'!E21,'2020'!E21,'2021'!E21,'2022'!E21,'2023'!E21,'2024'!E21,'2025'!E21) | F21: =AVERAGE('2010'!F21,'2011'!F21,'2012'!F21,'2013'!F21,'2014'!F21,'2015'!F21,'2016'!F21,'2017'!F21,'2018'!F21,'2019'!F21,'2020'!F21,'2021'!F21,'2022'!F21,'2023'!F21,'2024'!F21,'2025'!F21) | G21: =AVERAGE('2010'!G21,'2011'!G21,'2012'!G21,'2013'!G21,'2014'!G21,'2015'!G21,'2016'!G21,'2017'!G21,'2018'!G21,'2019'!G21,'2020'!G21,'2021'!G21,'2022'!G21,'2023'!G21,'2024'!G21,'2025'!G21) | H21: =AVERAGE('2010'!H21,'2011'!H21,'2012'!H21,'2013'!H21,'2014'!H21,'2015'!H21,'2016'!H21,'2017'!H21,'2018'!H21,'2019'!H21,'2020'!H21,'2021'!H21,'2022'!H21,'2023'!H21,'2024'!H21,'2025'!H21) | I21: =AVERAGE('2010'!I21,'2011'!I21,'2012'!I21,'2013'!I21,'2014'!I21,'2015'!I21,'2016'!I21,'2017'!I21,'2018'!I21,'2019'!I21,'2020'!I21,'2021'!I21,'2022'!I21,'2023'!I21,'2024'!I21,'2025'!I21) | ... M21: =AVERAGE('2010'!M21,'2011'!M21,'2012'!M21,'2013'!M21,'2014'!M21,'2015'!M21,'2016'!M21,'2017'!M21,'2018'!M21,'2019'!M21,'2020'!M21,'2021'!M21,'2022'!M21,'2023'!M21,'2024'!M21,'2025'!M21) | N21: =MAX(B21:M21)
A22: Sr. br. dana >= 0.1 mm | B22: =AVERAGE('2010'!B22,'2011'!B22,'2012'!B22,'2013'!B22,'2014'!B22,'2015'!B22,'2016'!B22,'2017'!B22,'2018'!B22,'2019'!B22,'2020'!B22,'2021'!B22,'2022'!B22,'2023'!B22,'2024'!B22,'2025'!B22) | C22: =AVERAGE('2010'!C22,'2011'!C22,'2012'!C22,'2013'!C22,'2014'!C22,'2015'!C22,'2016'!C22,'2017'!C22,'2018'!C22,'2019'!C22,'2020'!C22,'2021'!C22,'2022'!C22,'2023'!C22,'2024'!C22,'2025'!C22) | D22: =AVERAGE('2010'!D22,'2011'!D22,'2012'!D22,'2013'!D22,'2014'!D22,'2015'!D22,'2016'!D22,'2017'!D22,'2018'!D22,'2019'!D22,'2020'!D22,'2021'!D22,'2022'!D22,'2023'!D22,'2024'!D22,'2025'!D22) | E22: =AVERAGE('2010'!E22,'2011'!E22,'2012'!E22,'2013'!E22,'2014'!E22,'2015'!E22,'2016'!E22,'2017'!E22,'2018'!E22,'2019'!E22,'2020'!E22,'2021'!E22,'2022'!E22,'2023'!E22,'2024'!E22,'2025'!E22) | F22: =AVERAGE('2010'!F22,'2011'!F22,'2012'!F22,'2013'!F22,'2014'!F22,'2015'!F22,'2016'!F22,'2017'!F22,'2018'!F22,'2019'!F22,'2020'!F22,'2021'!F22,'2022'!F22,'2023'!F22,'2024'!F22,'2025'!F22) | G22: =AVERAGE('2010'!G22,'2011'!G22,'2012'!G22,'2013'!G22,'2014'!G22,'2015'!G22,'2016'!G22,'2017'!G22,'2018'!G22,'2019'!G22,'2020'!G22,'2021'!G22,'2022'!G22,'2023'!G22,'2024'!G22,'2025'!G22) | H22: =AVERAGE('2010'!H22,'2011'!H22,'2012'!H22,'2013'!H22,'2014'!H22,'2015'!H22,'2016'!H22,'2017'!H22,'2018'!H22,'2019'!H22,'2020'!H22,'2021'!H22,'2022'!H22,'2023'!H22,'2024'!H22,'2025'!H22) | I22: =AVERAGE('2010'!I22,'2011'!I22,'2012'!I22,'2013'!I22,'2014'!I22,'2015'!I22,'2016'!I22,'2017'!I22,'2018'!I22,'2019'!I22,'2020'!I22,'2021'!I22,'2022'!I22,'2023'!I22,'2024'!I22,'2025'!I22) | ... M22: =AVERAGE('2010'!M22,'2011'!M22,'2012'!M22,'2013'!M22,'2014'!M22,'2015'!M22,'2016'!M22,'2017'!M22,'2018'!M22,'2019'!M22,'2020'!M22,'2021'!M22,'2022'!M22,'2023'!M22,'2024'!M22,'2025'!M22) | N22: =SUM(B22:M22)
A23: Sr. br. dana >= 10.0 mm | B23: =AVERAGE('2010'!B23,'2011'!B23,'2012'!B23,'2013'!B23,'2014'!B23,'2015'!B23,'2016'!B23,'2017'!B23,'2018'!B23,'2019'!B23,'2020'!B23,'2021'!B23,'2022'!B23,'2023'!B23,'2024'!B23,'2025'!B23) | C23: =AVERAGE('2010'!C23,'2011'!C23,'2012'!C23,'2013'!C23,'2014'!C23,'2015'!C23,'2016'!C23,'2017'!C23,'2018'!C23,'2019'!C23,'2020'!C23,'2021'!C23,'2022'!C23,'2023'!C23,'2024'!C23,'2025'!C23) | D23: =AVERAGE('2010'!D23,'2011'!D23,'2012'!D23,'2013'!D23,'2014'!D23,'2015'!D23,'2016'!D23,'2017'!D23,'2018'!D23,'2019'!D23,'2020'!D23,'2021'!D23,'2022'!D23,'2023'!D23,'2024'!D23,'2025'!D23) | E23: =AVERAGE('2010'!E23,'2011'!E23,'2012'!E23,'2013'!E23,'2014'!E23,'2015'!E23,'2016'!E23,'2017'!E23,'2018'!E23,'2019'!E23,'2020'!E23,'2021'!E23,'2022'!E23,'2023'!E23,'2024'!E23,'2025'!E23) | F23: =AVERAGE('2010'!F23,'2011'!F23,'2012'!F23,'2013'!F23,'2014'!F23,'2015'!F23,'2016'!F23,'2017'!F23,'2018'!F23,'2019'!F23,'2020'!F23,'2021'!F23,'2022'!F23,'2023'!F23,'2024'!F23,'2025'!F23) | G23: =AVERAGE('2010'!G23,'2011'!G23,'2012'!G23,'2013'!G23,'2014'!G23,'2015'!G23,'2016'!G23,'2017'!G23,'2018'!G23,'2019'!G23,'2020'!G23,'2021'!G23,'2022'!G23,'2023'!G23,'2024'!G23,'2025'!G23) | H23: =AVERAGE('2010'!H23,'2011'!H23,'2012'!H23,'2013'!H23,'2014'!H23,'2015'!H23,'2016'!H23,'2017'!H23,'2018'!H23,'2019'!H23,'2020'!H23,'2021'!H23,'2022'!H23,'2023'!H23,'2024'!H23,'2025'!H23) | I23: =AVERAGE('2010'!I23,'2011'!I23,'2012'!I23,'2013'!I23,'2014'!I23,'2015'!I23,'2016'!I23,'2017'!I23,'2018'!I23,'2019'!I23,'2020'!I23,'2021'!I23,'2022'!I23,'2023'!I23,'2024'!I23,'2025'!I23) | ... M23: =AVERAGE('2010'!M23,'2011'!M23,'2012'!M23,'2013'!M23,'2014'!M23,'2015'!M23,'2016'!M23,'2017'!M23,'2018'!M23,'2019'!M23,'2020'!M23,'2021'!M23,'2022'!M23,'2023'!M23,'2024'!M23,'2025'!M23) | N23: =SUM(B23:M23)
A24: POJAVE (broj dana sa....)
A25: snegom | B25: =AVERAGE('2010'!B25,'2011'!B25,'2012'!B25,'2013'!B25,'2014'!B25,'2015'!B25,'2016'!B25,'2017'!B25,'2018'!B25,'2019'!B25,'2020'!B25,'2021'!B25,'2022'!B25,'2023'!B25,'2024'!B25,'2025'!B25) | C25: =AVERAGE('2010'!C25,'2011'!C25,'2012'!C25,'2013'!C25,'2014'!C25,'2015'!C25,'2016'!C25,'2017'!C25,'2018'!C25,'2019'!C25,'2020'!C25,'2021'!C25,'2022'!C25,'2023'!C25,'2024'!C25,'2025'!C25) | D25: =AVERAGE('2010'!D25,'2011'!D25,'2012'!D25,'2013'!D25,'2014'!D25,'2015'!D25,'2016'!D25,'2017'!D25,'2018'!D25,'2019'!D25,'2020'!D25,'2021'!D25,'2022'!D25,'2023'!D25,'2024'!D25,'2025'!D25) | E25: =AVERAGE('2010'!E25,'2011'!E25,'2012'!E25,'2013'!E25,'2014'!E25,'2015'!E25,'2016'!E25,'2017'!E25,'2018'!E25,'2019'!E25,'2020'!E25,'2021'!E25,'2022'!E25,'2023'!E25,'2024'!E25,'2025'!E25) | F25: =AVERAGE('2010'!F25,'2011'!F25,'2012'!F25,'2013'!F25,'2014'!F25,'2015'!F25,'2016'!F25,'2017'!F25,'2018'!F25,'2019'!F25,'2020'!F25,'2021'!F25,'2022'!F25,'2023'!F25,'2024'!F25,'2025'!F25) | G25: =AVERAGE('2010'!G25,'2011'!G25,'2012'!G25,'2013'!G25,'2014'!G25,'2015'!G25,'2016'!G25,'2017'!G25,'2018'!G25,'2019'!G25,'2020'!G25,'2021'!G25,'2022'!G25,'2023'!G25,'2024'!G25,'2025'!G25) | H25: =AVERAGE('2010'!H25,'2011'!H25,'2012'!H25,'2013'!H25,'2014'!H25,'2015'!H25,'2016'!H25,'2017'!H25,'2018'!H25,'2019'!H25,'2020'!H25,'2021'!H25,'2022'!H25,'2023'!H25,'2024'!H25,'2025'!H25) | I25: =AVERAGE('2010'!I25,'2011'!I25,'2012'!I25,'2013'!I25,'2014'!I25,'2015'!I25,'2016'!I25,'2017'!I25,'2018'!I25,'2019'!I25,'2020'!I25,'2021'!I25,'2022'!I25,'2023'!I25,'2024'!I25,'2025'!I25) | ... M25: =AVERAGE('2010'!M25,'2011'!M25,'2012'!M25,'2013'!M25,'2014'!M25,'2015'!M25,'2016'!M25,'2017'!M25,'2018'!M25,'2019'!M25,'2020'!M25,'2021'!M25,'2022'!M25,'2023'!M25,'2024'!M25,'2025'!M25) | N25: =SUM(B25:M25)
A26: snežnim pokrivačem | B26: =AVERAGE('2010'!B26,'2011'!B26,'2012'!B26,'2013'!B26,'2014'!B26,'2015'!B26,'2016'!B26,'2017'!B26,'2018'!B26,'2019'!B26,'2020'!B26,'2021'!B26,'2022'!B26,'2023'!B26,'2024'!B26,'2025'!B26) | C26: =AVERAGE('2010'!C26,'2011'!C26,'2012'!C26,'2013'!C26,'2014'!C26,'2015'!C26,'2016'!C26,'2017'!C26,'2018'!C26,'2019'!C26,'2020'!C26,'2021'!C26,'2022'!C26,'2023'!C26,'2024'!C26,'2025'!C26) | D26: =AVERAGE('2010'!D26,'2011'!D26,'2012'!D26,'2013'!D26,'2014'!D26,'2015'!D26,'2016'!D26,'2017'!D26,'2018'!D26,'2019'!D26,'2020'!D26,'2021'!D26,'2022'!D26,'2023'!D26,'2024'!D26,'2025'!D26) | E26: =AVERAGE('2010'!E26,'2011'!E26,'2012'!E26,'2013'!E26,'2014'!E26,'2015'!E26,'2016'!E26,'2017'!E26,'2018'!E26,'2019'!E26,'2020'!E26,'2021'!E26,'2022'!E26,'2023'!E26,'2024'!E26,'2025'!E26) | F26: =AVERAGE('2010'!F26,'2011'!F26,'2012'!F26,'2013'!F26,'2014'!F26,'2015'!F26,'2016'!F26,'2017'!F26,'2018'!F26,'2019'!F26,'2020'!F26,'2021'!F26,'2022'!F26,'2023'!F26,'2024'!F26,'2025'!F26) | G26: =AVERAGE('2010'!G26,'2011'!G26,'2012'!G26,'2013'!G26,'2014'!G26,'2015'!G26,'2016'!G26,'2017'!G26,'2018'!G26,'2019'!G26,'2020'!G26,'2021'!G26,'2022'!G26,'2023'!G26,'2024'!G26,'2025'!G26) | H26: =AVERAGE('2010'!H26,'2011'!H26,'2012'!H26,'2013'!H26,'2014'!H26,'2015'!H26,'2016'!H26,'2017'!H26,'2018'!H26,'2019'!H26,'2020'!H26,'2021'!H26,'2022'!H26,'2023'!H26,'2024'!H26,'2025'!H26) | I26: =AVERAGE('2010'!I26,'2011'!I26,'2012'!I26,'2013'!I26,'2014'!I26,'2015'!I26,'2016'!I26,'2017'!I26,'2018'!I26,'2019'!I26,'2020'!I26,'2021'!I26,'2022'!I26,'2023'!I26,'2024'!I26,'2025'!I26) | ... M26: =AVERAGE('2010'!M26,'2011'!M26,'2012'!M26,'2013'!M26,'2014'!M26,'2015'!M26,'2016'!M26,'2017'!M26,'2018'!M26,'2019'!M26,'2020'!M26,'2021'!M26,'2022'!M26,'2023'!M26,'2024'!M26,'2025'!M26) | N26: =SUM(B26:M26)
A27: maglom | B27: =AVERAGE('2010'!B27,'2011'!B27,'2012'!B27,'2013'!B27,'2014'!B27,'2015'!B27,'2016'!B27,'2017'!B27,'2018'!B27,'2019'!B27,'2020'!B27,'2021'!B27,'2022'!B27,'2023'!B27,'2024'!B27,'2025'!B27) | C27: =AVERAGE('2010'!C27,'2011'!C27,'2012'!C27,'2013'!C27,'2014'!C27,'2015'!C27,'2016'!C27,'2017'!C27,'2018'!C27,'2019'!C27,'2020'!C27,'2021'!C27,'2022'!C27,'2023'!C27,'2024'!C27,'2025'!C27) | D27: =AVERAGE('2010'!D27,'2011'!D27,'2012'!D27,'2013'!D27,'2014'!D27,'2015'!D27,'2016'!D27,'2017'!D27,'2018'!D27,'2019'!D27,'2020'!D27,'2021'!D27,'2022'!D27,'2023'!D27,'2024'!D27,'2025'!D27) | E27: =AVERAGE('2010'!E27,'2011'!E27,'2012'!E27,'2013'!E27,'2014'!E27,'2015'!E27,'2016'!E27,'2017'!E27,'2018'!E27,'2019'!E27,'2020'!E27,'2021'!E27,'2022'!E27,'2023'!E27,'2024'!E27,'2025'!E27) | F27: =AVERAGE('2010'!F27,'2011'!F27,'2012'!F27,'2013'!F27,'2014'!F27,'2015'!F27,'2016'!F27,'2017'!F27,'2018'!F27,'2019'!F27,'2020'!F27,'2021'!F27,'2022'!F27,'2023'!F27,'2024'!F27,'2025'!F27) | G27: =AVERAGE('2010'!G27,'2011'!G27,'2012'!G27,'2013'!G27,'2014'!G27,'2015'!G27,'2016'!G27,'2017'!G27,'2018'!G27,'2019'!G27,'2020'!G27,'2021'!G27,'2022'!G27,'2023'!G27,'2024'!G27,'2025'!G27) | H27: =AVERAGE('2010'!H27,'2011'!H27,'2012'!H27,'2013'!H27,'2014'!H27,'2015'!H27,'2016'!H27,'2017'!H27,'2018'!H27,'2019'!H27,'2020'!H27,'2021'!H27,'2022'!H27,'2023'!H27,'2024'!H27,'2025'!H27) | I27: =AVERAGE('2010'!I27,'2011'!I27,'2012'!I27,'2013'!I27,'2014'!I27,'2015'!I27,'2016'!I27,'2017'!I27,'2018'!I27,'2019'!I27,'2020'!I27,'2021'!I27,'2022'!I27,'2023'!I27,'2024'!I27,'2025'!I27) | ... M27: =AVERAGE('2010'!M27,'2011'!M27,'2012'!M27,'2013'!M27,'2014'!M27,'2015'!M27,'2016'!M27,'2017'!M27,'2018'!M27,'2019'!M27,'2020'!M27,'2021'!M27,'2022'!M27,'2023'!M27,'2024'!M27,'2025'!M27) | N27: =SUM(B27:M27)
A28: gradom | B28: =AVERAGE('2010'!B28,'2011'!B28,'2012'!B28,'2013'!B28,'2014'!B28,'2015'!B28,'2016'!B28,'2017'!B28,'2018'!B28,'2019'!B28,'2020'!B28,'2021'!B28,'2022'!B28,'2023'!B28,'2024'!B28,'2025'!B28) | C28: =AVERAGE('2010'!C28,'2011'!C28,'2012'!C28,'2013'!C28,'2014'!C28,'2015'!C28,'2016'!C28,'2017'!C28,'2018'!C28,'2019'!C28,'2020'!C28,'2021'!C28,'2022'!C28,'2023'!C28,'2024'!C28,'2025'!C28) | D28: =AVERAGE('2010'!D28,'2011'!D28,'2012'!D28,'2013'!D28,'2014'!D28,'2015'!D28,'2016'!D28,'2017'!D28,'2018'!D28,'2019'!D28,'2020'!D28,'2021'!D28,'2022'!D28,'2023'!D28,'2024'!D28,'2025'!D28) | E28: =AVERAGE('2010'!E28,'2011'!E28,'2012'!E28,'2013'!E28,'2014'!E28,'2015'!E28,'2016'!E28,'2017'!E28,'2018'!E28,'2019'!E28,'2020'!E28,'2021'!E28,'2022'!E28,'2023'!E28,'2024'!E28,'2025'!E28) | F28: =AVERAGE('2010'!F28,'2011'!F28,'2012'!F28,'2013'!F28,'2014'!F28,'2015'!F28,'2016'!F28,'2017'!F28,'2018'!F28,'2019'!F28,'2020'!F28,'2021'!F28,'2022'!F28,'2023'!F28,'2024'!F28,'2025'!F28) | G28: =AVERAGE('2010'!G28,'2011'!G28,'2012'!G28,'2013'!G28,'2014'!G28,'2015'!G28,'2016'!G28,'2017'!G28,'2018'!G28,'2019'!G28,'2020'!G28,'2021'!G28,'2022'!G28,'2023'!G28,'2024'!G28,'2025'!G28) | H28: =AVERAGE('2010'!H28,'2011'!H28,'2012'!H28,'2013'!H28,'2014'!H28,'2015'!H28,'2016'!H28,'2017'!H28,'2018'!H28,'2019'!H28,'2020'!H28,'2021'!H28,'2022'!H28,'2023'!H28,'2024'!H28,'2025'!H28) | I28: =AVERAGE('2010'!I28,'2011'!I28,'2012'!I28,'2013'!I28,'2014'!I28,'2015'!I28,'2016'!I28,'2017'!I28,'2018'!I28,'2019'!I28,'2020'!I28,'2021'!I28,'2022'!I28,'2023'!I28,'2024'!I28,'2025'!I28) | ... M28: =AVERAGE('2010'!M28,'2011'!M28,'2012'!M28,'2013'!M28,'2014'!M28,'2015'!M28,'2016'!M28,'2017'!M28,'2018'!M28,'2019'!M28,'2020'!M28,'2021'!M28,'2022'!M28,'2023'!M28,'2024'!M28,'2025'!M28) | N28: =SUM(B28:M28)

Sheet 2010
A1: PROSEČNE MESEČNE, GODIŠNJE I EKSTREMNE VREDNOSTI ZA 2010. GODINU
A2: CMILJEVAC II φ 43.11°N λ 17.66°E h 1295 m
A4: METEOROLOŠKI PARAMETAR | B4: jan | C4: feb | D4: mar | E4: apr | F4: maj | G4: jun | H4: jul | I4: avg | J4: sep | K4: okt | L4: nov | M4: dec | N4: god.
A5: TEMPERATURA VAZDUHA (°C)
A6: Normalna vrednost | B6: 2.9 | C6: 4.7 | D6: 6.8 | E6: 11.8 | F6: 15 | G6: 19.8 | H6: 24.2 | I6: 24.6 | J6: 17.8 | K6: 11.7 | L6: 10.2 | M6: 4.3 | N6: =AVERAGE(B6:M6)
A7: Srednja maksimalna | B7: 7.5 | C7: 9 | D7: 12.1 | E7: 17.5 | F7: 19.9 | G7: 25.1 | H7: 30 | I7: 31 | J7: 23.4 | K7: 16.6 | L7: 14.6 | M7: 8 | N7: =AVERAGE(B7:M7)
A8: Srednja minimalna | B8: -1.1 | C8: 0.3 | D8: 1 | E8: 5.5 | F8: 9.1 | G8: 13 | H8: 16.8 | I8: 16.4 | J8: 12.1 | K8: 6.9 | L8: 6.3 | M8: 0.5 | N8: =AVERAGE(B8:M8)
A9: Apsolutni maksimum | B9: 13.6 | C9: 13.5 | D9: 17.8 | E9: 22.2 | F9: 25 | G9: 31.5 | H9: 36.2 | I9: 34.5 | J9: 26.8 | K9: 21.2 | L9: 20.5 | M9: 15.1 | N9: =MAX(B9:M9)
A10: Apsolutni minimum | B10: -9.7 | C10: -7.7 | D10: -5.8 | E10: 0.9 | F10: 5.3 | G10: 7 | H10: 12.7 | I10: 11.9 | J10: 5.7 | K10: -0.3 | L10: 1.8 | M10: -8.2 | N10: =MIN(B10:M10)
A11: Sr. br. mraznih dana | B11: 21 | C11: 12 | D11: 13 | E11: 0 | F11: 0 | G11: 0 | H11: 0 | I11: 0 | J11: 0 | K11: 1 | L11: 0 | M11: 17 | N11: =SUM(B11:M11)
A12: Sr. br. tropskih dana | B12: 0 | C12: 0 | D12: 0 | E12: 0 | F12: 0 | G12: 5 | H12: 18 | I12: 22 | J12: 0 | K12: 0 | L12: 0 | M12: 0 | N12: =SUM(B12:M12)
A13: RELATIVNA VLAGA (%)
A14: Prosek | B14: 77.6 | C14: 81 | D14: 74 | E14: 72.5 | F14: 73.4 | G14: 69.3 | H14: 57.9 | I14: 52.2 | J14: 69.5 | K14: 76.6 | L14: 87.1 | M14: 77.1 | N14: =AVERAGE(B14:M14)
A15: TRAJANJE SIJANJA SUNCA (h)
A16: Prosek | B16: 178.6 | C16: 145.1 | D16: 267.6 | E16: 302.3 | F16: 360.1 | G16: 395.8 | H16: 431.8 | I16: 414.8 | J16: 317.3 | K16: 239.1 | L16: 163.7 | M16: 181.3 | N16: =SUM(B16:M16)
A17: Broj vedrih dana | B17: 7 | C17: 1 | D17: 2 | E17: 5 | F17: 2 | G17: 9 | H17: 15 | I17: 23 | J17: 8 | K17: 9 | L17: 5 | M17: 6 | N17: =SUM(B17:M17)
A18: Broj oblačnih dana | B18: 14 | C18: 16 | D18: 9 | E18: 8 | F18: 10 | G18: 4 | H18: 0 | I18: 0 | J18: 4 | K18: 10 | L18: 14 | M18: 12 | N18: =SUM(B18:M18)
A19: PADAVINE (mm)
A20: Sr. mesečna suma | B20: 280.8 | C20: 271.7 | D20: 202.6 | E20: 166.5 | F20: 180.4 | G20: 94.4 | H20: 17.8 | I20: 24.4 | J20: 179.8 | K20: 172 | L20: 361.4 | M20: 235.5 | N20: =SUM(B20:M20)
A21: Max. dnevna suma | B21: 61 | C21: 42.9 | D21: 58.2 | E21: 46.5 | F21: 59.5 | G21: 41.9 | H21: 5.7 | I21: 12.4 | J21: 63.2 | K21: 37.3 | L21: 59.8 | M21: 41.2 | N21: =MAX(B21:M21)
A22: Sr. br. dana >= 0.1 mm | B22: 16 | C22: 20 | D22: 19 | E22: 20 | F22: 17 | G22: 14 | H22: 15 | I22: 9 | J22: 13 | K22: 16 | L22: 23 | M22: 21 | N22: =SUM(B22:M22)
A23: Sr. br. dana >= 10.0 mm | B23: 10 | C23: 13 | D23: 6 | E23: 6 | F23: 5 | G23: 4 | H23: 0 | I23: 1 | J23: 6 | K23: 6 | L23: 13 | M23: 9 | N23: =SUM(B23:M23)
A24: POJAVE (broj dana sa....)
A25: snegom | B25: 5 | C25: 2 | D25: 4 | E25: 0 | F25: 0 | G25: 0 | H25: 0 | I25: 0 | J25: 0 | K25: 0 | L25: 0 | M25: 6 | N25: =SUM(B25:M25)
A26: snežnim pokrivačem | B26: 5 | C26: 2 | D26: 4 | E26: 0 | F26: 0 | G26: 0 | H26: 0 | I26: 0 | J26: 0 | K26: 0 | L26: 0 | M26: 6 | N26: =SUM(B26:M26)
A27: maglom | B27: 0 | C27: 0 | D27: 0 | E27: 0 | F27: 0 | G27: 0 | H27: 0 | I27: 0 | J27: 0 | K27: 0 | L27: 0 | M27: 0 | N27: =SUM(B27:M27)
A28: gradom | B28: 0 | C28: 0 | D28: 0 | E28: 0 | F28: 0 | G28: 0 | H28: 0 | I28: 0 | J28: 0 | K28: 0 | L28: 0 | M28: 0 | N28: =SUM(B28:M28)

Sheet 2011
A1: PROSEČNE MESEČNE, GODIŠNJE I EKSTREMNE VREDNOSTI ZA 2011. GODINU
A2: CMILJEVAC II φ 43.11°N λ 17.66°E h 1295 m
A4: METEOROLOŠKI PARAMETAR | B4: jan | C4: feb | D4: mar | E4: apr | F4: maj | G4: jun | H4: jul | I4: avg | J4: sep | K4: okt | L4: nov | M4: dec | N4: god.
A5: TEMPERATURA VAZDUHA (°C)
A6: Normalna vrednost | B6: 2.5 | C6: 3.3 | D6: 7.1 | E6: 12.3 | F6: 16.3 | G6: 21.5 | H6: 22.8 | I6: 24.7 | J6: 22 | K6: 12.7 | L6: 7 | M6: 4.7 | N6: =AVERAGE(B6:M6)
A7: Srednja maksimalna | B7: 8.1 | C7: 9.9 | D7: 12.6 | E7: 18.6 | F7: 22 | G7: 27.1 | H7: 28.2 | I7: 31.3 | J7: 28.5 | K7: 18.3 | L7: 13.9 | M7: 9.4 | N7: =AVERAGE(B7:M7)
A8: Srednja minimalna | B8: -2.1 | C8: -2 | D8: 1.5 | E8: 4.6 | F8: 9.3 | G8: 14.1 | H8: 16 | I8: 16.5 | J8: 14.6 | K8: 7.2 | L8: 1.6 | M8: 0.6 | N8: =AVERAGE(B8:M8)
A9: Apsolutni maksimum | B9: 13.9 | C9: 17.6 | D9: 19.3 | E9: 23.4 | F9: 26.9 | G9: 32.8 | H9: 35.2 | I9: 36.3 | J9: 33 | K9: 26.6 | L9: 17.4 | M9: 13.9 | N9: =MAX(B9:M9)
A10: Apsolutni minimum | B10: -12.4 | C10: -6.1 | D10: -4.4 | E10: -1.7 | F10: 2.1 | G10: 11.4 | H10: 11.7 | I10: 11.9 | J10: 9.9 | K10: -1.5 | L10: -3.7 | M10: -5.8 | N10: =MIN(B10:M10)
A11: Sr. br. mraznih dana | B11: 23 | C11: 21 | D11: 9 | E11: 1 | F11: 0 | G11: 0 | H11: 0 | I11: 0 | J11: 0 | K11: 2 | L11: 13 | M11: 17 | N11: =SUM(B11:M11)
A12: Sr. br. tropskih dana | B12: 0 | C12: 0 | D12: 0 | E12: 0 | F12: 0 | G12: 4 | H12: 12 | I12: 20 | J12: 12 | K12: 0 | L12: 0 | M12: 0 | N12: =SUM(B12:M12)
A13: RELATIVNA VLAGA (%)
A14: Prosek | B14: 78.9 | C14: 72.6 | D14: 70.7 | E14: 63 | F14: 69.2 | G14: 59.5 | H14: 63 | I14: 55.1 | J14: 59.9 | K14: 68 | L14: 75.7 | M14: 81.5 | N14: =AVERAGE(B14:M14)
A15: TRAJANJE SIJANJA SUNCA (h)
A16: Prosek | B16: 206 | C16: 225.6 | D16: 284.3 | E16: 347.1 | F16: 383.5 | G16: 418.7 | H16: 411.5 | I16: 414.2 | J16: 335.5 | K16: 294.8 | L16: 243.7 | M16: 189.7 | N16: =SUM(B16:M16)
A17: Broj vedrih dana | B17: 3 | C17: 9 | D17: 11 | E17: 10 | F17: 9 | G17: 13 | H17: 16 | I17: 28 | J17: 16 | K17: 13 | L17: 13 | M17: 6 | N17: =SUM(B17:M17)
A18: Broj oblačnih dana | B18: 10 | C18: 7 | D18: 9 | E18: 4 | F18: 5 | G18: 0 | H18: 1 | I18: 0 | J18: 2 | K18: 5 | L18: 5 | M18: 12 | N18: =SUM(B18:M18)
A19: PADAVINE (mm)
A20: Sr. mesečna suma | B20: 72 | C20: 61.7 | D20: 112.5 | E20: 39.4 | F20: 119 | G20: 32.5 | H20: 120.6 | I20: 1.5 | J20: 57.7 | K20: 76.7 | L20: 89.9 | M20: 192.8 | N20: =SUM(B20:M20)
A21: Max. dnevna suma | B21: 28.7 | C21: 14 | D21: 32.2 | E21: 18.6 | F21: 33.8 | G21: 11.7 | H21: 39.7 | I21: 1.1 | J21: 37.1 | K21: 34.6 | L21: 30.7 | M21: 38.6 | N21: =MAX(B21:M21)
A22: Sr. br. dana >= 0.1 mm | B22: 9 | C22: 10 | D22: 15 | E22: 6 | F22: 22 | G22: 12 | H22: 15 | I22: 4 | J22: 5 | K22: 11 | L22: 7 | M22: 20 | N22: =SUM(B22:M22)
A23: Sr. br. dana >= 10.0 mm | B23: 3 | C23: 3 | D23: 5 | E23: 1 | F23: 3 | G23: 1 | H23: 4 | I23: 0 | J23: 2 | K23: 3 | L23: 4 | M23: 8 | N23: =SUM(B23:M23)
A24: POJAVE (broj dana sa....)
A25: snegom | B25: 4 | C25: 5 | D25: 1 | E25: 1 | F25: 0 | G25: 0 | H25: 0 | I25: 0 | J25: 0 | K25: 0 | L25: 0 | M25: 0 | N25: =SUM(B25:M25)
A26: snežnim pokrivačem | B26: 4 | C26: 5 | D26: 1 | E26: 1 | F26: 0 | G26: 0 | H26: 0 | I26: 0 | J26: 0 | K26: 0 | L26: 0 | M26: 0 | N26: =SUM(B26:M26)
A27: maglom | B27: 0 | C27: 0 | D27: 0 | E27: 0 | F27: 0 | G27: 0 | H27: 0 | I27: 0 | J27: 0 | K27: 0 | L27: 0 | M27: 0 | N27: =SUM(B27:M27)
A28: gradom | B28: 0 | C28: 0 | D28: 0 | E28: 0 | F28: 0 | G28: 0 | H28: 0 | I28: 0 | J28: 0 | K28: 0 | L28: 0 | M28: 0 | N28: =SUM(B28:M28)

Sheet 2012
A1: PROSEČNE MESEČNE, GODIŠNJE I EKSTREMNE VREDNOSTI ZA 2012. GODINU
A2: CMILJEVAC II φ 43.11°N λ 17.66°E h 1295 m
A4: METEOROLOŠKI PARAMETAR | B4: jan | C4: feb | D4: mar | E4: apr | F4: maj | G4: jun | H4: jul | I4: avg | J4: sep | K4: okt | L4: nov | M4: dec | N4: god.
A5: TEMPERATURA VAZDUHA (°C)
A6: Normalna vrednost | B6: 1.8 | C6: -2.3 | D6: 8.5 | E6: 11 | F6: 15.4 | G6: 22.9 | H6: 26.3 | I6: 26.2 | J6: 20.2 | K6: 14.6 | L6: 10.8 | M6: 3 | N6: =AVERAGE(B6:M6)
A7: Srednja maksimalna | B7: 6.9 | C7: 3 | D7: 15.6 | E7: 15.8 | F7: 21.2 | G7: 29 | H7: 32.7 | I7: 33.1 | J7: 26.1 | K7: 20.4 | L7: 15.4 | M7: 7.6 | N7: =AVERAGE(B7:M7)
A8: Srednja minimalna | B8: -2.5 | C8: -7.1 | D8: 1 | E8: 5.5 | F8: 8.4 | G8: 14.8 | H8: 17.8 | I8: 17.6 | J8: 13.7 | K8: 9.1 | L8: 6.9 | M8: -1 | N8: =AVERAGE(B8:M8)
A9: Apsolutni maksimum | B9: 11.4 | C9: 14.8 | D9: 21 | E9: 27.1 | F9: 27.6 | G9: 34.4 | H9: 36.2 | I9: 38.3 | J9: 31.7 | K9: 27.4 | L9: 19.5 | M9: 12.3 | N9: =MAX(B9:M9)
A10: Apsolutni minimum | B10: -6.3 | C10: -16.9 | D10: -2.7 | E10: -2.9 | F10: 4 | G10: 9.6 | H10: 14.8 | I10: 13.3 | J10: 5.9 | K10: 2.2 | L10: 1.3 | M10: -9.4 | N10: =MIN(B10:M10)
A11: Sr. br. mraznih dana | B11: 25 | C11: 28 | D11: 13 | E11: 2 | F11: 0 | G11: 0 | H11: 0 | I11: 0 | J11: 0 | K11: 0 | L11: 0 | M11: 19 | N11: =SUM(B11:M11)
A12: Sr. br. tropskih dana | B12: 0 | C12: 0 | D12: 0 | E12: 0 | F12: 0 | G12: 13 | H12: 27 | I12: 26 | J12: 8 | K12: 0 | L12: 0 | M12: 0 | N12: =SUM(B12:M12)
A13: RELATIVNA VLAGA (%)
A14: Prosek | B14: 70.9 | C14: 72.4 | D14: 64.7 | E14: 77.7 | F14: 71 | G14: 60 | H14: 49.6 | I14: 43.5 | J14: 62.3 | K14: 78.5 | L14: 84.2 | M14: 78.2 | N14: =AVERAGE(B14:M14)
A15: TRAJANJE SIJANJA SUNCA (h)
A16: Prosek | B16: 218.4 | C16: 192.1 | D16: 353.9 | E16: 263.3 | F16: 391.4 | G16: 422.2 | H16: 427.1 | I16: 415.8 | J16: 318.4 | K16: 273.1 | L16: 201.5 | M16: 174.4 | N16: =SUM(B16:M16)
A17: Broj vedrih dana | B17: 10 | C17: 3 | D17: 14 | E17: 7 | F17: 11 | G17: 19 | H17: 25 | I17: 24 | J17: 12 | K17: 10 | L17: 1 | M17: 5 | N17: =SUM(B17:M17)
A18: Broj oblačnih dana | B18: 7 | C18: 10 | D18: 1 | E18: 13 | F18: 4 | G18: 1 | H18: 2 | I18: 0 | J18: 2 | K18: 6 | L18: 10 | M18: 11 | N18: =SUM(B18:M18)
A19: PADAVINE (mm)
A20: Sr. mesečna suma | B20: 54 | C20: 171.1 | D20: 4.8 | E20: 245.4 | F20: 119 | G20: 18.5 | H20: 17.5 | I20: 0.9 | J20: 107.2 | K20: 252.2 | L20: 197.1 | M20: 194.2 | N20: =SUM(B20:M20)
A21: Max. dnevna suma | B21: 12.8 | C21: 41.4 | D21: 2.5 | E21: 25 | F21: 32.1 | G21: 18.3 | H21: 12.6 | I21: 0.6 | J21: 32.6 | K21: 59.6 | L21: 50.4 | M21: 49.6 | N21: =MAX(B21:M21)
A22: Sr. br. dana >= 0.1 mm | B22: 9 | C22: 17 | D22: 8 | E22: 23 | F22: 18 | G22: 3 | H22: 8 | I22: 2 | J22: 10 | K22: 15 | L22: 15 | M22: 19 | N22: =SUM(B22:M22)
A23: Sr. br. dana >= 10.0 mm | B23: 2 | C23: 6 | D23: 0 | E23: 11 | F23: 5 | G23: 1 | H23: 1 | I23: 0 | J23: 3 | K23: 9 | L23: 5 | M23: 6 | N23: =SUM(B23:M23)
A24: POJAVE (broj dana sa....)
A25: snegom | B25: 1 | C25: 12 | D25: 0 | E25: 1 | F25: 0 | G25: 0 | H25: 0 | I25: 0 | J25: 0 | K25: 0 | L25: 0 | M25: 5 | N25: =SUM(B25:M25)
A26: snežnim pokrivačem | B26: 1 | C26: 12 | D26: 0 | E26: 1 | F26: 0 | G26: 0 | H26: 0 | I26: 0 | J26: 0 | K26: 0 | L26: 0 | M26: 5 | N26: =SUM(B26:M26)
A27: maglom | B27: 0 | C27: 0 | D27: 0 | E27: 0 | F27: 0 | G27: 0 | H27: 0 | I27: 0 | J27: 0 | K27: 0 | L27: 0 | M27: 0 | N27: =SUM(B27:M27)
A28: gradom | B28: 0 | C28: 0 | D28: 0 | E28: 0 | F28: 0 | G28: 0 | H28: 0 | I28: 0 | J28: 0 | K28: 0 | L28: 0 | M28: 0 | N28: =SUM(B28:M28)

Sheet 2013
A1: PROSEČNE MESEČNE, GODIŠNJE I EKSTREMNE VREDNOSTI ZA 2013. GODINU
A2: CMILJEVAC II φ 43.11°N λ 17.66°E h 1295 m
A4: METEOROLOŠKI PARAMETAR | B4: jan | C4: feb | D4: mar | E4: apr | F4: maj | G4: jun | H4: jul | I4: avg | J4: sep | K4: okt | L4: nov | M4: dec | N4: god.
A5: TEMPERATURA VAZDUHA (°C)
A6: Normalna vrednost | B6: 4 | C6: 4.7 | D6: 7.3 | E6: 12.8 | F6: 16.1 | G6: 19.7 | H6: 24 | I6: 24.9 | J6: 17.5 | K6: 13.8 | L6: 9.8 | M6: 3.3 | N6: =AVERAGE(B6:M6)
A7: Srednja maksimalna | B7: 8.7 | C7: 9.8 | D7: 12 | E7: 18.6 | F7: 21 | G7: 25 | H7: 30.3 | I7: 31.2 | J7: 23.3 | K7: 19.4 | L7: 14.4 | M7: 9.9 | N7: =AVERAGE(B7:M7)
A8: Srednja minimalna | B8: -0.4 | C8: -0.2 | D8: 2.3 | E8: 6.2 | F8: 10.1 | G8: 12.7 | H8: 16 | I8: 17.4 | J8: 11.6 | K8: 8.9 | L8: 5.7 | M8: -1.4 | N8: =AVERAGE(B8:M8)
A9: Apsolutni maksimum | B9: 12.5 | C9: 12.5 | D9: 16.8 | E9: 26.1 | F9: 28.2 | G9: 33.5 | H9: 36.4 | I9: 37.1 | J9: 28.1 | K9: 23 | L9: 20.6 | M9: 13.6 | N9: =MAX(B9:M9)
A10: Apsolutni minimum | B10: -5.5 | C10: -5.5 | D10: -4.5 | E10: 2.1 | F10: 5.3 | G10: 8.1 | H10: 10.8 | I10: 12.2 | J10: 6.4 | K10: 0.7 | L10: -3.8 | M10: -4.7 | N10: =MIN(B10:M10)
A11: Sr. br. mraznih dana | B11: 21 | C11: 15 | D11: 10 | E11: 0 | F11: 0 | G11: 0 | H11: 0 | I11: 0 | J11: 0 | K11: 0 | L11: 4 | M11: 23 | N11: =SUM(B11:M11)
A12: Sr. br. tropskih dana | B12: 0 | C12: 0 | D12: 0 | E12: 0 | F12: 0 | G12: 6 | H12: 13 | I12: 22 | J12: 0 | K12: 0 | L12: 0 | M12: 0 | N12: =SUM(B12:M12)
A13: RELATIVNA VLAGA (%)
A14: Prosek | B14: 80.3 | C14: 79 | D14: 76.7 | E14: 71.8 | F14: 73.8 | G14: 69.4 | H14: 54.9 | I14: 54.4 | J14: 73.6 | K14: 80.3 | L14: 80.2 | M14: 80.5 | N14: =AVERAGE(B14:M14)
A15: TRAJANJE SIJANJA SUNCA (h)
A16: Prosek | B16: 181.8 | C16: 206.2 | D16: 247.8 | E16: 336.9 | F16: 374.2 | G16: 409.5 | H16: 426.9 | I16: 397 | J16: 317.6 | K16: 265.6 | L16: 199.2 | M16: 219 | N16: =SUM(B16:M16)
A17: Broj vedrih dana | B17: 4 | C17: 0 | D17: 4 | E17: 9 | F17: 6 | G17: 12 | H17: 17 | I17: 19 | J17: 12 | K17: 10 | L17: 6 | M17: 14 | N17: =SUM(B17:M17)
A18: Broj oblačnih dana | B18: 13 | C18: 14 | D18: 18 | E18: 4 | F18: 6 | G18: 1 | H18: 0 | I18: 1 | J18: 5 | K18: 8 | L18: 11 | M18: 5 | N18: =SUM(B18:M18)
A19: PADAVINE (mm)
A20: Sr. mesečna suma | B20: 216 | C20: 261.6 | D20: 342.3 | E20: 167.2 | F20: 204.5 | G20: 64.1 | H20: 22.3 | I20: 108.8 | J20: 203.1 | K20: 184.2 | L20: 227.3 | M20: 59.4 | N20: =SUM(B20:M20)
A21: Max. dnevna suma | B21: 38.5 | C21: 73.2 | D21: 48.7 | E21: 57.3 | F21: 45.9 | G21: 19.6 | H21: 5.5 | I21: 36.4 | J21: 70.3 | K21: 44.9 | L21: 59.4 | M21: 24.8 | N21: =MAX(B21:M21)
A22: Sr. br. dana >= 0.1 mm | B22: 17 | C22: 21 | D22: 20 | E22: 13 | F22: 22 | G22: 14 | H22: 10 | I22: 9 | J22: 10 | K22: 13 | L22: 18 | M22: 6 | N22: =SUM(B22:M22)
A23: Sr. br. dana >= 10.0 mm | B23: 10 | C23: 8 | D23: 15 | E23: 6 | F23: 9 | G23: 2 | H23: 0 | I23: 3 | J23: 6 | K23: 6 | L23: 9 | M23: 3 | N23: =SUM(B23:M23)
A24: POJAVE (broj dana sa....)
A25: snegom | B25: 0 | C25: 4 | D25: 2 | E25: 0 | F25: 0 | G25: 0 | H25: 0 | I25: 0 | J25: 0 | K25: 0 | L25: 2 | M25: 0 | N25: =SUM(B25:M25)
A26: snežnim pokrivačem | B26: 0 | C26: 4 | D26: 2 | E26: 0 | F26: 0 | G26: 0 | H26: 0 | I26: 0 | J26: 0 | K26: 0 | L26: 2 | M26: 0 | N26: =SUM(B26:M26)
A27: maglom | B27: 0 | C27: 0 | D27: 0 | E27: 0 | F27: 0 | G27: 0 | H27: 0 | I27: 0 | J27: 0 | K27: 0 | L27: 0 | M27: 0 | N27: =SUM(B27:M27)
A28: gradom | B28: 0 | C28: 0 | D28: 0 | E28: 0 | F28: 0 | G28: 0 | H28: 0 | I28: 0 | J28: 0 | K28: 0 | L28: 0 | M28: 0 | N28: =SUM(B28:M28)

Sheet 2014
A1: PROSEČNE MESEČNE, GODIŠNJE I EKSTREMNE VREDNOSTI ZA 2014. GODINU
A2: CMILJEVAC II φ 43.11°N λ 17.66°E h 1295 m
A4: METEOROLOŠKI PARAMETAR | B4: jan | C4: feb | D4: mar | E4: apr | F4: maj | G4: jun | H4: jul | I4: avg | J4: sep | K4: okt | L4: nov | M4: dec | N4: god.
A5: TEMPERATURA VAZDUHA (°C)
A6: Normalna vrednost | B6: 6.6 | C6: 7.9 | D6: 8.5 | E6: 11.8 | F6: 14.8 | G6: 20 | H6: 21.2 | I6: 22 | J6: 17.2 | K6: 13.5 | L6: 10.3 | M6: 5.3 | N6: =AVERAGE(B6:M6)
A7: Srednja maksimalna | B7: 10.5 | C7: 12.2 | D7: 14.8 | E7: 17.1 | F7: 19.9 | G7: 25.6 | H7: 26.4 | I7: 27.7 | J7: 22 | K7: 19.3 | L7: 15.2 | M7: 9.6 | N7: =AVERAGE(B7:M7)
A8: Srednja minimalna | B8: 2.8 | C8: 3.6 | D8: 1.8 | E8: 6.4 | F8: 8.7 | G8: 13.2 | H8: 14.9 | I8: 15.3 | J8: 12.3 | K8: 7.9 | L8: 6.1 | M8: 1.5 | N8: =AVERAGE(B8:M8)
A9: Apsolutni maksimum | B9: 13.5 | C9: 15.5 | D9: 19.5 | E9: 21.3 | F9: 25.7 | G9: 32.4 | H9: 31 | I9: 31.8 | J9: 25.2 | K9: 23.5 | L9: 18.5 | M9: 15.6 | N9: =MAX(B9:M9)
A10: Apsolutni minimum | B10: -5.6 | C10: -2.5 | D10: -1.1 | E10: 1.2 | F10: 2.7 | G10: 8 | H10: 11.1 | I10: 11.5 | J10: 4.9 | K10: 1.4 | L10: -1.4 | M10: -10.5 | N10: =MIN(B10:M10)
A11: Sr. br. mraznih dana | B11: 6 | C11: 7 | D11: 8 | E11: 0 | F11: 0 | G11: 0 | H11: 0 | I11: 0 | J11: 0 | K11: 0 | L11: 2 | M11: 12 | N11: =SUM(B11:M11)
A12: Sr. br. tropskih dana | B12: 0 | C12: 0 | D12: 0 | E12: 0 | F12: 0 | G12: 5 | H12: 1 | I12: 4 | J12: 0 | K12: 0 | L12: 0 | M12: 0 | N12: =SUM(B12:M12)
A13: RELATIVNA VLAGA (%)
A14: Prosek | B14: 86.6 | C14: 83.2 | D14: 74.1 | E14: 75.6 | F14: 72.6 | G14: 68.5 | H14: 72.3 | I14: 68.6 | J14: 78.6 | K14: 79 | L14: 84.6 | M14: 80.5 | N14: =AVERAGE(B14:M14)
A15: TRAJANJE SIJANJA SUNCA (h)
A16: Prosek | B16: 152.4 | C16: 170.4 | D16: 294.3 | E16: 313.5 | F16: 361.7 | G16: 390.8 | H16: 406.1 | I16: 411 | J16: 298.8 | K16: 299 | L16: 180 | M16: 185.6 | N16: =SUM(B16:M16)
A17: Broj vedrih dana | B17: 0 | C17: 2 | D17: 12 | E17: 1 | F17: 6 | G17: 9 | H17: 9 | I17: 13 | J17: 11 | K17: 10 | L17: 7 | M17: 5 | N17: =SUM(B17:M17)
A18: Broj oblačnih dana | B18: 17 | C18: 15 | D18: 7 | E18: 12 | F18: 8 | G18: 5 | H18: 2 | I18: 0 | J18: 10 | K18: 4 | L18: 14 | M18: 11 | N18: =SUM(B18:M18)
A19: PADAVINE (mm)
A20: Sr. mesečna suma | B20: 255.3 | C20: 187.7 | D20: 81.3 | E20: 115.6 | F20: 84.6 | G20: 218.1 | H20: 127.4 | I20: 47.6 | J20: 273 | K20: 68.5 | L20: 225.1 | M20: 221 | N20: =SUM(B20:M20)
A21: Max. dnevna suma | B21: 45.6 | C21: 23.9 | D21: 21.6 | E21: 19 | F21: 32.4 | G21: 63.6 | H21: 34.3 | I21: 13.4 | J21: 50 | K21: 35.1 | L21: 38.7 | M21: 62.9 | N21: =MAX(B21:M21)
A22: Sr. br. dana >= 0.1 mm | B22: 20 | C22: 19 | D22: 11 | E22: 23 | F22: 20 | G22: 17 | H22: 20 | I22: 10 | J22: 19 | K22: 12 | L22: 17 | M22: 14 | N22: =SUM(B22:M22)
A23: Sr. br. dana >= 10.0 mm | B23: 7 | C23: 8 | D23: 3 | E23: 4 | F23: 2 | G23: 7 | H23: 5 | I23: 2 | J23: 8 | K23: 1 | L23: 8 | M23: 8 | N23: =SUM(B23:M23)
A24: POJAVE (broj dana sa....)
A25: snegom | B25: 1 | C25: 0 | D25: 0 | E25: 0 | F25: 0 | G25: 0 | H25: 0 | I25: 0 | J25: 0 | K25: 0 | L25: 0 | M25: 4 | N25: =SUM(B25:M25)
A26: snežnim pokrivačem | B26: 1 | C26: 0 | D26: 0 | E26: 0 | F26: 0 | G26: 0 | H26: 0 | I26: 0 | J26: 0 | K26: 0 | L26: 0 | M26: 4 | N26: =SUM(B26:M26)
A27: maglom | B27: 0 | C27: 0 | D27: 0 | E27: 0 | F27: 0 | G27: 0 | H27: 0 | I27: 0 | J27: 0 | K27: 0 | L27: 0 | M27: 0 | N27: =SUM(B27:M27)
A28: gradom | B28: 0 | C28: 0 | D28: 0 | E28: 0 | F28: 0 | G28: 0 | H28: 0 | I28: 0 | J28: 0 | K28: 0 | L28: 0 | M28: 0 | N28: =SUM(B28:M28)

Sheet 2015
A1: PROSEČNE MESEČNE, GODIŠNJE I EKSTREMNE VREDNOSTI ZA 2015. GODINU
A2: CMILJEVAC II φ 43.11°N λ 17.66°E h 1295 m
A4: METEOROLOŠKI PARAMETAR | B4: jan | C4: feb | D4: mar | E4: apr | F4: maj | G4: jun | H4: jul | I4: avg | J4: sep | K4: okt | L4: nov | M4: dec | N4: god.
A5: TEMPERATURA VAZDUHA (°C)
A6: Normalna vrednost | B6: 3.6 | C6: 4.1 | D6: 7.1 | E6: 10.8 | F6: 17.4 | G6: 21.4 | H6: 27.3 | I6: 25.2 | J6: 20 | K6: 13.8 | L6: 8.6 | M6: 3.5 | N6: =AVERAGE(B6:M6)
A7: Srednja maksimalna | B7: 8.6 | C7: 9.7 | D7: 12.8 | E7: 16.6 | F7: 23 | G7: 27.4 | H7: 33.9 | I7: 31.4 | J7: 25.9 | K7: 18.5 | L7: 15.5 | M7: 11.7 | N7: =AVERAGE(B7:M7)
A8: Srednja minimalna | B8: -0.6 | C8: -1.1 | D8: 1.1 | E8: 4.1 | F8: 10.3 | G8: 13.9 | H8: 18.5 | I8: 17.9 | J8: 14 | K8: 9.4 | L8: 3.1 | M8: -1.9 | N8: =AVERAGE(B8:M8)
A9: Apsolutni maksimum | B9: 11.9 | C9: 14.4 | D9: 20.2 | E9: 22.1 | F9: 29 | G9: 31 | H9: 38.1 | I9: 36.3 | J9: 34.5 | K9: 24 | L9: 22.2 | M9: 15.5 | N9: =MAX(B9:M9)
A10: Apsolutni minimum | B10: -8.6 | C10: -6 | D10: -3.7 | E10: -2.6 | F10: 4.9 | G10: 8.7 | H10: 12.9 | I10: 13.8 | J10: 9.4 | K10: 3 | L10: -3.1 | M10: -4.9 | N10: =MIN(B10:M10)
A11: Sr. br. mraznih dana | B11: 21 | C11: 18 | D11: 13 | E11: 3 | F11: 0 | G11: 0 | H11: 0 | I11: 0 | J11: 0 | K11: 0 | L11: 2 | M11: 26 | N11: =SUM(B11:M11)
A12: Sr. br. tropskih dana | B12: 0 | C12: 0 | D12: 0 | E12: 0 | F12: 0 | G12: 9 | H12: 30 | I12: 21 | J12: 6 | K12: 0 | L12: 0 | M12: 0 | N12: =SUM(B12:M12)
A13: RELATIVNA VLAGA (%)
A14: Prosek | B14: 76.1 | C14: 74.4 | D14: 69.7 | E14: 63.5 | F14: 65.4 | G14: 57.5 | H14: 47.8 | I14: 57.8 | J14: 60.6 | K14: 79.2 | L14: 79.3 | M14: 81.5 | N14: =AVERAGE(B14:M14)
A15: TRAJANJE SIJANJA SUNCA (h)
A16: Prosek | B16: 201 | C16: 220.2 | D16: 282 | E16: 344.7 | F16: 384.2 | G16: 412.8 | H16: 435.9 | I16: 401.2 | J16: 333.4 | K16: 227.7 | L16: 236.5 | M16: 263.2 | N16: =SUM(B16:M16)
A17: Broj vedrih dana | B17: 7 | C17: 9 | D17: 4 | E17: 6 | F17: 5 | G17: 9 | H17: 23 | I17: 11 | J17: 11 | K17: 3 | L17: 13 | M17: 22 | N17: =SUM(B17:M17)
A18: Broj oblačnih dana | B18: 10 | C18: 10 | D18: 6 | E18: 7 | F18: 7 | G18: 1 | H18: 0 | I18: 0 | J18: 3 | K18: 14 | L18: 4 | M18: 1 | N18: =SUM(B18:M18)
A19: PADAVINE (mm)
A20: Sr. mesečna suma | B20: 204.7 | C20: 135.2 | D20: 119.6 | E20: 58.3 | F20: 45.6 | G20: 44.2 | H20: 8.1 | I20: 71.5 | J20: 57.1 | K20: 273.1 | L20: 77 | M20: 0 | N20: =SUM(B20:M20)
A21: Max. dnevna suma | B21: 61.3 | C21: 43.4 | D21: 72.2 | E21: 21.6 | F21: 17.4 | G21: 19.4 | H21: 3.3 | I21: 45.1 | J21: 29.7 | K21: 74.3 | L21: 32.3 | M21: 0 | N21: =MAX(B21:M21)
A22: Sr. br. dana >= 0.1 mm | B22: 15 | C22: 15 | D22: 15 | E22: 15 | F22: 12 | G22: 12 | H22: 6 | I22: 17 | J22: 5 | K22: 20 | L22: 9 | M22: 0 | N22: =SUM(B22:M22)
A23: Sr. br. dana >= 10.0 mm | B23: 5 | C23: 5 | D23: 2 | E23: 2 | F23: 2 | G23: 1 | H23: 0 | I23: 2 | J23: 2 | K23: 7 | L23: 3 | M23: 0 | N23: =SUM(B23:M23)
A24: POJAVE (broj dana sa....)
A25: snegom | B25: 3 | C25: 2 | D25: 2 | E25: 1 | F25: 0 | G25: 0 | H25: 0 | I25: 0 | J25: 0 | K25: 0 | L25: 0 | M25: 0 | N25: =SUM(B25:M25)
A26: snežnim pokrivačem | B26: 3 | C26: 2 | D26: 2 | E26: 1 | F26: 0 | G26: 0 | H26: 0 | I26: 0 | J26: 0 | K26: 0 | L26: 0 | M26: 0 | N26: =SUM(B26:M26)
A27: maglom | B27: 0 | C27: 0 | D27: 0 | E27: 0 | F27: 0 | G27: 0 | H27: 0 | I27: 0 | J27: 0 | K27: 0 | L27: 0 | M27: 0 | N27: =SUM(B27:M27)
A28: gradom | B28: 0 | C28: 0 | D28: 0 | E28: 0 | F28: 0 | G28: 0 | H28: 0 | I28: 0 | J28: 0 | K28: 0 | L28: 0 | M28: 0 | N28: =SUM(B28:M28)

Sheet 2016
A1: PROSEČNE MESEČNE, GODIŠNJE I EKSTREMNE VREDNOSTI ZA 2016. GODINU
A2: CMILJEVAC II φ 43.11°N λ 17.66°E h 1295 m
A4: METEOROLOŠKI PARAMETAR | B4: jan | C4: feb | D4: mar | E4: apr | F4: maj | G4: jun | H4: jul | I4: avg | J4: sep | K4: okt | L4: nov | M4: dec | N4: god.
A5: TEMPERATURA VAZDUHA (°C)
A6: Normalna vrednost | B6: 4.2 | C6: 8 | D6: 8.1 | E6: 13.2 | F6: 15 | G6: 20.5 | H6: 24.4 | I6: 23.6 | J6: 18.7 | K6: 12.5 | L6: 8.3 | M6: 1 | N6: =AVERAGE(B6:M6)
A7: Srednja maksimalna | B7: 8.6 | C7: 12.4 | D7: 13 | E7: 19 | F7: 19.9 | G7: 25.8 | H7: 30.3 | I7: 29.7 | J7: 25.1 | K7: 17.6 | L7: 13 | M7: 8.5 | N7: =AVERAGE(B7:M7)
A8: Srednja minimalna | B8: 0.3 | C8: 3.2 | D8: 2.9 | E8: 6.7 | F8: 9 | G8: 14.2 | H8: 16.9 | I8: 16.4 | J8: 12.5 | K8: 7.5 | L8: 4 | M8: -3.5 | N8: =AVERAGE(B8:M8)
A9: Apsolutni maksimum | B9: 13.8 | C9: 18.9 | D9: 17.8 | E9: 23.2 | F9: 26.3 | G9: 33.8 | H9: 34.2 | I9: 32.8 | J9: 30.9 | K9: 22.7 | L9: 17.6 | M9: 11.3 | N9: =MAX(B9:M9)
A10: Apsolutni minimum | B10: -6.4 | C10: -4.8 | D10: -2.4 | E10: -1.1 | F10: 4.7 | G10: 8.2 | H10: 12.8 | I10: 11.1 | J10: 6.4 | K10: 1.4 | L10: -3.8 | M10: -6.6 | N10: =MIN(B10:M10)
A11: Sr. br. mraznih dana | B11: 15 | C11: 6 | D11: 7 | E11: 1 | F11: 0 | G11: 0 | H11: 0 | I11: 0 | J11: 0 | K11: 0 | L11: 7 | M11: 31 | N11: =SUM(B11:M11)
A12: Sr. br. tropskih dana | B12: 0 | C12: 0 | D12: 0 | E12: 0 | F12: 0 | G12: 5 | H12: 21 | I12: 19 | J12: 3 | K12: 0 | L12: 0 | M12: 0 | N12: =SUM(B12:M12)
A13: RELATIVNA VLAGA (%)
A14: Prosek | B14: 79.3 | C14: 81.2 | D14: 77.2 | E14: 68.7 | F14: 74.9 | G14: 73.6 | H14: 58.9 | I14: 55.6 | J14: 68.1 | K14: 76.5 | L14: 79.6 | M14: 74.2 | N14: =AVERAGE(B14:M14)
A15: TRAJANJE SIJANJA SUNCA (h)
A16: Prosek | B16: 183 | C16: 191 | D16: 247.6 | E16: 333.9 | F16: 360.8 | G16: 384.1 | H16: 425.9 | I16: 407.8 | J16: 313.2 | K16: 262 | L16: 201.8 | M16: 252 | N16: =SUM(B16:M16)
A17: Broj vedrih dana | B17: 3 | C17: 2 | D17: 4 | E17: 8 | F17: 5 | G17: 2 | H17: 22 | I17: 20 | J17: 8 | K17: 7 | L17: 7 | M17: 19 | N17: =SUM(B17:M17)
A18: Broj oblačnih dana | B18: 12 | C18: 10 | D18: 14 | E18: 6 | F18: 8 | G18: 5 | H18: 1 | I18: 1 | J18: 5 | K18: 10 | L18: 11 | M18: 0 | N18: =SUM(B18:M18)
A19: PADAVINE (mm)
A20: Sr. mesečna suma | B20: 139.8 | C20: 223.8 | D20: 154.9 | E20: 109.7 | F20: 188.9 | G20: 109.7 | H20: 34.8 | I20: 25.9 | J20: 109.5 | K20: 227 | L20: 214.2 | M20: 1.7 | N20: =SUM(B20:M20)
A21: Max. dnevna suma | B21: 32.2 | C21: 47.9 | D21: 39.1 | E21: 26 | F21: 27.4 | G21: 41 | H21: 21.1 | I21: 6.2 | J21: 29.5 | K21: 40.9 | L21: 34.1 | M21: 1 | N21: =MAX(B21:M21)
A22: Sr. br. dana >= 0.1 mm | B22: 17 | C22: 22 | D22: 21 | E22: 12 | F22: 23 | G22: 23 | H22: 9 | I22: 9 | J22: 16 | K22: 16 | L22: 16 | M22: 3 | N22: =SUM(B22:M22)
A23: Sr. br. dana >= 10.0 mm | B23: 5 | C23: 8 | D23: 5 | E23: 5 | F23: 9 | G23: 3 | H23: 1 | I23: 0 | J23: 4 | K23: 9 | L23: 8 | M23: 0 | N23: =SUM(B23:M23)
A24: POJAVE (broj dana sa....)
A25: snegom | B25: 0 | C25: 1 | D25: 0 | E25: 0 | F25: 0 | G25: 0 | H25: 0 | I25: 0 | J25: 0 | K25: 0 | L25: 0 | M25: 0 | N25: =SUM(B25:M25)
A26: snežnim pokrivačem | B26: 0 | C26: 1 | D26: 0 | E26: 0 | F26: 0 | G26: 0 | H26: 0 | I26: 0 | J26: 0 | K26: 0 | L26: 0 | M26: 0 | N26: =SUM(B26:M26)
A27: maglom | B27: 0 | C27: 0 | D27: 0 | E27: 0 | F27: 0 | G27: 0 | H27: 0 | I27: 0 | J27: 0 | K27: 0 | L27: 0 | M27: 0 | N27: =SUM(B27:M27)
A28: gradom | B28: 0 | C28: 0 | D28: 0 | E28: 0 | F28: 0 | G28: 0 | H28: 0 | I28: 0 | J28: 0 | K28: 0 | L28: 0 | M28: 0 | N28: =SUM(B28:M28)

Sheet 2017
A1: PROSEČNE MESEČNE, GODIŠNJE I EKSTREMNE VREDNOSTI ZA 2017. GODINU
A2: CMILJEVAC II φ 43.11°N λ 17.66°E h 1295 m
A4: METEOROLOŠKI PARAMETAR | B4: jan | C4: feb | D4: mar | E4: apr | F4: maj | G4: jun | H4: jul | I4: avg | J4: sep | K4: okt | L4: nov | M4: dec | N4: god.
A5: TEMPERATURA VAZDUHA (°C)
A6: Normalna vrednost | B6: -0.5 | C6: 6.8 | D6: 9.9 | E6: 11 | F6: 16.7 | G6: 23.4 | H6: 25.5 | I6: 26.6 | J6: 17.6 | K6: 13.1 | L6: 8.4 | M6: 4.7 | N6: =AVERAGE(B6:M6)
A7: Srednja maksimalna | B7: 4.9 | C7: 12.6 | D7: 16.2 | E7: 17 | F7: 22.8 | G7: 29.6 | H7: 32.4 | I7: 34.3 | J7: 23.6 | K7: 20 | L7: 13.2 | M7: 9 | N7: =AVERAGE(B7:M7)
A8: Srednja minimalna | B8: -4.3 | C8: 2 | D8: 3.9 | E8: 5.1 | F8: 10.9 | G8: 16.9 | H8: 18.3 | I8: 19.3 | J8: 12.9 | K8: 7.4 | L8: 4.1 | M8: 0.6 | N8: =AVERAGE(B8:M8)
A9: Apsolutni maksimum | B9: 10.4 | C9: 16.3 | D9: 22.2 | E9: 21.2 | F9: 26.5 | G9: 34.8 | H9: 36.2 | I9: 40.2 | J9: 30.6 | K9: 25.5 | L9: 16.3 | M9: 15.2 | N9: =MAX(B9:M9)
A10: Apsolutni minimum | B10: -9.8 | C10: -4.6 | D10: -1.4 | E10: -0.8 | F10: 6.5 | G10: 12.2 | H10: 14.9 | I10: 14 | J10: 6.7 | K10: 3.1 | L10: -2.8 | M10: -4.9 | N10: =MIN(B10:M10)
A11: Sr. br. mraznih dana | B11: 28 | C11: 11 | D11: 2 | E11: 1 | F11: 0 | G11: 0 | H11: 0 | I11: 0 | J11: 0 | K11: 0 | L11: 3 | M11: 16 | N11: =SUM(B11:M11)
