Workbook

Sheet Prosek 1991-2025
A1: PROSEČNE MESEČNE, GODIŠNJE I EKSTREMNE VREDNOSTI ZA PERIOD 1991-2025. GODINA
A2: KRUŠEVAC φ 43.58°N λ 21.32°E h 166 m
A4: METEOROLOŠKI PARAMETAR | B4: jan | C4: feb | D4: mar | E4: apr | F4: maj | G4: jun | H4: jul | I4: avg | J4: sep | K4: okt | L4: nov | M4: dec | N4: god.
A5: TEMPERATURA VAZDUHA (°C)
A6: Normalna vrednost | B6: =AVERAGE('1991'!B6,'1992'!B6,'1993'!B6,'1994'!B6,'1995'!B6,'1996'!B6,'1997'!B6,'1998'!B6,'1999'!B6,'2000'!B6,'2001'!B6,'2002'!B6,'2003'!B6,'2004'!B6,'2005'!B6,'2006'!B6,'2007'!B6,'2008'!B6,'2009'!B6,'2010'!B6,'2011'!B6,'2012'!B6,'2013'!B6,'2014'!B6,'2015'!B6,'2016'!B6,'2017'!B6,'2018'!B6,'2019'!B6,'2020'!B6,'2021'!B6,'2022'!B6,'2023'!B6,'2024'!B6,'2025'!B6) | C6: =AVERAGE('1991'!C6,'1992'!C6,'1993'!C6,'1994'!C6,'1995'!C6,'1996'!C6,'1997'!C6,'1998'!C6,'1999'!C6,'2000'!C6,'2001'!C6,'2002'!C6,'2003'!C6,'2004'!C6,'2005'!C6,'2006'!C6,'2007'!C6,'2008'!C6,'2009'!C6,'2010'!C6,'2011'!C6,'2012'!C6,'2013'!C6,'2014'!C6,'2015'!C6,'2016'!C6,'2017'!C6,'2018'!C6,'2019'!C6,'2020'!C6,'2021'!C6,'2022'!C6,'2023'!C6,'2024'!C6,'2025'!C6) | D6: =AVERAGE('1991'!D6,'1992'!D6,'1993'!D6,'1994'!D6,'1995'!D6,'1996'!D6,'1997'!D6,'1998'!D6,'1999'!D6,'2000'!D6,'2001'!D6,'2002'!D6,'2003'!D6,'2004'!D6,'2005'!D6,'2006'!D6,'2007'!D6,'2008'!D6,'2009'!D6,'2010'!D6,'2011'!D6,'2012'!D6,'2013'!D6,'2014'!D6,'2015'!D6,'2016'!D6,'2017'!D6,'2018'!D6,'2019'!D6,'2020'!D6,'2021'!D6,'2022'!D6,'2023'!D6,'2024'!D6,'2025'!D6) | E6: =AVERAGE('1991'!E6,'1992'!E6,'1993'!E6,'1994'!E6,'1995'!E6,'1996'!E6,'1997'!E6,'1998'!E6,'1999'!E6,'2000'!E6,'2001'!E6,'2002'!E6,'2003'!E6,'2004'!E6,'2005'!E6,'2006'!E6,'2007'!E6,'2008'!E6,'2009'!E6,'2010'!E6,'2011'!E6,'2012'!E6,'2013'!E6,'2014'!E6,'2015'!E6,'2016'!E6,'2017'!E6,'2018'!E6,'2019'!E6,'2020'!E6,'2021'!E6,'2022'!E6,'2023'!E6,'2024'!E6,'2025'!E6) | F6: =AVERAGE('1991'!F6,'1992'!F6,'1993'!F6,'1994'!F6,'1995'!F6,'1996'!F6,'1997'!F6,'1998'!F6,'1999'!F6,'2000'!F6,'2001'!F6,'2002'!F6,'2003'!F6,'2004'!F6,'2005'!F6,'2006'!F6,'2007'!F6,'2008'!F6,'2009'!F6,'2010'!F6,'2011'!F6,'2012'!F6,'2013'!F6,'2014'!F6,'2015'!F6,'2016'!F6,'2017'!F6,'2018'!F6,'2019'!F6,'2020'!F6,'2021'!F6,'2022'!F6,'2023'!F6,'2024'!F6,'2025'!F6) | G6: =AVERAGE('1991'!G6,'1992'!G6,'1993'!G6,'1994'!G6,'1995'!G6,'1996'!G6,'1997'!G6,'1998'!G6,'1999'!G6,'2000'!G6,'2001'!G6,'2002'!G6,'2003'!G6,'2004'!G6,'2005'!G6,'2006'!G6,'2007'!G6,'2008'!G6,'2009'!G6,'2010'!G6,'2011'!G6,'2012'!G6,'2013'!G6,'2014'!G6,'2015'!G6,'2016'!G6,'2017'!G6,'2018'!G6,'2019'!G6,'2020'!G6,'2021'!G6,'2022'!G6,'2023'!G6,'2024'!G6,'2025'!G6) | H6: =AVERAGE('1991'!H6,'1992'!H6,'1993'!H6,'1994'!H6,'1995'!H6,'1996'!H6,'1997'!H6,'1998'!H6,'1999'!H6,'2000'!H6,'2001'!H6,'2002'!H6,'2003'!H6,'2004'!H6,'2005'!H6,'2006'!H6,'2007'!H6,'2008'!H6,'2009'!H6,'2010'!H6,'2011'!H6,'2012'!H6,'2013'!H6,'2014'!H6,'2015'!H6,'2016'!H6,'2017'!H6,'2018'!H6,'2019'!H6,'2020'!H6,'2021'!H6,'2022'!H6,'2023'!H6,'2024'!H6,'2025'!H6) | I6: =AVERAGE('1991'!I6,'1992'!I6,'1993'!I6,'1994'!I6,'1995'!I6,'1996'!I6,'1997'!I6,'1998'!I6,'1999'!I6,'2000'!I6,'2001'!I6,'2002'!I6,'2003'!I6,'2004'!I6,'2005'!I6,'2006'!I6,'2007'!I6,'2008'!I6,'2009'!I6,'2010'!I6,'2011'!I6,'2012'!I6,'2013'!I6,'2014'!I6,'2015'!I6,'2016'!I6,'2017'!I6,'2018'!I6,'2019'!I6,'2020'!I6,'2021'!I6,'2022'!I6,'2023'!I6,'2024'!I6,'2025'!I6) | ... M6: =AVERAGE('1991'!M6,'1992'!M6,'1993'!M6,'1994'!M6,'1995'!M6,'1996'!M6,'1997'!M6,'1998'!M6,'1999'!M6,'2000'!M6,'2001'!M6,'2002'!M6,'2003'!M6,'2004'!M6,'2005'!M6,'2006'!M6,'2007'!M6,'2008'!M6,'2009'!M6,'2010'!M6,'2011'!M6,'2012'!M6,'2013'!M6,'2014'!M6,'2015'!M6,'2016'!M6,'2017'!M6,'2018'!M6,'2019'!M6,'2020'!M6,'2021'!M6,'2022'!M6,'2023'!M6,'2024'!M6,'2025'!M6) | N6: =AVERAGE(B6:M6)
A7: Srednja maksimalna | B7: =AVERAGE('1991'!B7,'1992'!B7,'1993'!B7,'1994'!B7,'1995'!B7,'1996'!B7,'1997'!B7,'1998'!B7,'1999'!B7,'2000'!B7,'2001'!B7,'2002'!B7,'2003'!B7,'2004'!B7,'2005'!B7,'2006'!B7,'2007'!B7,'2008'!B7,'2009'!B7,'2010'!B7,'2011'!B7,'2012'!B7,'2013'!B7,'2014'!B7,'2015'!B7,'2016'!B7,'2017'!B7,'2018'!B7,'2019'!B7,'2020'!B7,'2021'!B7,'2022'!B7,'2023'!B7,'2024'!B7,'2025'!B7) | C7: =AVERAGE('1991'!C7,'1992'!C7,'1993'!C7,'1994'!C7,'1995'!C7,'1996'!C7,'1997'!C7,'1998'!C7,'1999'!C7,'2000'!C7,'2001'!C7,'2002'!C7,'2003'!C7,'2004'!C7,'2005'!C7,'2006'!C7,'2007'!C7,'2008'!C7,'2009'!C7,'2010'!C7,'2011'!C7,'2012'!C7,'2013'!C7,'2014'!C7,'2015'!C7,'2016'!C7,'2017'!C7,'2018'!C7,'2019'!C7,'2020'!C7,'2021'!C7,'2022'!C7,'2023'!C7,'2024'!C7,'2025'!C7) | D7: =AVERAGE('1991'!D7,'1992'!D7,'1993'!D7,'1994'!D7,'1995'!D7,'1996'!D7,'1997'!D7,'1998'!D7,'1999'!D7,'2000'!D7,'2001'!D7,'2002'!D7,'2003'!D7,'2004'!D7,'2005'!D7,'2006'!D7,'2007'!D7,'2008'!D7,'2009'!D7,'2010'!D7,'2011'!D7,'2012'!D7,'2013'!D7,'2014'!D7,'2015'!D7,'2016'!D7,'2017'!D7,'2018'!D7,'2019'!D7,'2020'!D7,'2021'!D7,'2022'!D7,'2023'!D7,'2024'!D7,'2025'!D7) | E7: =AVERAGE('1991'!E7,'1992'!E7,'1993'!E7,'1994'!E7,'1995'!E7,'1996'!E7,'1997'!E7,'1998'!E7,'1999'!E7,'2000'!E7,'2001'!E7,'2002'!E7,'2003'!E7,'2004'!E7,'2005'!E7,'2006'!E7,'2007'!E7,'2008'!E7,'2009'!E7,'2010'!E7,'2011'!E7,'2012'!E7,'2013'!E7,'2014'!E7,'2015'!E7,'2016'!E7,'2017'!E7,'2018'!E7,'2019'!E7,'2020'!E7,'2021'!E7,'2022'!E7,'2023'!E7,'2024'!E7,'2025'!E7) | F7: =AVERAGE('1991'!F7,'1992'!F7,'1993'!F7,'1994'!F7,'1995'!F7,'1996'!F7,'1997'!F7,'1998'!F7,'1999'!F7,'2000'!F7,'2001'!F7,'2002'!F7,'2003'!F7,'2004'!F7,'2005'!F7,'2006'!F7,'2007'!F7,'2008'!F7,'2009'!F7,'2010'!F7,'2011'!F7,'2012'!F7,'2013'!F7,'2014'!F7,'2015'!F7,'2016'!F7,'2017'!F7,'2018'!F7,'2019'!F7,'2020'!F7,'2021'!F7,'2022'!F7,'2023'!F7,'2024'!F7,'2025'!F7) | G7: =AVERAGE('1991'!G7,'1992'!G7,'1993'!G7,'1994'!G7,'1995'!G7,'1996'!G7,'1997'!G7,'1998'!G7,'1999'!G7,'2000'!G7,'2001'!G7,'2002'!G7,'2003'!G7,'2004'!G7,'2005'!G7,'2006'!G7,'2007'!G7,'2008'!G7,'2009'!G7,'2010'!G7,'2011'!G7,'2012'!G7,'2013'!G7,'2014'!G7,'2015'!G7,'2016'!G7,'2017'!G7,'2018'!G7,'2019'!G7,'2020'!G7,'2021'!G7,'2022'!G7,'2023'!G7,'2024'!G7,'2025'!G7) | H7: =AVERAGE('1991'!H7,'1992'!H7,'1993'!H7,'1994'!H7,'1995'!H7,'1996'!H7,'1997'!H7,'1998'!H7,'1999'!H7,'2000'!H7,'2001'!H7,'2002'!H7,'2003'!H7,'2004'!H7,'2005'!H7,'2006'!H7,'2007'!H7,'2008'!H7,'2009'!H7,'2010'!H7,'2011'!H7,'2012'!H7,'2013'!H7,'2014'!H7,'2015'!H7,'2016'!H7,'2017'!H7,'2018'!H7,'2019'!H7,'2020'!H7,'2021'!H7,'2022'!H7,'2023'!H7,'2024'!H7,'2025'!H7) | I7: =AVERAGE('1991'!I7,'1992'!I7,'1993'!I7,'1994'!I7,'1995'!I7,'1996'!I7,'1997'!I7,'1998'!I7,'1999'!I7,'2000'!I7,'2001'!I7,'2002'!I7,'2003'!I7,'2004'!I7,'2005'!I7,'2006'!I7,'2007'!I7,'2008'!I7,'2009'!I7,'2010'!I7,'2011'!I7,'2012'!I7,'2013'!I7,'2014'!I7,'2015'!I7,'2016'!I7,'2017'!I7,'2018'!I7,'2019'!I7,'2020'!I7,'2021'!I7,'2022'!I7,'2023'!I7,'2024'!I7,'2025'!I7) | ... M7: =AVERAGE('1991'!M7,'1992'!M7,'1993'!M7,'1994'!M7,'1995'!M7,'1996'!M7,'1997'!M7,'1998'!M7,'1999'!M7,'2000'!M7,'2001'!M7,'2002'!M7,'2003'!M7,'2004'!M7,'2005'!M7,'2006'!M7,'2007'!M7,'2008'!M7,'2009'!M7,'2010'!M7,'2011'!M7,'2012'!M7,'2013'!M7,'2014'!M7,'2015'!M7,'2016'!M7,'2017'!M7,'2018'!M7,'2019'!M7,'2020'!M7,'2021'!M7,'2022'!M7,'2023'!M7,'2024'!M7,'2025'!M7) | N7: =AVERAGE(B7:M7)
A8: Srednja minimalna | B8: =AVERAGE('1991'!B8,'1992'!B8,'1993'!B8,'1994'!B8,'1995'!B8,'1996'!B8,'1997'!B8,'1998'!B8,'1999'!B8,'2000'!B8,'2001'!B8,'2002'!B8,'2003'!B8,'2004'!B8,'2005'!B8,'2006'!B8,'2007'!B8,'2008'!B8,'2009'!B8,'2010'!B8,'2011'!B8,'2012'!B8,'2013'!B8,'2014'!B8,'2015'!B8,'2016'!B8,'2017'!B8,'2018'!B8,'2019'!B8,'2020'!B8,'2021'!B8,'2022'!B8,'2023'!B8,'2024'!B8,'2025'!B8) | C8: =AVERAGE('1991'!C8,'1992'!C8,'1993'!C8,'1994'!C8,'1995'!C8,'1996'!C8,'1997'!C8,'1998'!C8,'1999'!C8,'2000'!C8,'2001'!C8,'2002'!C8,'2003'!C8,'2004'!C8,'2005'!C8,'2006'!C8,'2007'!C8,'2008'!C8,'2009'!C8,'2010'!C8,'2011'!C8,'2012'!C8,'2013'!C8,'2014'!C8,'2015'!C8,'2016'!C8,'2017'!C8,'2018'!C8,'2019'!C8,'2020'!C8,'2021'!C8,'2022'!C8,'2023'!C8,'2024'!C8,'2025'!C8) | D8: =AVERAGE('1991'!D8,'1992'!D8,'1993'!D8,'1994'!D8,'1995'!D8,'1996'!D8,'1997'!D8,'1998'!D8,'1999'!D8,'2000'!D8,'2001'!D8,'2002'!D8,'2003'!D8,'2004'!D8,'2005'!D8,'2006'!D8,'2007'!D8,'2008'!D8,'2009'!D8,'2010'!D8,'2011'!D8,'2012'!D8,'2013'!D8,'2014'!D8,'2015'!D8,'2016'!D8,'2017'!D8,'2018'!D8,'2019'!D8,'2020'!D8,'2021'!D8,'2022'!D8,'2023'!D8,'2024'!D8,'2025'!D8) | E8: =AVERAGE('1991'!E8,'1992'!E8,'1993'!E8,'1994'!E8,'1995'!E8,'1996'!E8,'1997'!E8,'1998'!E8,'1999'!E8,'2000'!E8,'2001'!E8,'2002'!E8,'2003'!E8,'2004'!E8,'2005'!E8,'2006'!E8,'2007'!E8,'2008'!E8,'2009'!E8,'2010'!E8,'2011'!E8,'2012'!E8,'2013'!E8,'2014'!E8,'2015'!E8,'2016'!E8,'2017'!E8,'2018'!E8,'2019'!E8,'2020'!E8,'2021'!E8,'2022'!E8,'2023'!E8,'2024'!E8,'2025'!E8) | F8: =AVERAGE('1991'!F8,'1992'!F8,'1993'!F8,'1994'!F8,'1995'!F8,'1996'!F8,'1997'!F8,'1998'!F8,'1999'!F8,'2000'!F8,'2001'!F8,'2002'!F8,'2003'!F8,'2004'!F8,'2005'!F8,'2006'!F8,'2007'!F8,'2008'!F8,'2009'!F8,'2010'!F8,'2011'!F8,'2012'!F8,'2013'!F8,'2014'!F8,'2015'!F8,'2016'!F8,'2017'!F8,'2018'!F8,'2019'!F8,'2020'!F8,'2021'!F8,'2022'!F8,'2023'!F8,'2024'!F8,'2025'!F8) | G8: =AVERAGE('1991'!G8,'1992'!G8,'1993'!G8,'1994'!G8,'1995'!G8,'1996'!G8,'1997'!G8,'1998'!G8,'1999'!G8,'2000'!G8,'2001'!G8,'2002'!G8,'2003'!G8,'2004'!G8,'2005'!G8,'2006'!G8,'2007'!G8,'2008'!G8,'2009'!G8,'2010'!G8,'2011'!G8,'2012'!G8,'2013'!G8,'2014'!G8,'2015'!G8,'2016'!G8,'2017'!G8,'2018'!G8,'2019'!G8,'2020'!G8,'2021'!G8,'2022'!G8,'2023'!G8,'2024'!G8,'2025'!G8) | H8: =AVERAGE('1991'!H8,'1992'!H8,'1993'!H8,'1994'!H8,'1995'!H8,'1996'!H8,'1997'!H8,'1998'!H8,'1999'!H8,'2000'!H8,'2001'!H8,'2002'!H8,'2003'!H8,'2004'!H8,'2005'!H8,'2006'!H8,'2007'!H8,'2008'!H8,'2009'!H8,'2010'!H8,'2011'!H8,'2012'!H8,'2013'!H8,'2014'!H8,'2015'!H8,'2016'!H8,'2017'!H8,'2018'!H8,'2019'!H8,'2020'!H8,'2021'!H8,'2022'!H8,'2023'!H8,'2024'!H8,'2025'!H8) | I8: =AVERAGE('1991'!I8,'1992'!I8,'1993'!I8,'1994'!I8,'1995'!I8,'1996'!I8,'1997'!I8,'1998'!I8,'1999'!I8,'2000'!I8,'2001'!I8,'2002'!I8,'2003'!I8,'2004'!I8,'2005'!I8,'2006'!I8,'2007'!I8,'2008'!I8,'2009'!I8,'2010'!I8,'2011'!I8,'2012'!I8,'2013'!I8,'2014'!I8,'2015'!I8,'2016'!I8,'2017'!I8,'2018'!I8,'2019'!I8,'2020'!I8,'2021'!I8,'2022'!I8,'2023'!I8,'2024'!I8,'2025'!I8) | ... M8: =AVERAGE('1991'!M8,'1992'!M8,'1993'!M8,'1994'!M8,'1995'!M8,'1996'!M8,'1997'!M8,'1998'!M8,'1999'!M8,'2000'!M8,'2001'!M8,'2002'!M8,'2003'!M8,'2004'!M8,'2005'!M8,'2006'!M8,'2007'!M8,'2008'!M8,'2009'!M8,'2010'!M8,'2011'!M8,'2012'!M8,'2013'!M8,'2014'!M8,'2015'!M8,'2016'!M8,'2017'!M8,'2018'!M8,'2019'!M8,'2020'!M8,'2021'!M8,'2022'!M8,'2023'!M8,'2024'!M8,'2025'!M8) | N8: =AVERAGE(B8:M8)
A9: Apsolutni maksimum | B9: =AVERAGE('1991'!B9,'1992'!B9,'1993'!B9,'1994'!B9,'1995'!B9,'1996'!B9,'1997'!B9,'1998'!B9,'1999'!B9,'2000'!B9,'2001'!B9,'2002'!B9,'2003'!B9,'2004'!B9,'2005'!B9,'2006'!B9,'2007'!B9,'2008'!B9,'2009'!B9,'2010'!B9,'2011'!B9,'2012'!B9,'2013'!B9,'2014'!B9,'2015'!B9,'2016'!B9,'2017'!B9,'2018'!B9,'2019'!B9,'2020'!B9,'2021'!B9,'2022'!B9,'2023'!B9,'2024'!B9,'2025'!B9) | C9: =AVERAGE('1991'!C9,'1992'!C9,'1993'!C9,'1994'!C9,'1995'!C9,'1996'!C9,'1997'!C9,'1998'!C9,'1999'!C9,'2000'!C9,'2001'!C9,'2002'!C9,'2003'!C9,'2004'!C9,'2005'!C9,'2006'!C9,'2007'!C9,'2008'!C9,'2009'!C9,'2010'!C9,'2011'!C9,'2012'!C9,'2013'!C9,'2014'!C9,'2015'!C9,'2016'!C9,'2017'!C9,'2018'!C9,'2019'!C9,'2020'!C9,'2021'!C9,'2022'!C9,'2023'!C9,'2024'!C9,'2025'!C9) | D9: =AVERAGE('1991'!D9,'1992'!D9,'1993'!D9,'1994'!D9,'1995'!D9,'1996'!D9,'1997'!D9,'1998'!D9,'1999'!D9,'2000'!D9,'2001'!D9,'2002'!D9,'2003'!D9,'2004'!D9,'2005'!D9,'2006'!D9,'2007'!D9,'2008'!D9,'2009'!D9,'2010'!D9,'2011'!D9,'2012'!D9,'2013'!D9,'2014'!D9,'2015'!D9,'2016'!D9,'2017'!D9,'2018'!D9,'2019'!D9,'2020'!D9,'2021'!D9,'2022'!D9,'2023'!D9,'2024'!D9,'2025'!D9) | E9: =AVERAGE('1991'!E9,'1992'!E9,'1993'!E9,'1994'!E9,'1995'!E9,'1996'!E9,'1997'!E9,'1998'!E9,'1999'!E9,'2000'!E9,'2001'!E9,'2002'!E9,'2003'!E9,'2004'!E9,'2005'!E9,'2006'!E9,'2007'!E9,'2008'!E9,'2009'!E9,'2010'!E9,'2011'!E9,'2012'!E9,'2013'!E9,'2014'!E9,'2015'!E9,'2016'!E9,'2017'!E9,'2018'!E9,'2019'!E9,'2020'!E9,'2021'!E9,'2022'!E9,'2023'!E9,'2024'!E9,'2025'!E9) | F9: =AVERAGE('1991'!F9,'1992'!F9,'1993'!F9,'1994'!F9,'1995'!F9,'1996'!F9,'1997'!F9,'1998'!F9,'1999'!F9,'2000'!F9,'2001'!F9,'2002'!F9,'2003'!F9,'2004'!F9,'2005'!F9,'2006'!F9,'2007'!F9,'2008'!F9,'2009'!F9,'2010'!F9,'2011'!F9,'2012'!F9,'2013'!F9,'2014'!F9,'2015'!F9,'2016'!F9,'2017'!F9,'2018'!F9,'2019'!F9,'2020'!F9,'2021'!F9,'2022'!F9,'2023'!F9,'2024'!F9,'2025'!F9) | G9: =AVERAGE('1991'!G9,'1992'!G9,'1993'!G9,'1994'!G9,'1995'!G9,'1996'!G9,'1997'!G9,'1998'!G9,'1999'!G9,'2000'!G9,'2001'!G9,'2002'!G9,'2003'!G9,'2004'!G9,'2005'!G9,'2006'!G9,'2007'!G9,'2008'!G9,'2009'!G9,'2010'!G9,'2011'!G9,'2012'!G9,'2013'!G9,'2014'!G9,'2015'!G9,'2016'!G9,'2017'!G9,'2018'!G9,'2019'!G9,'2020'!G9,'2021'!G9,'2022'!G9,'2023'!G9,'2024'!G9,'2025'!G9) | H9: =AVERAGE('1991'!H9,'1992'!H9,'1993'!H9,'1994'!H9,'1995'!H9,'1996'!H9,'1997'!H9,'1998'!H9,'1999'!H9,'2000'!H9,'2001'!H9,'2002'!H9,'2003'!H9,'2004'!H9,'2005'!H9,'2006'!H9,'2007'!H9,'2008'!H9,'2009'!H9,'2010'!H9,'2011'!H9,'2012'!H9,'2013'!H9,'2014'!H9,'2015'!H9,'2016'!H9,'2017'!H9,'2018'!H9,'2019'!H9,'2020'!H9,'2021'!H9,'2022'!H9,'2023'!H9,'2024'!H9,'2025'!H9) | I9: =AVERAGE('1991'!I9,'1992'!I9,'1993'!I9,'1994'!I9,'1995'!I9,'1996'!I9,'1997'!I9,'1998'!I9,'1999'!I9,'2000'!I9,'2001'!I9,'2002'!I9,'2003'!I9,'2004'!I9,'2005'!I9,'2006'!I9,'2007'!I9,'2008'!I9,'2009'!I9,'2010'!I9,'2011'!I9,'2012'!I9,'2013'!I9,'2014'!I9,'2015'!I9,'2016'!I9,'2017'!I9,'2018'!I9,'2019'!I9,'2020'!I9,'2021'!I9,'2022'!I9,'2023'!I9,'2024'!I9,'2025'!I9) | ... M9: =AVERAGE('1991'!M9,'1992'!M9,'1993'!M9,'1994'!M9,'1995'!M9,'1996'!M9,'1997'!M9,'1998'!M9,'1999'!M9,'2000'!M9,'2001'!M9,'2002'!M9,'2003'!M9,'2004'!M9,'2005'!M9,'2006'!M9,'2007'!M9,'2008'!M9,'2009'!M9,'2010'!M9,'2011'!M9,'2012'!M9,'2013'!M9,'2014'!M9,'2015'!M9,'2016'!M9,'2017'!M9,'2018'!M9,'2019'!M9,'2020'!M9,'2021'!M9,'2022'!M9,'2023'!M9,'2024'!M9,'2025'!M9) | N9: =MAX(B9:M9)
A10: Apsolutni minimum | B10: =AVERAGE('1991'!B10,'1992'!B10,'1993'!B10,'1994'!B10,'1995'!B10,'1996'!B10,'1997'!B10,'1998'!B10,'1999'!B10,'2000'!B10,'2001'!B10,'2002'!B10,'2003'!B10,'2004'!B10,'2005'!B10,'2006'!B10,'2007'!B10,'2008'!B10,'2009'!B10,'2010'!B10,'2011'!B10,'2012'!B10,'2013'!B10,'2014'!B10,'2015'!B10,'2016'!B10,'2017'!B10,'2018'!B10,'2019'!B10,'2020'!B10,'2021'!B10,'2022'!B10,'2023'!B10,'2024'!B10,'2025'!B10) | C10: =AVERAGE('1991'!C10,'1992'!C10,'1993'!C10,'1994'!C10,'1995'!C10,'1996'!C10,'1997'!C10,'1998'!C10,'1999'!C10,'2000'!C10,'2001'!C10,'2002'!C10,'2003'!C10,'2004'!C10,'2005'!C10,'2006'!C10,'2007'!C10,'2008'!C10,'2009'!C10,'2010'!C10,'2011'!C10,'2012'!C10,'2013'!C10,'2014'!C10,'2015'!C10,'2016'!C10,'2017'!C10,'2018'!C10,'2019'!C10,'2020'!C10,'2021'!C10,'2022'!C10,'2023'!C10,'2024'!C10,'2025'!C10) | D10: =AVERAGE('1991'!D10,'1992'!D10,'1993'!D10,'1994'!D10,'1995'!D10,'1996'!D10,'1997'!D10,'1998'!D10,'1999'!D10,'2000'!D10,'2001'!D10,'2002'!D10,'2003'!D10,'2004'!D10,'2005'!D10,'2006'!D10,'2007'!D10,'2008'!D10,'2009'!D10,'2010'!D10,'2011'!D10,'2012'!D10,'2013'!D10,'2014'!D10,'2015'!D10,'2016'!D10,'2017'!D10,'2018'!D10,'2019'!D10,'2020'!D10,'2021'!D10,'2022'!D10,'2023'!D10,'2024'!D10,'2025'!D10) | E10: =AVERAGE('1991'!E10,'1992'!E10,'1993'!E10,'1994'!E10,'1995'!E10,'1996'!E10,'1997'!E10,'1998'!E10,'1999'!E10,'2000'!E10,'2001'!E10,'2002'!E10,'2003'!E10,'2004'!E10,'2005'!E10,'2006'!E10,'2007'!E10,'2008'!E10,'2009'!E10,'2010'!E10,'2011'!E10,'2012'!E10,'2013'!E10,'2014'!E10,'2015'!E10,'2016'!E10,'2017'!E10,'2018'!E10,'2019'!E10,'2020'!E10,'2021'!E10,'2022'!E10,'2023'!E10,'2024'!E10,'2025'!E10) | F10: =AVERAGE('1991'!F10,'1992'!F10,'1993'!F10,'1994'!F10,'1995'!F10,'1996'!F10,'1997'!F10,'1998'!F10,'1999'!F10,'2000'!F10,'2001'!F10,'2002'!F10,'2003'!F10,'2004'!F10,'2005'!F10,'2006'!F10,'2007'!F10,'2008'!F10,'2009'!F10,'2010'!F10,'2011'!F10,'2012'!F10,'2013'!F10,'2014'!F10,'2015'!F10,'2016'!F10,'2017'!F10,'2018'!F10,'2019'!F10,'2020'!F10,'2021'!F10,'2022'!F10,'2023'!F10,'2024'!F10,'2025'!F10) | G10: =AVERAGE('1991'!G10,'1992'!G10,'1993'!G10,'1994'!G10,'1995'!G10,'1996'!G10,'1997'!G10,'1998'!G10,'1999'!G10,'2000'!G10,'2001'!G10,'2002'!G10,'2003'!G10,'2004'!G10,'2005'!G10,'2006'!G10,'2007'!G10,'2008'!G10,'2009'!G10,'2010'!G10,'2011'!G10,'2012'!G10,'2013'!G10,'2014'!G10,'2015'!G10,'2016'!G10,'2017'!G10,'2018'!G10,'2019'!G10,'2020'!G10,'2021'!G10,'2022'!G10,'2023'!G10,'2024'!G10,'2025'!G10) | H10: =AVERAGE('1991'!H10,'1992'!H10,'1993'!H10,'1994'!H10,'1995'!H10,'1996'!H10,'1997'!H10,'1998'!H10,'1999'!H10,'2000'!H10,'2001'!H10,'2002'!H10,'2003'!H10,'2004'!H10,'2005'!H10,'2006'!H10,'2007'!H10,'2008'!H10,'2009'!H10,'2010'!H10,'2011'!H10,'2012'!H10,'2013'!H10,'2014'!H10,'2015'!H10,'2016'!H10,'2017'!H10,'2018'!H10,'2019'!H10,'2020'!H10,'2021'!H10,'2022'!H10,'2023'!H10,'2024'!H10,'2025'!H10) | I10: =AVERAGE('1991'!I10,'1992'!I10,'1993'!I10,'1994'!I10,'1995'!I10,'1996'!I10,'1997'!I10,'1998'!I10,'1999'!I10,'2000'!I10,'2001'!I10,'2002'!I10,'2003'!I10,'2004'!I10,'2005'!I10,'2006'!I10,'2007'!I10,'2008'!I10,'2009'!I10,'2010'!I10,'2011'!I10,'2012'!I10,'2013'!I10,'2014'!I10,'2015'!I10,'2016'!I10,'2017'!I10,'2018'!I10,'2019'!I10,'2020'!I10,'2021'!I10,'2022'!I10,'2023'!I10,'2024'!I10,'2025'!I10) | ... M10: =AVERAGE('1991'!M10,'1992'!M10,'1993'!M10,'1994'!M10,'1995'!M10,'1996'!M10,'1997'!M10,'1998'!M10,'1999'!M10,'2000'!M10,'2001'!M10,'2002'!M10,'2003'!M10,'2004'!M10,'2005'!M10,'2006'!M10,'2007'!M10,'2008'!M10,'2009'!M10,'2010'!M10,'2011'!M10,'2012'!M10,'2013'!M10,'2014'!M10,'2015'!M10,'2016'!M10,'2017'!M10,'2018'!M10,'2019'!M10,'2020'!M10,'2021'!M10,'2022'!M10,'2023'!M10,'2024'!M10,'2025'!M10) | N10: =MIN(B10:M10)
A11: Sr. br. mraznih dana | B11: =AVERAGE('1991'!B11,'1992'!B11,'1993'!B11,'1994'!B11,'1995'!B11,'1996'!B11,'1997'!B11,'1998'!B11,'1999'!B11,'2000'!B11,'2001'!B11,'2002'!B11,'2003'!B11,'2004'!B11,'2005'!B11,'2006'!B11,'2007'!B11,'2008'!B11,'2009'!B11,'2010'!B11,'2011'!B11,'2012'!B11,'2013'!B11,'2014'!B11,'2015'!B11,'2016'!B11,'2017'!B11,'2018'!B11,'2019'!B11,'2020'!B11,'2021'!B11,'2022'!B11,'2023'!B11,'2024'!B11,'2025'!B11) | C11: =AVERAGE('1991'!C11,'1992'!C11,'1993'!C11,'1994'!C11,'1995'!C11,'1996'!C11,'1997'!C11,'1998'!C11,'1999'!C11,'2000'!C11,'2001'!C11,'2002'!C11,'2003'!C11,'2004'!C11,'2005'!C11,'2006'!C11,'2007'!C11,'2008'!C11,'2009'!C11,'2010'!C11,'2011'!C11,'2012'!C11,'2013'!C11,'2014'!C11,'2015'!C11,'2016'!C11,'2017'!C11,'2018'!C11,'2019'!C11,'2020'!C11,'2021'!C11,'2022'!C11,'2023'!C11,'2024'!C11,'2025'!C11) | D11: =AVERAGE('1991'!D11,'1992'!D11,'1993'!D11,'1994'!D11,'1995'!D11,'1996'!D11,'1997'!D11,'1998'!D11,'1999'!D11,'2000'!D11,'2001'!D11,'2002'!D11,'2003'!D11,'2004'!D11,'2005'!D11,'2006'!D11,'2007'!D11,'2008'!D11,'2009'!D11,'2010'!D11,'2011'!D11,'2012'!D11,'2013'!D11,'2014'!D11,'2015'!D11,'2016'!D11,'2017'!D11,'2018'!D11,'2019'!D11,'2020'!D11,'2021'!D11,'2022'!D11,'2023'!D11,'2024'!D11,'2025'!D11) | E11: =AVERAGE('1991'!E11,'1992'!E11,'1993'!E11,'1994'!E11,'1995'!E11,'1996'!E11,'1997'!E11,'1998'!E11,'1999'!E11,'2000'!E11,'2001'!E11,'2002'!E11,'2003'!E11,'2004'!E11,'2005'!E11,'2006'!E11,'2007'!E11,'2008'!E11,'2009'!E11,'2010'!E11,'2011'!E11,'2012'!E11,'2013'!E11,'2014'!E11,'2015'!E11,'2016'!E11,'2017'!E11,'2018'!E11,'2019'!E11,'2020'!E11,'2021'!E11,'2022'!E11,'2023'!E11,'2024'!E11,'2025'!E11) | F11: =AVERAGE('1991'!F11,'1992'!F11,'1993'!F11,'1994'!F11,'1995'!F11,'1996'!F11,'1997'!F11,'1998'!F11,'1999'!F11,'2000'!F11,'2001'!F11,'2002'!F11,'2003'!F11,'2004'!F11,'2005'!F11,'2006'!F11,'2007'!F11,'2008'!F11,'2009'!F11,'2010'!F11,'2011'!F11,'2012'!F11,'2013'!F11,'2014'!F11,'2015'!F11,'2016'!F11,'2017'!F11,'2018'!F11,'2019'!F11,'2020'!F11,'2021'!F11,'2022'!F11,'2023'!F11,'2024'!F11,'2025'!F11) | G11: =AVERAGE('1991'!G11,'1992'!G11,'1993'!G11,'1994'!G11,'1995'!G11,'1996'!G11,'1997'!G11,'1998'!G11,'1999'!G11,'2000'!G11,'2001'!G11,'2002'!G11,'2003'!G11,'2004'!G11,'2005'!G11,'2006'!G11,'2007'!G11,'2008'!G11,'2009'!G11,'2010'!G11,'2011'!G11,'2012'!G11,'2013'!G11,'2014'!G11,'2015'!G11,'2016'!G11,'2017'!G11,'2018'!G11,'2019'!G11,'2020'!G11,'2021'!G11,'2022'!G11,'2023'!G11,'2024'!G11,'2025'!G11) | H11: =AVERAGE('1991'!H11,'1992'!H11,'1993'!H11,'1994'!H11,'1995'!H11,'1996'!H11,'1997'!H11,'1998'!H11,'1999'!H11,'2000'!H11,'2001'!H11,'2002'!H11,'2003'!H11,'2004'!H11,'2005'!H11,'2006'!H11,'2007'!H11,'2008'!H11,'2009'!H11,'2010'!H11,'2011'!H11,'2012'!H11,'2013'!H11,'2014'!H11,'2015'!H11,'2016'!H11,'2017'!H11,'2018'!H11,'2019'!H11,'2020'!H11,'2021'!H11,'2022'!H11,'2023'!H11,'2024'!H11,'2025'!H11) | I11: =AVERAGE('1991'!I11,'1992'!I11,'1993'!I11,'1994'!I11,'1995'!I11,'1996'!I11,'1997'!I11,'1998'!I11,'1999'!I11,'2000'!I11,'2001'!I11,'2002'!I11,'2003'!I11,'2004'!I11,'2005'!I11,'2006'!I11,'2007'!I11,'2008'!I11,'2009'!I11,'2010'!I11,'2011'!I11,'2012'!I11,'2013'!I11,'2014'!I11,'2015'!I11,'2016'!I11,'2017'!I11,'2018'!I11,'2019'!I11,'2020'!I11,'2021'!I11,'2022'!I11,'2023'!I11,'2024'!I11,'2025'!I11) | ... M11: =AVERAGE('1991'!M11,'1992'!M11,'1993'!M11,'1994'!M11,'1995'!M11,'1996'!M11,'1997'!M11,'1998'!M11,'1999'!M11,'2000'!M11,'2001'!M11,'2002'!M11,'2003'!M11,'2004'!M11,'2005'!M11,'2006'!M11,'2007'!M11,'2008'!M11,'2009'!M11,'2010'!M11,'2011'!M11,'2012'!M11,'2013'!M11,'2014'!M11,'2015'!M11,'2016'!M11,'2017'!M11,'2018'!M11,'2019'!M11,'2020'!M11,'2021'!M11,'2022'!M11,'2023'!M11,'2024'!M11,'2025'!M11) | N11: =SUM(B11:M11)
A12: Sr. br. tropskih dana | B12: =AVERAGE('1991'!B12,'1992'!B12,'1993'!B12,'1994'!B12,'1995'!B12,'1996'!B12,'1997'!B12,'1998'!B12,'1999'!B12,'2000'!B12,'2001'!B12,'2002'!B12,'2003'!B12,'2004'!B12,'2005'!B12,'2006'!B12,'2007'!B12,'2008'!B12,'2009'!B12,'2010'!B12,'2011'!B12,'2012'!B12,'2013'!B12,'2014'!B12,'2015'!B12,'2016'!B12,'2017'!B12,'2018'!B12,'2019'!B12,'2020'!B12,'2021'!B12,'2022'!B12,'2023'!B12,'2024'!B12,'2025'!B12) | C12: =AVERAGE('1991'!C12,'1992'!C12,'1993'!C12,'1994'!C12,'1995'!C12,'1996'!C12,'1997'!C12,'1998'!C12,'1999'!C12,'2000'!C12,'2001'!C12,'2002'!C12,'2003'!C12,'2004'!C12,'2005'!C12,'2006'!C12,'2007'!C12,'2008'!C12,'2009'!C12,'2010'!C12,'2011'!C12,'2012'!C12,'2013'!C12,'2014'!C12,'2015'!C12,'2016'!C12,'2017'!C12,'2018'!C12,'2019'!C12,'2020'!C12,'2021'!C12,'2022'!C12,'2023'!C12,'2024'!C12,'2025'!C12) | D12: =AVERAGE('1991'!D12,'1992'!D12,'1993'!D12,'1994'!D12,'1995'!D12,'1996'!D12,'1997'!D12,'1998'!D12,'1999'!D12,'2000'!D12,'2001'!D12,'2002'!D12,'2003'!D12,'2004'!D12,'2005'!D12,'2006'!D12,'2007'!D12,'2008'!D12,'2009'!D12,'2010'!D12,'2011'!D12,'2012'!D12,'2013'!D12,'2014'!D12,'2015'!D12,'2016'!D12,'2017'!D12,'2018'!D12,'2019'!D12,'2020'!D12,'2021'!D12,'2022'!D12,'2023'!D12,'2024'!D12,'2025'!D12) | E12: =AVERAGE('1991'!E12,'1992'!E12,'1993'!E12,'1994'!E12,'1995'!E12,'1996'!E12,'1997'!E12,'1998'!E12,'1999'!E12,'2000'!E12,'2001'!E12,'2002'!E12,'2003'!E12,'2004'!E12,'2005'!E12,'2006'!E12,'2007'!E12,'2008'!E12,'2009'!E12,'2010'!E12,'2011'!E12,'2012'!E12,'2013'!E12,'2014'!E12,'2015'!E12,'2016'!E12,'2017'!E12,'2018'!E12,'2019'!E12,'2020'!E12,'2021'!E12,'2022'!E12,'2023'!E12,'2024'!E12,'2025'!E12) | F12: =AVERAGE('1991'!F12,'1992'!F12,'1993'!F12,'1994'!F12,'1995'!F12,'1996'!F12,'1997'!F12,'1998'!F12,'1999'!F12,'2000'!F12,'2001'!F12,'2002'!F12,'2003'!F12,'2004'!F12,'2005'!F12,'2006'!F12,'2007'!F12,'2008'!F12,'2009'!F12,'2010'!F12,'2011'!F12,'2012'!F12,'2013'!F12,'2014'!F12,'2015'!F12,'2016'!F12,'2017'!F12,'2018'!F12,'2019'!F12,'2020'!F12,'2021'!F12,'2022'!F12,'2023'!F12,'2024'!F12,'2025'!F12) | G12: =AVERAGE('1991'!G12,'1992'!G12,'1993'!G12,'1994'!G12,'1995'!G12,'1996'!G12,'1997'!G12,'1998'!G12,'1999'!G12,'2000'!G12,'2001'!G12,'2002'!G12,'2003'!G12,'2004'!G12,'2005'!G12,'2006'!G12,'2007'!G12,'2008'!G12,'2009'!G12,'2010'!G12,'2011'!G12,'2012'!G12,'2013'!G12,'2014'!G12,'2015'!G12,'2016'!G12,'2017'!G12,'2018'!G12,'2019'!G12,'2020'!G12,'2021'!G12,'2022'!G12,'2023'!G12,'2024'!G12,'2025'!G12) | H12: =AVERAGE('1991'!H12,'1992'!H12,'1993'!H12,'1994'!H12,'1995'!H12,'1996'!H12,'1997'!H12,'1998'!H12,'1999'!H12,'2000'!H12,'2001'!H12,'2002'!H12,'2003'!H12,'2004'!H12,'2005'!H12,'2006'!H12,'2007'!H12,'2008'!H12,'2009'!H12,'2010'!H12,'2011'!H12,'2012'!H12,'2013'!H12,'2014'!H12,'2015'!H12,'2016'!H12,'2017'!H12,'2018'!H12,'2019'!H12,'2020'!H12,'2021'!H12,'2022'!H12,'2023'!H12,'2024'!H12,'2025'!H12) | I12: =AVERAGE('1991'!I12,'1992'!I12,'1993'!I12,'1994'!I12,'1995'!I12,'1996'!I12,'1997'!I12,'1998'!I12,'1999'!I12,'2000'!I12,'2001'!I12,'2002'!I12,'2003'!I12,'2004'!I12,'2005'!I12,'2006'!I12,'2007'!I12,'2008'!I12,'2009'!I12,'2010'!I12,'2011'!I12,'2012'!I12,'2013'!I12,'2014'!I12,'2015'!I12,'2016'!I12,'2017'!I12,'2018'!I12,'2019'!I12,'2020'!I12,'2021'!I12,'2022'!I12,'2023'!I12,'2024'!I12,'2025'!I12) | ... M12: =AVERAGE('1991'!M12,'1992'!M12,'1993'!M12,'1994'!M12,'1995'!M12,'1996'!M12,'1997'!M12,'1998'!M12,'1999'!M12,'2000'!M12,'2001'!M12,'2002'!M12,'2003'!M12,'2004'!M12,'2005'!M12,'2006'!M12,'2007'!M12,'2008'!M12,'2009'!M12,'2010'!M12,'2011'!M12,'2012'!M12,'2013'!M12,'2014'!M12,'2015'!M12,'2016'!M12,'2017'!M12,'2018'!M12,'2019'!M12,'2020'!M12,'2021'!M12,'2022'!M12,'2023'!M12,'2024'!M12,'2025'!M12) | N12: =SUM(B12:M12)
A13: RELATIVNA VLAGA (%)
A14: Prosek | B14: =AVERAGE('1991'!B14,'1992'!B14,'1993'!B14,'1994'!B14,'1995'!B14,'1996'!B14,'1997'!B14,'1998'!B14,'1999'!B14,'2000'!B14,'2001'!B14,'2002'!B14,'2003'!B14,'2004'!B14,'2005'!B14,'2006'!B14,'2007'!B14,'2008'!B14,'2009'!B14,'2010'!B14,'2011'!B14,'2012'!B14,'2013'!B14,'2014'!B14,'2015'!B14,'2016'!B14,'2017'!B14,'2018'!B14,'2019'!B14,'2020'!B14,'2021'!B14,'2022'!B14,'2023'!B14,'2024'!B14,'2025'!B14) | C14: =AVERAGE('1991'!C14,'1992'!C14,'1993'!C14,'1994'!C14,'1995'!C14,'1996'!C14,'1997'!C14,'1998'!C14,'1999'!C14,'2000'!C14,'2001'!C14,'2002'!C14,'2003'!C14,'2004'!C14,'2005'!C14,'2006'!C14,'2007'!C14,'2008'!C14,'2009'!C14,'2010'!C14,'2011'!C14,'2012'!C14,'2013'!C14,'2014'!C14,'2015'!C14,'2016'!C14,'2017'!C14,'2018'!C14,'2019'!C14,'2020'!C14,'2021'!C14,'2022'!C14,'2023'!C14,'2024'!C14,'2025'!C14) | D14: =AVERAGE('1991'!D14,'1992'!D14,'1993'!D14,'1994'!D14,'1995'!D14,'1996'!D14,'1997'!D14,'1998'!D14,'1999'!D14,'2000'!D14,'2001'!D14,'2002'!D14,'2003'!D14,'2004'!D14,'2005'!D14,'2006'!D14,'2007'!D14,'2008'!D14,'2009'!D14,'2010'!D14,'2011'!D14,'2012'!D14,'2013'!D14,'2014'!D14,'2015'!D14,'2016'!D14,'2017'!D14,'2018'!D14,'2019'!D14,'2020'!D14,'2021'!D14,'2022'!D14,'2023'!D14,'2024'!D14,'2025'!D14) | E14: =AVERAGE('1991'!E14,'1992'!E14,'1993'!E14,'1994'!E14,'1995'!E14,'1996'!E14,'1997'!E14,'1998'!E14,'1999'!E14,'2000'!E14,'2001'!E14,'2002'!E14,'2003'!E14,'2004'!E14,'2005'!E14,'2006'!E14,'2007'!E14,'2008'!E14,'2009'!E14,'2010'!E14,'2011'!E14,'2012'!E14,'2013'!E14,'2014'!E14,'2015'!E14,'2016'!E14,'2017'!E14,'2018'!E14,'2019'!E14,'2020'!E14,'2021'!E14,'2022'!E14,'2023'!E14,'2024'!E14,'2025'!E14) | F14: =AVERAGE('1991'!F14,'1992'!F14,'1993'!F14,'1994'!F14,'1995'!F14,'1996'!F14,'1997'!F14,'1998'!F14,'1999'!F14,'2000'!F14,'2001'!F14,'2002'!F14,'2003'!F14,'2004'!F14,'2005'!F14,'2006'!F14,'2007'!F14,'2008'!F14,'2009'!F14,'2010'!F14,'2011'!F14,'2012'!F14,'2013'!F14,'2014'!F14,'2015'!F14,'2016'!F14,'2017'!F14,'2018'!F14,'2019'!F14,'2020'!F14,'2021'!F14,'2022'!F14,'2023'!F14,'2024'!F14,'2025'!F14) | G14: =AVERAGE('1991'!G14,'1992'!G14,'1993'!G14,'1994'!G14,'1995'!G14,'1996'!G14,'1997'!G14,'1998'!G14,'1999'!G14,'2000'!G14,'2001'!G14,'2002'!G14,'2003'!G14,'2004'!G14,'2005'!G14,'2006'!G14,'2007'!G14,'2008'!G14,'2009'!G14,'2010'!G14,'2011'!G14,'2012'!G14,'2013'!G14,'2014'!G14,'2015'!G14,'2016'!G14,'2017'!G14,'2018'!G14,'2019'!G14,'2020'!G14,'2021'!G14,'2022'!G14,'2023'!G14,'2024'!G14,'2025'!G14) | H14: =AVERAGE('1991'!H14,'1992'!H14,'1993'!H14,'1994'!H14,'1995'!H14,'1996'!H14,'1997'!H14,'1998'!H14,'1999'!H14,'2000'!H14,'2001'!H14,'2002'!H14,'2003'!H14,'2004'!H14,'2005'!H14,'2006'!H14,'2007'!H14,'2008'!H14,'2009'!H14,'2010'!H14,'2011'!H14,'2012'!H14,'2013'!H14,'2014'!H14,'2015'!H14,'2016'!H14,'2017'!H14,'2018'!H14,'2019'!H14,'2020'!H14,'2021'!H14,'2022'!H14,'2023'!H14,'2024'!H14,'2025'!H14) | I14: =AVERAGE('1991'!I14,'1992'!I14,'1993'!I14,'1994'!I14,'1995'!I14,'1996'!I14,'1997'!I14,'1998'!I14,'1999'!I14,'2000'!I14,'2001'!I14,'2002'!I14,'2003'!I14,'2004'!I14,'2005'!I14,'2006'!I14,'2007'!I14,'2008'!I14,'2009'!I14,'2010'!I14,'2011'!I14,'2012'!I14,'2013'!I14,'2014'!I14,'2015'!I14,'2016'!I14,'2017'!I14,'2018'!I14,'2019'!I14,'2020'!I14,'2021'!I14,'2022'!I14,'2023'!I14,'2024'!I14,'2025'!I14) | ... M14: =AVERAGE('1991'!M14,'1992'!M14,'1993'!M14,'1994'!M14,'1995'!M14,'1996'!M14,'1997'!M14,'1998'!M14,'1999'!M14,'2000'!M14,'2001'!M14,'2002'!M14,'2003'!M14,'2004'!M14,'2005'!M14,'2006'!M14,'2007'!M14,'2008'!M14,'2009'!M14,'2010'!M14,'2011'!M14,'2012'!M14,'2013'!M14,'2014'!M14,'2015'!M14,'2016'!M14,'2017'!M14,'2018'!M14,'2019'!M14,'2020'!M14,'2021'!M14,'2022'!M14,'2023'!M14,'2024'!M14,'2025'!M14) | N14: =AVERAGE(B14:M14)
A15: TRAJANJE SIJANJA SUNCA (h)
A16: Prosek | B16: =AVERAGE('1991'!B16,'1992'!B16,'1993'!B16,'1994'!B16,'1995'!B16,'1996'!B16,'1997'!B16,'1998'!B16,'1999'!B16,'2000'!B16,'2001'!B16,'2002'!B16,'2003'!B16,'2004'!B16,'2005'!B16,'2006'!B16,'2007'!B16,'2008'!B16,'2009'!B16,'2010'!B16,'2011'!B16,'2012'!B16,'2013'!B16,'2014'!B16,'2015'!B16,'2016'!B16,'2017'!B16,'2018'!B16,'2019'!B16,'2020'!B16,'2021'!B16,'2022'!B16,'2023'!B16,'2024'!B16,'2025'!B16) | C16: =AVERAGE('1991'!C16,'1992'!C16,'1993'!C16,'1994'!C16,'1995'!C16,'1996'!C16,'1997'!C16,'1998'!C16,'1999'!C16,'2000'!C16,'2001'!C16,'2002'!C16,'2003'!C16,'2004'!C16,'2005'!C16,'2006'!C16,'2007'!C16,'2008'!C16,'2009'!C16,'2010'!C16,'2011'!C16,'2012'!C16,'2013'!C16,'2014'!C16,'2015'!C16,'2016'!C16,'2017'!C16,'2018'!C16,'2019'!C16,'2020'!C16,'2021'!C16,'2022'!C16,'2023'!C16,'2024'!C16,'2025'!C16) | D16: =AVERAGE('1991'!D16,'1992'!D16,'1993'!D16,'1994'!D16,'1995'!D16,'1996'!D16,'1997'!D16,'1998'!D16,'1999'!D16,'2000'!D16,'2001'!D16,'2002'!D16,'2003'!D16,'2004'!D16,'2005'!D16,'2006'!D16,'2007'!D16,'2008'!D16,'2009'!D16,'2010'!D16,'2011'!D16,'2012'!D16,'2013'!D16,'2014'!D16,'2015'!D16,'2016'!D16,'2017'!D16,'2018'!D16,'2019'!D16,'2020'!D16,'2021'!D16,'2022'!D16,'2023'!D16,'2024'!D16,'2025'!D16) | E16: =AVERAGE('1991'!E16,'1992'!E16,'1993'!E16,'1994'!E16,'1995'!E16,'1996'!E16,'1997'!E16,'1998'!E16,'1999'!E16,'2000'!E16,'2001'!E16,'2002'!E16,'2003'!E16,'2004'!E16,'2005'!E16,'2006'!E16,'2007'!E16,'2008'!E16,'2009'!E16,'2010'!E16,'2011'!E16,'2012'!E16,'2013'!E16,'2014'!E16,'2015'!E16,'2016'!E16,'2017'!E16,'2018'!E16,'2019'!E16,'2020'!E16,'2021'!E16,'2022'!E16,'2023'!E16,'2024'!E16,'2025'!E16) | F16: =AVERAGE('1991'!F16,'1992'!F16,'1993'!F16,'1994'!F16,'1995'!F16,'1996'!F16,'1997'!F16,'1998'!F16,'1999'!F16,'2000'!F16,'2001'!F16,'2002'!F16,'2003'!F16,'2004'!F16,'2005'!F16,'2006'!F16,'2007'!F16,'2008'!F16,'2009'!F16,'2010'!F16,'2011'!F16,'2012'!F16,'2013'!F16,'2014'!F16,'2015'!F16,'2016'!F16,'2017'!F16,'2018'!F16,'2019'!F16,'2020'!F16,'2021'!F16,'2022'!F16,'2023'!F16,'2024'!F16,'2025'!F16) | G16: =AVERAGE('1991'!G16,'1992'!G16,'1993'!G16,'1994'!G16,'1995'!G16,'1996'!G16,'1997'!G16,'1998'!G16,'1999'!G16,'2000'!G16,'2001'!G16,'2002'!G16,'2003'!G16,'2004'!G16,'2005'!G16,'2006'!G16,'2007'!G16,'2008'!G16,'2009'!G16,'2010'!G16,'2011'!G16,'2012'!G16,'2013'!G16,'2014'!G16,'2015'!G16,'2016'!G16,'2017'!G16,'2018'!G16,'2019'!G16,'2020'!G16,'2021'!G16,'2022'!G16,'2023'!G16,'2024'!G16,'2025'!G16) | H16: =AVERAGE('1991'!H16,'1992'!H16,'1993'!H16,'1994'!H16,'1995'!H16,'1996'!H16,'1997'!H16,'1998'!H16,'1999'!H16,'2000'!H16,'2001'!H16,'2002'!H16,'2003'!H16,'2004'!H16,'2005'!H16,'2006'!H16,'2007'!H16,'2008'!H16,'2009'!H16,'2010'!H16,'2011'!H16,'2012'!H16,'2013'!H16,'2014'!H16,'2015'!H16,'2016'!H16,'2017'!H16,'2018'!H16,'2019'!H16,'2020'!H16,'2021'!H16,'2022'!H16,'2023'!H16,'2024'!H16,'2025'!H16) | I16: =AVERAGE('1991'!I16,'1992'!I16,'1993'!I16,'1994'!I16,'1995'!I16,'1996'!I16,'1997'!I16,'1998'!I16,'1999'!I16,'2000'!I16,'2001'!I16,'2002'!I16,'2003'!I16,'2004'!I16,'2005'!I16,'2006'!I16,'2007'!I16,'2008'!I16,'2009'!I16,'2010'!I16,'2011'!I16,'2012'!I16,'2013'!I16,'2014'!I16,'2015'!I16,'2016'!I16,'2017'!I16,'2018'!I16,'2019'!I16,'2020'!I16,'2021'!I16,'2022'!I16,'2023'!I16,'2024'!I16,'2025'!I16) | ... M16: =AVERAGE('1991'!M16,'1992'!M16,'1993'!M16,'1994'!M16,'1995'!M16,'1996'!M16,'1997'!M16,'1998'!M16,'1999'!M16,'2000'!M16,'2001'!M16,'2002'!M16,'2003'!M16,'2004'!M16,'2005'!M16,'2006'!M16,'2007'!M16,'2008'!M16,'2009'!M16,'2010'!M16,'2011'!M16,'2012'!M16,'2013'!M16,'2014'!M16,'2015'!M16,'2016'!M16,'2017'!M16,'2018'!M16,'2019'!M16,'2020'!M16,'2021'!M16,'2022'!M16,'2023'!M16,'2024'!M16,'2025'!M16) | N16: =SUM(B16:M16)
A17: Broj vedrih dana | B17: =AVERAGE('1991'!B17,'1992'!B17,'1993'!B17,'1994'!B17,'1995'!B17,'1996'!B17,'1997'!B17,'1998'!B17,'1999'!B17,'2000'!B17,'2001'!B17,'2002'!B17,'2003'!B17,'2004'!B17,'2005'!B17,'2006'!B17,'2007'!B17,'2008'!B17,'2009'!B17,'2010'!B17,'2011'!B17,'2012'!B17,'2013'!B17,'2014'!B17,'2015'!B17,'2016'!B17,'2017'!B17,'2018'!B17,'2019'!B17,'2020'!B17,'2021'!B17,'2022'!B17,'2023'!B17,'2024'!B17,'2025'!B17) | C17: =AVERAGE('1991'!C17,'1992'!C17,'1993'!C17,'1994'!C17,'1995'!C17,'1996'!C17,'1997'!C17,'1998'!C17,'1999'!C17,'2000'!C17,'2001'!C17,'2002'!C17,'2003'!C17,'2004'!C17,'2005'!C17,'2006'!C17,'2007'!C17,'2008'!C17,'2009'!C17,'2010'!C17,'2011'!C17,'2012'!C17,'2013'!C17,'2014'!C17,'2015'!C17,'2016'!C17,'2017'!C17,'2018'!C17,'2019'!C17,'2020'!C17,'2021'!C17,'2022'!C17,'2023'!C17,'2024'!C17,'2025'!C17) | D17: =AVERAGE('1991'!D17,'1992'!D17,'1993'!D17,'1994'!D17,'1995'!D17,'1996'!D17,'1997'!D17,'1998'!D17,'1999'!D17,'2000'!D17,'2001'!D17,'2002'!D17,'2003'!D17,'2004'!D17,'2005'!D17,'2006'!D17,'2007'!D17,'2008'!D17,'2009'!D17,'2010'!D17,'2011'!D17,'2012'!D17,'2013'!D17,'2014'!D17,'2015'!D17,'2016'!D17,'2017'!D17,'2018'!D17,'2019'!D17,'2020'!D17,'2021'!D17,'2022'!D17,'2023'!D17,'2024'!D17,'2025'!D17) | E17: =AVERAGE('1991'!E17,'1992'!E17,'1993'!E17,'1994'!E17,'1995'!E17,'1996'!E17,'1997'!E17,'1998'!E17,'1999'!E17,'2000'!E17,'2001'!E17,'2002'!E17,'2003'!E17,'2004'!E17,'2005'!E17,'2006'!E17,'2007'!E17,'2008'!E17,'2009'!E17,'2010'!E17,'2011'!E17,'2012'!E17,'2013'!E17,'2014'!E17,'2015'!E17,'2016'!E17,'2017'!E17,'2018'!E17,'2019'!E17,'2020'!E17,'2021'!E17,'2022'!E17,'2023'!E17,'2024'!E17,'2025'!E17) | F17: =AVERAGE('1991'!F17,'1992'!F17,'1993'!F17,'1994'!F17,'1995'!F17,'1996'!F17,'1997'!F17,'1998'!F17,'1999'!F17,'2000'!F17,'2001'!F17,'2002'!F17,'2003'!F17,'2004'!F17,'2005'!F17,'2006'!F17,'2007'!F17,'2008'!F17,'2009'!F17,'2010'!F17,'2011'!F17,'2012'!F17,'2013'!F17,'2014'!F17,'2015'!F17,'2016'!F17,'2017'!F17,'2018'!F17,'2019'!F17,'2020'!F17,'2021'!F17,'2022'!F17,'2023'!F17,'2024'!F17,'2025'!F17) | G17: =AVERAGE('1991'!G17,'1992'!G17,'1993'!G17,'1994'!G17,'1995'!G17,'1996'!G17,'1997'!G17,'1998'!G17,'1999'!G17,'2000'!G17,'2001'!G17,'2002'!G17,'2003'!G17,'2004'!G17,'2005'!G17,'2006'!G17,'2007'!G17,'2008'!G17,'2009'!G17,'2010'!G17,'2011'!G17,'2012'!G17,'2013'!G17,'2014'!G17,'2015'!G17,'2016'!G17,'2017'!G17,'2018'!G17,'2019'!G17,'2020'!G17,'2021'!G17,'2022'!G17,'2023'!G17,'2024'!G17,'2025'!G17) | H17: =AVERAGE('1991'!H17,'1992'!H17,'1993'!H17,'1994'!H17,'1995'!H17,'1996'!H17,'1997'!H17,'1998'!H17,'1999'!H17,'2000'!H17,'2001'!H17,'2002'!H17,'2003'!H17,'2004'!H17,'2005'!H17,'2006'!H17,'2007'!H17,'2008'!H17,'2009'!H17,'2010'!H17,'2011'!H17,'2012'!H17,'2013'!H17,'2014'!H17,'2015'!H17,'2016'!H17,'2017'!H17,'2018'!H17,'2019'!H17,'2020'!H17,'2021'!H17,'2022'!H17,'2023'!H17,'2024'!H17,'2025'!H17) | I17: =AVERAGE('1991'!I17,'1992'!I17,'1993'!I17,'1994'!I17,'1995'!I17,'1996'!I17,'1997'!I17,'1998'!I17,'1999'!I17,'2000'!I17,'2001'!I17,'2002'!I17,'2003'!I17,'2004'!I17,'2005'!I17,'2006'!I17,'2007'!I17,'2008'!I17,'2009'!I17,'2010'!I17,'2011'!I17,'2012'!I17,'2013'!I17,'2014'!I17,'2015'!I17,'2016'!I17,'2017'!I17,'2018'!I17,'2019'!I17,'2020'!I17,'2021'!I17,'2022'!I17,'2023'!I17,'2024'!I17,'2025'!I17) | ... M17: =AVERAGE('1991'!M17,'1992'!M17,'1993'!M17,'1994'!M17,'1995'!M17,'1996'!M17,'1997'!M17,'1998'!M17,'1999'!M17,'2000'!M17,'2001'!M17,'2002'!M17,'2003'!M17,'2004'!M17,'2005'!M17,'2006'!M17,'2007'!M17,'2008'!M17,'2009'!M17,'2010'!M17,'2011'!M17,'2012'!M17,'2013'!M17,'2014'!M17,'2015'!M17,'2016'!M17,'2017'!M17,'2018'!M17,'2019'!M17,'2020'!M17,'2021'!M17,'2022'!M17,'2023'!M17,'2024'!M17,'2025'!M17) | N17: =SUM(B17:M17)
A18: Broj oblačnih dana | B18: =AVERAGE('1991'!B18,'1992'!B18,'1993'!B18,'1994'!B18,'1995'!B18,'1996'!B18,'1997'!B18,'1998'!B18,'1999'!B18,'2000'!B18,'2001'!B18,'2002'!B18,'2003'!B18,'2004'!B18,'2005'!B18,'2006'!B18,'2007'!B18,'2008'!B18,'2009'!B18,'2010'!B18,'2011'!B18,'2012'!B18,'2013'!B18,'2014'!B18,'2015'!B18,'2016'!B18,'2017'!B18,'2018'!B18,'2019'!B18,'2020'!B18,'2021'!B18,'2022'!B18,'2023'!B18,'2024'!B18,'2025'!B18) | C18: =AVERAGE('1991'!C18,'1992'!C18,'1993'!C18,'1994'!C18,'1995'!C18,'1996'!C18,'1997'!C18,'1998'!C18,'1999'!C18,'2000'!C18,'2001'!C18,'2002'!C18,'2003'!C18,'2004'!C18,'2005'!C18,'2006'!C18,'2007'!C18,'2008'!C18,'2009'!C18,'2010'!C18,'2011'!C18,'2012'!C18,'2013'!C18,'2014'!C18,'2015'!C18,'2016'!C18,'2017'!C18,'2018'!C18,'2019'!C18,'2020'!C18,'2021'!C18,'2022'!C18,'2023'!C18,'2024'!C18,'2025'!C18) | D18: =AVERAGE('1991'!D18,'1992'!D18,'1993'!D18,'1994'!D18,'1995'!D18,'1996'!D18,'1997'!D18,'1998'!D18,'1999'!D18,'2000'!D18,'2001'!D18,'2002'!D18,'2003'!D18,'2004'!D18,'2005'!D18,'2006'!D18,'2007'!D18,'2008'!D18,'2009'!D18,'2010'!D18,'2011'!D18,'2012'!D18,'2013'!D18,'2014'!D18,'2015'!D18,'2016'!D18,'2017'!D18,'2018'!D18,'2019'!D18,'2020'!D18,'2021'!D18,'2022'!D18,'2023'!D18,'2024'!D18,'2025'!D18) | E18: =AVERAGE('1991'!E18,'1992'!E18,'1993'!E18,'1994'!E18,'1995'!E18,'1996'!E18,'1997'!E18,'1998'!E18,'1999'!E18,'2000'!E18,'2001'!E18,'2002'!E18,'2003'!E18,'2004'!E18,'2005'!E18,'2006'!E18,'2007'!E18,'2008'!E18,'2009'!E18,'2010'!E18,'2011'!E18,'2012'!E18,'2013'!E18,'2014'!E18,'2015'!E18,'2016'!E18,'2017'!E18,'2018'!E18,'2019'!E18,'2020'!E18,'2021'!E18,'2022'!E18,'2023'!E18,'2024'!E18,'2025'!E18) | F18: =AVERAGE('1991'!F18,'1992'!F18,'1993'!F18,'1994'!F18,'1995'!F18,'1996'!F18,'1997'!F18,'1998'!F18,'1999'!F18,'2000'!F18,'2001'!F18,'2002'!F18,'2003'!F18,'2004'!F18,'2005'!F18,'2006'!F18,'2007'!F18,'2008'!F18,'2009'!F18,'2010'!F18,'2011'!F18,'2012'!F18,'2013'!F18,'2014'!F18,'2015'!F18,'2016'!F18,'2017'!F18,'2018'!F18,'2019'!F18,'2020'!F18,'2021'!F18,'2022'!F18,'2023'!F18,'2024'!F18,'2025'!F18) | G18: =AVERAGE('1991'!G18,'1992'!G18,'1993'!G18,'1994'!G18,'1995'!G18,'1996'!G18,'1997'!G18,'1998'!G18,'1999'!G18,'2000'!G18,'2001'!G18,'2002'!G18,'2003'!G18,'2004'!G18,'2005'!G18,'2006'!G18,'2007'!G18,'2008'!G18,'2009'!G18,'2010'!G18,'2011'!G18,'2012'!G18,'2013'!G18,'2014'!G18,'2015'!G18,'2016'!G18,'2017'!G18,'2018'!G18,'2019'!G18,'2020'!G18,'2021'!G18,'2022'!G18,'2023'!G18,'2024'!G18,'2025'!G18) | H18: =AVERAGE('1991'!H18,'1992'!H18,'1993'!H18,'1994'!H18,'1995'!H18,'1996'!H18,'1997'!H18,'1998'!H18,'1999'!H18,'2000'!H18,'2001'!H18,'2002'!H18,'2003'!H18,'2004'!H18,'2005'!H18,'2006'!H18,'2007'!H18,'2008'!H18,'2009'!H18,'2010'!H18,'2011'!H18,'2012'!H18,'2013'!H18,'2014'!H18,'2015'!H18,'2016'!H18,'2017'!H18,'2018'!H18,'2019'!H18,'2020'!H18,'2021'!H18,'2022'!H18,'2023'!H18,'2024'!H18,'2025'!H18) | I18: =AVERAGE('1991'!I18,'1992'!I18,'1993'!I18,'1994'!I18,'1995'!I18,'1996'!I18,'1997'!I18,'1998'!I18,'1999'!I18,'2000'!I18,'2001'!I18,'2002'!I18,'2003'!I18,'2004'!I18,'2005'!I18,'2006'!I18,'2007'!I18,'2008'!I18,'2009'!I18,'2010'!I18,'2011'!I18,'2012'!I18,'2013'!I18,'2014'!I18,'2015'!I18,'2016'!I18,'2017'!I18,'2018'!I18,'2019'!I18,'2020'!I18,'2021'!I18,'2022'!I18,'2023'!I18,'2024'!I18,'2025'!I18) | ... M18: =AVERAGE('1991'!M18,'1992'!M18,'1993'!M18,'1994'!M18,'1995'!M18,'1996'!M18,'1997'!M18,'1998'!M18,'1999'!M18,'2000'!M18,'2001'!M18,'2002'!M18,'2003'!M18,'2004'!M18,'2005'!M18,'2006'!M18,'2007'!M18,'2008'!M18,'2009'!M18,'2010'!M18,'2011'!M18,'2012'!M18,'2013'!M18,'2014'!M18,'2015'!M18,'2016'!M18,'2017'!M18,'2018'!M18,'2019'!M18,'2020'!M18,'2021'!M18,'2022'!M18,'2023'!M18,'2024'!M18,'2025'!M18) | N18: =SUM(B18:M18)
A19: PADAVINE (mm)
A20: Sr. mesečna suma | B20: =AVERAGE('1991'!B20,'1992'!B20,'1993'!B20,'1994'!B20,'1995'!B20,'1996'!B20,'1997'!B20,'1998'!B20,'1999'!B20,'2000'!B20,'2001'!B20,'2002'!B20,'2003'!B20,'2004'!B20,'2005'!B20,'2006'!B20,'2007'!B20,'2008'!B20,'2009'!B20,'2010'!B20,'2011'!B20,'2012'!B20,'2013'!B20,'2014'!B20,'2015'!B20,'2016'!B20,'2017'!B20,'2018'!B20,'2019'!B20,'2020'!B20,'2021'!B20,'2022'!B20,'2023'!B20,'2024'!B20,'2025'!B20) | C20: =AVERAGE('1991'!C20,'1992'!C20,'1993'!C20,'1994'!C20,'1995'!C20,'1996'!C20,'1997'!C20,'1998'!C20,'1999'!C20,'2000'!C20,'2001'!C20,'2002'!C20,'2003'!C20,'2004'!C20,'2005'!C20,'2006'!C20,'2007'!C20,'2008'!C20,'2009'!C20,'2010'!C20,'2011'!C20,'2012'!C20,'2013'!C20,'2014'!C20,'2015'!C20,'2016'!C20,'2017'!C20,'2018'!C20,'2019'!C20,'2020'!C20,'2021'!C20,'2022'!C20,'2023'!C20,'2024'!C20,'2025'!C20) | D20: =AVERAGE('1991'!D20,'1992'!D20,'1993'!D20,'1994'!D20,'1995'!D20,'1996'!D20,'1997'!D20,'1998'!D20,'1999'!D20,'2000'!D20,'2001'!D20,'2002'!D20,'2003'!D20,'2004'!D20,'2005'!D20,'2006'!D20,'2007'!D20,'2008'!D20,'2009'!D20,'2010'!D20,'2011'!D20,'2012'!D20,'2013'!D20,'2014'!D20,'2015'!D20,'2016'!D20,'2017'!D20,'2018'!D20,'2019'!D20,'2020'!D20,'2021'!D20,'2022'!D20,'2023'!D20,'2024'!D20,'2025'!D20) | E20: =AVERAGE('1991'!E20,'1992'!E20,'1993'!E20,'1994'!E20,'1995'!E20,'1996'!E20,'1997'!E20,'1998'!E20,'1999'!E20,'2000'!E20,'2001'!E20,'2002'!E20,'2003'!E20,'2004'!E20,'2005'!E20,'2006'!E20,'2007'!E20,'2008'!E20,'2009'!E20,'2010'!E20,'2011'!E20,'2012'!E20,'2013'!E20,'2014'!E20,'2015'!E20,'2016'!E20,'2017'!E20,'2018'!E20,'2019'!E20,'2020'!E20,'2021'!E20,'2022'!E20,'2023'!E20,'2024'!E20,'2025'!E20) | F20: =AVERAGE('1991'!F20,'1992'!F20,'1993'!F20,'1994'!F20,'1995'!F20,'1996'!F20,'1997'!F20,'1998'!F20,'1999'!F20,'2000'!F20,'2001'!F20,'2002'!F20,'2003'!F20,'2004'!F20,'2005'!F20,'2006'!F20,'2007'!F20,'2008'!F20,'2009'!F20,'2010'!F20,'2011'!F20,'2012'!F20,'2013'!F20,'2014'!F20,'2015'!F20,'2016'!F20,'2017'!F20,'2018'!F20,'2019'!F20,'2020'!F20,'2021'!F20,'2022'!F20,'2023'!F20,'2024'!F20,'2025'!F20) | G20: =AVERAGE('1991'!G20,'1992'!G20,'1993'!G20,'1994'!G20,'1995'!G20,'1996'!G20,'1997'!G20,'1998'!G20,'1999'!G20,'2000'!G20,'2001'!G20,'2002'!G20,'2003'!G20,'2004'!G20,'2005'!G20,'2006'!G20,'2007'!G20,'2008'!G20,'2009'!G20,'2010'!G20,'2011'!G20,'2012'!G20,'2013'!G20,'2014'!G20,'2015'!G20,'2016'!G20,'2017'!G20,'2018'!G20,'2019'!G20,'2020'!G20,'2021'!G20,'2022'!G20,'2023'!G20,'2024'!G20,'2025'!G20) | H20: =AVERAGE('1991'!H20,'1992'!H20,'1993'!H20,'1994'!H20,'1995'!H20,'1996'!H20,'1997'!H20,'1998'!H20,'1999'!H20,'2000'!H20,'2001'!H20,'2002'!H20,'2003'!H20,'2004'!H20,'2005'!H20,'2006'!H20,'2007'!H20,'2008'!H20,'2009'!H20,'2010'!H20,'2011'!H20,'2012'!H20,'2013'!H20,'2014'!H20,'2015'!H20,'2016'!H20,'2017'!H20,'2018'!H20,'2019'!H20,'2020'!H20,'2021'!H20,'2022'!H20,'2023'!H20,'2024'!H20,'2025'!H20) | I20: =AVERAGE('1991'!I20,'1992'!I20,'1993'!I20,'1994'!I20,'1995'!I20,'1996'!I20,'1997'!I20,'1998'!I20,'1999'!I20,'2000'!I20,'2001'!I20,'2002'!I20,'2003'!I20,'2004'!I20,'2005'!I20,'2006'!I20,'2007'!I20,'2008'!I20,'2009'!I20,'2010'!I20,'2011'!I20,'2012'!I20,'2013'!I20,'2014'!I20,'2015'!I20,'2016'!I20,'2017'!I20,'2018'!I20,'2019'!I20,'2020'!I20,'2021'!I20,'2022'!I20,'2023'!I20,'2024'!I20,'2025'!I20) | ... M20: =AVERAGE('1991'!M20,'1992'!M20,'1993'!M20,'1994'!M20,'1995'!M20,'1996'!M20,'1997'!M20,'1998'!M20,'1999'!M20,'2000'!M20,'2001'!M20,'2002'!M20,'2003'!M20,'2004'!M20,'2005'!M20,'2006'!M20,'2007'!M20,'2008'!M20,'2009'!M20,'2010'!M20,'2011'!M20,'2012'!M20,'2013'!M20,'2014'!M20,'2015'!M20,'2016'!M20,'2017'!M20,'2018'!M20,'2019'!M20,'2020'!M20,'2021'!M20,'2022'!M20,'2023'!M20,'2024'!M20,'2025'!M20) | N20: =SUM(B20:M20)
A21: Max. dnevna suma | B21: =AVERAGE('1991'!B21,'1992'!B21,'1993'!B21,'1994'!B21,'1995'!B21,'1996'!B21,'1997'!B21,'1998'!B21,'1999'!B21,'2000'!B21,'2001'!B21,'2002'!B21,'2003'!B21,'2004'!B21,'2005'!B21,'2006'!B21,'2007'!B21,'2008'!B21,'2009'!B21,'2010'!B21,'2011'!B21,'2012'!B21,'2013'!B21,'2014'!B21,'2015'!B21,'2016'!B21,'2017'!B21,'2018'!B21,'2019'!B21,'2020'!B21,'2021'!B21,'2022'!B21,'2023'!B21,'2024'!B21,'2025'!B21) | C21: =AVERAGE('1991'!C21,'1992'!C21,'1993'!C21,'1994'!C21,'1995'!C21,'1996'!C21,'1997'!C21,'1998'!C21,'1999'!C21,'2000'!C21,'2001'!C21,'2002'!C21,'2003'!C21,'2004'!C21,'2005'!C21,'2006'!C21,'2007'!C21,'2008'!C21,'2009'!C21,'2010'!C21,'2011'!C21,'2012'!C21,'2013'!C21,'2014'!C21,'2015'!C21,'2016'!C21,'2017'!C21,'2018'!C21,'2019'!C21,'2020'!C21,'2021'!C21,'2022'!C21,'2023'!C21,'2024'!C21,'2025'!C21) | D21: =AVERAGE('1991'!D21,'1992'!D21,'1993'!D21,'1994'!D21,'1995'!D21,'1996'!D21,'1997'!D21,'1998'!D21,'1999'!D21,'2000'!D21,'2001'!D21,'2002'!D21,'2003'!D21,'2004'!D21,'2005'!D21,'2006'!D21,'2007'!D21,'2008'!D21,'2009'!D21,'2010'!D21,'2011'!D21,'2012'!D21,'2013'!D21,'2014'!D21,'2015'!D21,'2016'!D21,'2017'!D21,'2018'!D21,'2019'!D21,'2020'!D21,'2021'!D21,'2022'!D21,'2023'!D21,'2024'!D21,'2025'!D21) | E21: =AVERAGE('1991'!E21,'1992'!E21,'1993'!E21,'1994'!E21,'1995'!E21,'1996'!E21,'1997'!E21,'1998'!E21,'1999'!E21,'2000'!E21,'2001'!E21,'2002'!E21,'2003'!E21,'2004'!E21,'2005'!E21,'2006'!E21,'2007'!E21,'2008'!E21,'2009'!E21,'2010'!E21,'2011'!E21,'2012'!E21,'2013'!E21,'2014'!E21,'2015'!E21,'2016'!E21,'2017'!E21,'2018'!E21,'2019'!E21,'2020'!E21,'2021'!E21,'2022'!E21,'2023'!E21,'2024'!E21,'2025'!E21) | F21: =AVERAGE('1991'!F21,'1992'!F21,'1993'!F21,'1994'!F21,'1995'!F21,'1996'!F21,'1997'!F21,'1998'!F21,'1999'!F21,'2000'!F21,'2001'!F21,'2002'!F21,'2003'!F21,'2004'!F21,'2005'!F21,'2006'!F21,'2007'!F21,'2008'!F21,'2009'!F21,'2010'!F21,'2011'!F21,'2012'!F21,'2013'!F21,'2014'!F21,'2015'!F21,'2016'!F21,'2017'!F21,'2018'!F21,'2019'!F21,'2020'!F21,'2021'!F21,'2022'!F21,'2023'!F21,'2024'!F21,'2025'!F21) | G21: =AVERAGE('1991'!G21,'1992'!G21,'1993'!G21,'1994'!G21,'1995'!G21,'1996'!G21,'1997'!G21,'1998'!G21,'1999'!G21,'2000'!G21,'2001'!G21,'2002'!G21,'2003'!G21,'2004'!G21,'2005'!G21,'2006'!G21,'2007'!G21,'2008'!G21,'2009'!G21,'2010'!G21,'2011'!G21,'2012'!G21,'2013'!G21,'2014'!G21,'2015'!G21,'2016'!G21,'2017'!G21,'2018'!G21,'2019'!G21,'2020'!G21,'2021'!G21,'2022'!G21,'2023'!G21,'2024'!G21,'2025'!G21) | H21: =AVERAGE('1991'!H21,'1992'!H21,'1993'!H21,'1994'!H21,'1995'!H21,'1996'!H21,'1997'!H21,'1998'!H21,'1999'!H21,'2000'!H21,'2001'!H21,'2002'!H21,'2003'!H21,'2004'!H21,'2005'!H21,'2006'!H21,'2007'!H21,'2008'!H21,'2009'!H21,'2010'!H21,'2011'!H21,'2012'!H21,'2013'!H21,'2014'!H21,'2015'!H21,'2016'!H21,'2017'!H21,'2018'!H21,'2019'!H21,'2020'!H21,'2021'!H21,'2022'!H21,'2023'!H21,'2024'!H21,'2025'!H21) | I21: =AVERAGE('1991'!I21,'1992'!I21,'1993'!I21,'1994'!I21,'1995'!I21,'1996'!I21,'1997'!I21,'1998'!I21,'1999'!I21,'2000'!I21,'2001'!I21,'2002'!I21,'2003'!I21,'2004'!I21,'2005'!I21,'2006'!I21,'2007'!I21,'2008'!I21,'2009'!I21,'2010'!I21,'2011'!I21,'2012'!I21,'2013'!I21,'2014'!I21,'2015'!I21,'2016'!I21,'2017'!I21,'2018'!I21,'2019'!I21,'2020'!I21,'2021'!I21,'2022'!I21,'2023'!I21,'2024'!I21,'2025'!I21) | ... M21: =AVERAGE('1991'!M21,'1992'!M21,'1993'!M21,'1994'!M21,'1995'!M21,'1996'!M21,'1997'!M21,'1998'!M21,'1999'!M21,'2000'!M21,'2001'!M21,'2002'!M21,'2003'!M21,'2004'!M21,'2005'!M21,'2006'!M21,'2007'!M21,'2008'!M21,'2009'!M21,'2010'!M21,'2011'!M21,'2012'!M21,'2013'!M21,'2014'!M21,'2015'!M21,'2016'!M21,'2017'!M21,'2018'!M21,'2019'!M21,'2020'!M21,'2021'!M21,'2022'!M21,'2023'!M21,'2024'!M21,'2025'!M21) | N21: =MAX(B21:M21)
A22: Sr. br. dana >= 0.1 mm | B22: =AVERAGE('1991'!B22,'1992'!B22,'1993'!B22,'1994'!B22,'1995'!B22,'1996'!B22,'1997'!B22,'1998'!B22,'1999'!B22,'2000'!B22,'2001'!B22,'2002'!B22,'2003'!B22,'2004'!B22,'2005'!B22,'2006'!B22,'2007'!B22,'2008'!B22,'2009'!B22,'2010'!B22,'2011'!B22,'2012'!B22,'2013'!B22,'2014'!B22,'2015'!B22,'2016'!B22,'2017'!B22,'2018'!B22,'2019'!B22,'2020'!B22,'2021'!B22,'2022'!B22,'2023'!B22,'2024'!B22,'2025'!B22) | C22: =AVERAGE('1991'!C22,'1992'!C22,'1993'!C22,'1994'!C22,'1995'!C22,'1996'!C22,'1997'!C22,'1998'!C22,'1999'!C22,'2000'!C22,'2001'!C22,'2002'!C22,'2003'!C22,'2004'!C22,'2005'!C22,'2006'!C22,'2007'!C22,'2008'!C22,'2009'!C22,'2010'!C22,'2011'!C22,'2012'!C22,'2013'!C22,'2014'!C22,'2015'!C22,'2016'!C22,'2017'!C22,'2018'!C22,'2019'!C22,'2020'!C22,'2021'!C22,'2022'!C22,'2023'!C22,'2024'!C22,'2025'!C22) | D22: =AVERAGE('1991'!D22,'1992'!D22,'1993'!D22,'1994'!D22,'1995'!D22,'1996'!D22,'1997'!D22,'1998'!D22,'1999'!D22,'2000'!D22,'2001'!D22,'2002'!D22,'2003'!D22,'2004'!D22,'2005'!D22,'2006'!D22,'2007'!D22,'2008'!D22,'2009'!D22,'2010'!D22,'2011'!D22,'2012'!D22,'2013'!D22,'2014'!D22,'2015'!D22,'2016'!D22,'2017'!D22,'2018'!D22,'2019'!D22,'2020'!D22,'2021'!D22,'2022'!D22,'2023'!D22,'2024'!D22,'2025'!D22) | E22: =AVERAGE('1991'!E22,'1992'!E22,'1993'!E22,'1994'!E22,'1995'!E22,'1996'!E22,'1997'!E22,'1998'!E22,'1999'!E22,'2000'!E22,'2001'!E22,'2002'!E22,'2003'!E22,'2004'!E22,'2005'!E22,'2006'!E22,'2007'!E22,'2008'!E22,'2009'!E22,'2010'!E22,'2011'!E22,'2012'!E22,'2013'!E22,'2014'!E22,'2015'!E22,'2016'!E22,'2017'!E22,'2018'!E22,'2019'!E22,'2020'!E22,'2021'!E22,'2022'!E22,'2023'!E22,'2024'!E22,'2025'!E22) | F22: =AVERAGE('1991'!F22,'1992'!F22,'1993'!F22,'1994'!F22,'1995'!F22,'1996'!F22,'1997'!F22,'1998'!F22,'1999'!F22,'2000'!F22,'2001'!F22,'2002'!F22,'2003'!F22,'2004'!F22,'2005'!F22,'2006'!F22,'2007'!F22,'2008'!F22,'2009'!F22,'2010'!F22,'2011'!F22,'2012'!F22,'2013'!F22,'2014'!F22,'2015'!F22,'2016'!F22,'2017'!F22,'2018'!F22,'2019'!F22,'2020'!F22,'2021'!F22,'2022'!F22,'2023'!F22,'2024'!F22,'2025'!F22) | G22: =AVERAGE('1991'!G22,'1992'!G22,'1993'!G22,'1994'!G22,'1995'!G22,'1996'!G22,'1997'!G22,'1998'!G22,'1999'!G22,'2000'!G22,'2001'!G22,'2002'!G22,'2003'!G22,'2004'!G22,'2005'!G22,'2006'!G22,'2007'!G22,'2008'!G22,'2009'!G22,'2010'!G22,'2011'!G22,'2012'!G22,'2013'!G22,'2014'!G22,'2015'!G22,'2016'!G22,'2017'!G22,'2018'!G22,'2019'!G22,'2020'!G22,'2021'!G22,'2022'!G22,'2023'!G22,'2024'!G22,'2025'!G22) | H22: =AVERAGE('1991'!H22,'1992'!H22,'1993'!H22,'1994'!H22,'1995'!H22,'1996'!H22,'1997'!H22,'1998'!H22,'1999'!H22,'2000'!H22,'2001'!H22,'2002'!H22,'2003'!H22,'2004'!H22,'2005'!H22,'2006'!H22,'2007'!H22,'2008'!H22,'2009'!H22,'2010'!H22,'2011'!H22,'2012'!H22,'2013'!H22,'2014'!H22,'2015'!H22,'2016'!H22,'2017'!H22,'2018'!H22,'2019'!H22,'2020'!H22,'2021'!H22,'2022'!H22,'2023'!H22,'2024'!H22,'2025'!H22) | I22: =AVERAGE('1991'!I22,'1992'!I22,'1993'!I22,'1994'!I22,'1995'!I22,'1996'!I22,'1997'!I22,'1998'!I22,'1999'!I22,'2000'!I22,'2001'!I22,'2002'!I22,'2003'!I22,'2004'!I22,'2005'!I22,'2006'!I22,'2007'!I22,'2008'!I22,'2009'!I22,'2010'!I22,'2011'!I22,'2012'!I22,'2013'!I22,'2014'!I22,'2015'!I22,'2016'!I22,'2017'!I22,'2018'!I22,'2019'!I22,'2020'!I22,'2021'!I22,'2022'!I22,'2023'!I22,'2024'!I22,'2025'!I22) | ... M22: =AVERAGE('1991'!M22,'1992'!M22,'1993'!M22,'1994'!M22,'1995'!M22,'1996'!M22,'1997'!M22,'1998'!M22,'1999'!M22,'2000'!M22,'2001'!M22,'2002'!M22,'2003'!M22,'2004'!M22,'2005'!M22,'2006'!M22,'2007'!M22,'2008'!M22,'2009'!M22,'2010'!M22,'2011'!M22,'2012'!M22,'2013'!M22,'2014'!M22,'2015'!M22,'2016'!M22,'2017'!M22,'2018'!M22,'2019'!M22,'2020'!M22,'2021'!M22,'2022'!M22,'2023'!M22,'2024'!M22,'2025'!M22) | N22: =SUM(B22:M22)
A23: Sr. br. dana >= 10.0 mm | B23: =AVERAGE('1991'!B23,'1992'!B23,'1993'!B23,'1994'!B23,'1995'!B23,'1996'!B23,'1997'!B23,'1998'!B23,'1999'!B23,'2000'!B23,'2001'!B23,'2002'!B23,'2003'!B23,'2004'!B23,'2005'!B23,'2006'!B23,'2007'!B23,'2008'!B23,'2009'!B23,'2010'!B23,'2011'!B23,'2012'!B23,'2013'!B23,'2014'!B23,'2015'!B23,'2016'!B23,'2017'!B23,'2018'!B23,'2019'!B23,'2020'!B23,'2021'!B23,'2022'!B23,'2023'!B23,'2024'!B23,'2025'!B23) | C23: =AVERAGE('1991'!C23,'1992'!C23,'1993'!C23,'1994'!C23,'1995'!C23,'1996'!C23,'1997'!C23,'1998'!C23,'1999'!C23,'2000'!C23,'2001'!C23,'2002'!C23,'2003'!C23,'2004'!C23,'2005'!C23,'2006'!C23,'2007'!C23,'2008'!C23,'2009'!C23,'2010'!C23,'2011'!C23,'2012'!C23,'2013'!C23,'2014'!C23,'2015'!C23,'2016'!C23,'2017'!C23,'2018'!C23,'2019'!C23,'2020'!C23,'2021'!C23,'2022'!C23,'2023'!C23,'2024'!C23,'2025'!C23) | D23: =AVERAGE('1991'!D23,'1992'!D23,'1993'!D23,'1994'!D23,'1995'!D23,'1996'!D23,'1997'!D23,'1998'!D23,'1999'!D23,'2000'!D23,'2001'!D23,'2002'!D23,'2003'!D23,'2004'!D23,'2005'!D23,'2006'!D23,'2007'!D23,'2008'!D23,'2009'!D23,'2010'!D23,'2011'!D23,'2012'!D23,'2013'!D23,'2014'!D23,'2015'!D23,'2016'!D23,'2017'!D23,'2018'!D23,'2019'!D23,'2020'!D23,'2021'!D23,'2022'!D23,'2023'!D23,'2024'!D23,'2025'!D23) | E23: =AVERAGE('1991'!E23,'1992'!E23,'1993'!E23,'1994'!E23,'1995'!E23,'1996'!E23,'1997'!E23,'1998'!E23,'1999'!E23,'2000'!E23,'2001'!E23,'2002'!E23,'2003'!E23,'2004'!E23,'2005'!E23,'2006'!E23,'2007'!E23,'2008'!E23,'2009'!E23,'2010'!E23,'2011'!E23,'2012'!E23,'2013'!E23,'2014'!E23,'2015'!E23,'2016'!E23,'2017'!E23,'2018'!E23,'2019'!E23,'2020'!E23,'2021'!E23,'2022'!E23,'2023'!E23,'2024'!E23,'2025'!E23) | F23: =AVERAGE('1991'!F23,'1992'!F23,'1993'!F23,'1994'!F23,'1995'!F23,'1996'!F23,'1997'!F23,'1998'!F23,'1999'!F23,'2000'!F23,'2001'!F23,'2002'!F23,'2003'!F23,'2004'!F23,'2005'!F23,'2006'!F23,'2007'!F23,'2008'!F23,'2009'!F23,'2010'!F23,'2011'!F23,'2012'!F23,'2013'!F23,'2014'!F23,'2015'!F23,'2016'!F23,'2017'!F23,'2018'!F23,'2019'!F23,'2020'!F23,'2021'!F23,'2022'!F23,'2023'!F23,'2024'!F23,'2025'!F23) | G23: =AVERAGE('1991'!G23,'1992'!G23,'1993'!G23,'1994'!G23,'1995'!G23,'1996'!G23,'1997'!G23,'1998'!G23,'1999'!G23,'2000'!G23,'2001'!G23,'2002'!G23,'2003'!G23,'2004'!G23,'2005'!G23,'2006'!G23,'2007'!G23,'2008'!G23,'2009'!G23,'2010'!G23,'2011'!G23,'2012'!G23,'2013'!G23,'2014'!G23,'2015'!G23,'2016'!G23,'2017'!G23,'2018'!G23,'2019'!G23,'2020'!G23,'2021'!G23,'2022'!G23,'2023'!G23,'2024'!G23,'2025'!G23) | H23: =AVERAGE('1991'!H23,'1992'!H23,'1993'!H23,'1994'!H23,'1995'!H23,'1996'!H23,'1997'!H23,'1998'!H23,'1999'!H23,'2000'!H23,'2001'!H23,'2002'!H23,'2003'!H23,'2004'!H23,'2005'!H23,'2006'!H23,'2007'!H23,'2008'!H23,'2009'!H23,'2010'!H23,'2011'!H23,'2012'!H23,'2013'!H23,'2014'!H23,'2015'!H23,'2016'!H23,'2017'!H23,'2018'!H23,'2019'!H23,'2020'!H23,'2021'!H23,'2022'!H23,'2023'!H23,'2024'!H23,'2025'!H23) | I23: =AVERAGE('1991'!I23,'1992'!I23,'1993'!I23,'1994'!I23,'1995'!I23,'1996'!I23,'1997'!I23,'1998'!I23,'1999'!I23,'2000'!I23,'2001'!I23,'2002'!I23,'2003'!I23,'2004'!I23,'2005'!I23,'2006'!I23,'2007'!I23,'2008'!I23,'2009'!I23,'2010'!I23,'2011'!I23,'2012'!I23,'2013'!I23,'2014'!I23,'2015'!I23,'2016'!I23,'2017'!I23,'2018'!I23,'2019'!I23,'2020'!I23,'2021'!I23,'2022'!I23,'2023'!I23,'2024'!I23,'2025'!I23) | ... M23: =AVERAGE('1991'!M23,'1992'!M23,'1993'!M23,'1994'!M23,'1995'!M23,'1996'!M23,'1997'!M23,'1998'!M23,'1999'!M23,'2000'!M23,'2001'!M23,'2002'!M23,'2003'!M23,'2004'!M23,'2005'!M23,'2006'!M23,'2007'!M23,'2008'!M23,'2009'!M23,'2010'!M23,'2011'!M23,'2012'!M23,'2013'!M23,'2014'!M23,'2015'!M23,'2016'!M23,'2017'!M23,'2018'!M23,'2019'!M23,'2020'!M23,'2021'!M23,'2022'!M23,'2023'!M23,'2024'!M23,'2025'!M23) | N23: =SUM(B23:M23)
A24: POJAVE (broj dana sa....)
A25: snegom | B25: =AVERAGE('1991'!B25,'1992'!B25,'1993'!B25,'1994'!B25,'1995'!B25,'1996'!B25,'1997'!B25,'1998'!B25,'1999'!B25,'2000'!B25,'2001'!B25,'2002'!B25,'2003'!B25,'2004'!B25,'2005'!B25,'2006'!B25,'2007'!B25,'2008'!B25,'2009'!B25,'2010'!B25,'2011'!B25,'2012'!B25,'2013'!B25,'2014'!B25,'2015'!B25,'2016'!B25,'2017'!B25,'2018'!B25,'2019'!B25,'2020'!B25,'2021'!B25,'2022'!B25,'2023'!B25,'2024'!B25,'2025'!B25) | C25: =AVERAGE('1991'!C25,'1992'!C25,'1993'!C25,'1994'!C25,'1995'!C25,'1996'!C25,'1997'!C25,'1998'!C25,'1999'!C25,'2000'!C25,'2001'!C25,'2002'!C25,'2003'!C25,'2004'!C25,'2005'!C25,'2006'!C25,'2007'!C25,'2008'!C25,'2009'!C25,'2010'!C25,'2011'!C25,'2012'!C25,'2013'!C25,'2014'!C25,'2015'!C25,'2016'!C25,'2017'!C25,'2018'!C25,'2019'!C25,'2020'!C25,'2021'!C25,'2022'!C25,'2023'!C25,'2024'!C25,'2025'!C25) | D25: =AVERAGE('1991'!D25,'1992'!D25,'1993'!D25,'1994'!D25,'1995'!D25,'1996'!D25,'1997'!D25,'1998'!D25,'1999'!D25,'2000'!D25,'2001'!D25,'2002'!D25,'2003'!D25,'2004'!D25,'2005'!D25,'2006'!D25,'2007'!D25,'2008'!D25,'2009'!D25,'2010'!D25,'2011'!D25,'2012'!D25,'2013'!D25,'2014'!D25,'2015'!D25,'2016'!D25,'2017'!D25,'2018'!D25,'2019'!D25,'2020'!D25,'2021'!D25,'2022'!D25,'2023'!D25,'2024'!D25,'2025'!D25) | E25: =AVERAGE('1991'!E25,'1992'!E25,'1993'!E25,'1994'!E25,'1995'!E25,'1996'!E25,'1997'!E25,'1998'!E25,'1999'!E25,'2000'!E25,'2001'!E25,'2002'!E25,'2003'!E25,'2004'!E25,'2005'!E25,'2006'!E25,'2007'!E25,'2008'!E25,'2009'!E25,'2010'!E25,'2011'!E25,'2012'!E25,'2013'!E25,'2014'!E25,'2015'!E25,'2016'!E25,'2017'!E25,'2018'!E25,'2019'!E25,'2020'!E25,'2021'!E25,'2022'!E25,'2023'!E25,'2024'!E25,'2025'!E25) | F25: =AVERAGE('1991'!F25,'1992'!F25,'1993'!F25,'1994'!F25,'1995'!F25,'1996'!F25,'1997'!F25,'1998'!F25,'1999'!F25,'2000'!F25,'2001'!F25,'2002'!F25,'2003'!F25,'2004'!F25,'2005'!F25,'2006'!F25,'2007'!F25,'2008'!F25,'2009'!F25,'2010'!F25,'2011'!F25,'2012'!F25,'2013'!F25,'2014'!F25,'2015'!F25,'2016'!F25,'2017'!F25,'2018'!F25,'2019'!F25,'2020'!F25,'2021'!F25,'2022'!F25,'2023'!F25,'2024'!F25,'2025'!F25) | G25: =AVERAGE('1991'!G25,'1992'!G25,'1993'!G25,'1994'!G25,'1995'!G25,'1996'!G25,'1997'!G25,'1998'!G25,'1999'!G25,'2000'!G25,'2001'!G25,'2002'!G25,'2003'!G25,'2004'!G25,'2005'!G25,'2006'!G25,'2007'!G25,'2008'!G25,'2009'!G25,'2010'!G25,'2011'!G25,'2012'!G25,'2013'!G25,'2014'!G25,'2015'!G25,'2016'!G25,'2017'!G25,'2018'!G25,'2019'!G25,'2020'!G25,'2021'!G25,'2022'!G25,'2023'!G25,'2024'!G25,'2025'!G25) | H25: =AVERAGE('1991'!H25,'1992'!H25,'1993'!H25,'1994'!H25,'1995'!H25,'1996'!H25,'1997'!H25,'1998'!H25,'1999'!H25,'2000'!H25,'2001'!H25,'2002'!H25,'2003'!H25,'2004'!H25,'2005'!H25,'2006'!H25,'2007'!H25,'2008'!H25,'2009'!H25,'2010'!H25,'2011'!H25,'2012'!H25,'2013'!H25,'2014'!H25,'2015'!H25,'2016'!H25,'2017'!H25,'2018'!H25,'2019'!H25,'2020'!H25,'2021'!H25,'2022'!H25,'2023'!H25,'2024'!H25,'2025'!H25) | I25: =AVERAGE('1991'!I25,'1992'!I25,'1993'!I25,'1994'!I25,'1995'!I25,'1996'!I25,'1997'!I25,'1998'!I25,'1999'!I25,'2000'!I25,'2001'!I25,'2002'!I25,'2003'!I25,'2004'!I25,'2005'!I25,'2006'!I25,'2007'!I25,'2008'!I25,'2009'!I25,'2010'!I25,'2011'!I25,'2012'!I25,'2013'!I25,'2014'!I25,'2015'!I25,'2016'!I25,'2017'!I25,'2018'!I25,'2019'!I25,'2020'!I25,'2021'!I25,'2022'!I25,'2023'!I25,'2024'!I25,'2025'!I25) | ... M25: =AVERAGE('1991'!M25,'1992'!M25,'1993'!M25,'1994'!M25,'1995'!M25,'1996'!M25,'1997'!M25,'1998'!M25,'1999'!M25,'2000'!M25,'2001'!M25,'2002'!M25,'2003'!M25,'2004'!M25,'2005'!M25,'2006'!M25,'2007'!M25,'2008'!M25,'2009'!M25,'2010'!M25,'2011'!M25,'2012'!M25,'2013'!M25,'2014'!M25,'2015'!M25,'2016'!M25,'2017'!M25,'2018'!M25,'2019'!M25,'2020'!M25,'2021'!M25,'2022'!M25,'2023'!M25,'2024'!M25,'2025'!M25) | N25: =SUM(B25:M25)
